Workbook
Name Brand: Setup!$G$5:$G$34
Name Category: Setup!$E$5:$E$34
Name GroceryCostTable: 'Grocery List'!$D$6:$K$154
Name GroceryItemTable: 'Grocery List'!$D$6:$D$154
Name GroceryLowestPriceRef: 'Grocery List'!$B$6:$K$154
Name GroceryMartRef: 'Grocery List'!$C$6:$K$154
Name GroceryPriceTable: 'Grocery List'!$K$6:$K$154
Name ItemName: Setup!$B$5:$B$140
Name LowestPrice: 'Grocery List'!$A$6:$A$154
Name Mart: Setup!$K$5:$K$34
Name MartRef: 'Cost Summary'!$D$18
Name Unit: Setup!$I$5:$I$34

Sheet Cost Summary
B2: Grocery Cost Summary
A4: 0 | B4: Price Based On Lowest Price
B5: No | C5: Item | D5: Category | E5: Brand | F5: Store | G5: Price
B6: 1 | C6: Laundry Detergent | D6: =IFERROR(VLOOKUP(C6,Setup!$B$5:$C$140,2,FALSE),"") -> Cleaning | E6: =IF(C6<>"",IFERROR(VLOOKUP(0&C6,GroceryLowestPriceRef,5,FALSE),""),"") -> Brand 3 | F6: =IF(C6<>"",IFERROR(VLOOKUP(0&C6,GroceryLowestPriceRef,8,FALSE),""),"") -> Mart 1 | G6: =IF(C6<>"",SUMPRODUCT((GroceryItemTable=C6)*(LowestPrice=0)*GroceryPriceTable),"") -> 0.0083333333
B7: 2 | C7: Paper Towels | D7: =IFERROR(VLOOKUP(C7,Setup!$B$5:$C$140,2,FALSE),"") -> Cleaning | E7: =IF(C7<>"",IFERROR(VLOOKUP(0&C7,GroceryLowestPriceRef,5,FALSE),""),"") -> Brand 1 | F7: =IF(C7<>"",IFERROR(VLOOKUP(0&C7,GroceryLowestPriceRef,8,FALSE),""),"") -> Mart 1 | G7: =IF(C7<>"",SUMPRODUCT((GroceryItemTable=C7)*(LowestPrice=0)*GroceryPriceTable),"") -> 0.55
B8: 3 | D8: =IFERROR(VLOOKUP(C8,Setup!$B$5:$C$140,2,FALSE),"") | E8: =IF(C8<>"",IFERROR(VLOOKUP(0&C8,GroceryLowestPriceRef,5,FALSE),""),"") | F8: =IF(C8<>"",IFERROR(VLOOKUP(0&C8,GroceryLowestPriceRef,8,FALSE),""),"") | G8: =IF(C8<>"",SUMPRODUCT((GroceryItemTable=C8)*(LowestPrice=0)*GroceryPriceTable),"")
B9: 4 | D9: =IFERROR(VLOOKUP(C9,Setup!$B$5:$C$140,2,FALSE),"") | E9: =IF(C9<>"",IFERROR(VLOOKUP(0&C9,GroceryLowestPriceRef,5,FALSE),""),"") | F9: =IF(C9<>"",IFERROR(VLOOKUP(0&C9,GroceryLowestPriceRef,8,FALSE),""),"") | G9: =IF(C9<>"",SUMPRODUCT((GroceryItemTable=C9)*(LowestPrice=0)*GroceryPriceTable),"")
B10: 5 | D10: =IFERROR(VLOOKUP(C10,Setup!$B$5:$C$140,2,FALSE),"") | E10: =IF(C10<>"",IFERROR(VLOOKUP(0&C10,GroceryLowestPriceRef,5,FALSE),""),"") | F10: =IF(C10<>"",IFERROR(VLOOKUP(0&C10,GroceryLowestPriceRef,8,FALSE),""),"") | G10: =IF(C10<>"",SUMPRODUCT((GroceryItemTable=C10)*(LowestPrice=0)*GroceryPriceTable),"")
B11: 6 | D11: =IFERROR(VLOOKUP(C11,Setup!$B$5:$C$140,2,FALSE),"") | E11: =IF(C11<>"",IFERROR(VLOOKUP(0&C11,GroceryLowestPriceRef,5,FALSE),""),"") | F11: =IF(C11<>"",IFERROR(VLOOKUP(0&C11,GroceryLowestPriceRef,8,FALSE),""),"") | G11: =IF(C11<>"",SUMPRODUCT((GroceryItemTable=C11)*(LowestPrice=0)*GroceryPriceTable),"")
B12: 7 | D12: =IFERROR(VLOOKUP(C12,Setup!$B$5:$C$140,2,FALSE),"") | E12: =IF(C12<>"",IFERROR(VLOOKUP(0&C12,GroceryLowestPriceRef,5,FALSE),""),"") | F12: =IF(C12<>"",IFERROR(VLOOKUP(0&C12,GroceryLowestPriceRef,8,FALSE),""),"") | G12: =IF(C12<>"",SUMPRODUCT((GroceryItemTable=C12)*(LowestPrice=0)*GroceryPriceTable),"")
B13: 8 | D13: =IFERROR(VLOOKUP(C13,Setup!$B$5:$C$140,2,FALSE),"") | E13: =IF(C13<>"",IFERROR(VLOOKUP(0&C13,GroceryLowestPriceRef,5,FALSE),""),"") | F13: =IF(C13<>"",IFERROR(VLOOKUP(0&C13,GroceryLowestPriceRef,8,FALSE),""),"") | G13: =IF(C13<>"",SUMPRODUCT((GroceryItemTable=C13)*(LowestPrice=0)*GroceryPriceTable),"")
B14: 9 | D14: =IFERROR(VLOOKUP(C14,Setup!$B$5:$C$140,2,FALSE),"") | E14: =IF(C14<>"",IFERROR(VLOOKUP(0&C14,GroceryLowestPriceRef,5,FALSE),""),"") | F14: =IF(C14<>"",IFERROR(VLOOKUP(0&C14,GroceryLowestPriceRef,8,FALSE),""),"") | G14: =IF(C14<>"",SUMPRODUCT((GroceryItemTable=C14)*(LowestPrice=0)*GroceryPriceTable),"")
B15: 10 | D15: =IFERROR(VLOOKUP(C15,Setup!$B$5:$C$140,2,FALSE),"") | E15: =IF(C15<>"",IFERROR(VLOOKUP(0&C15,GroceryLowestPriceRef,5,FALSE),""),"") | F15: =IF(C15<>"",IFERROR(VLOOKUP(0&C15,GroceryLowestPriceRef,8,FALSE),""),"") | G15: =IF(C15<>"",SUMPRODUCT((GroceryItemTable=C15)*(LowestPrice=0)*GroceryPriceTable),"")
B16: Total | G16: =SUM(G6:G15) -> 0.55833333
A18: 0 | B18: Price Based On Similar Store | D18: Mart 3
B19: No | C19: Item | D19: Category | E19: Brand | F19: Store | G19: Price
B20: 1 | C20: =IF(C6<>"",C6,"") -> Laundry Detergent | D20: =IFERROR(VLOOKUP(C20,Setup!$B$5:$C$140,2,FALSE),"") -> Cleaning | E20: =IF(C20<>"",IFERROR(VLOOKUP(MartRef&C20,GroceryMartRef,4,FALSE),""),"") -> Brand 1 | F20: =IF(C20<>"",IFERROR(VLOOKUP(MartRef&C20,GroceryMartRef,7,FALSE),""),"") -> Mart 3 | G20: =IF(C20<>"",IFERROR(VLOOKUP(MartRef&C20,GroceryMartRef,9,FALSE),""),"") -> 0.17857143
B21: 2 | C21: =IF(C7<>"",C7,"") -> Paper Towels | D21: =IFERROR(VLOOKUP(C21,Setup!$B$5:$C$140,2,FALSE),"") -> Cleaning | E21: =IF(C21<>"",IFERROR(VLOOKUP(MartRef&C21,GroceryMartRef,4,FALSE),""),"") | F21: =IF(C21<>"",IFERROR(VLOOKUP(MartRef&C21,GroceryMartRef,7,FALSE),""),"") | G21: =IF(C21<>"",IFERROR(VLOOKUP(MartRef&C21,GroceryMartRef,9,FALSE),""),"")
B22: 3 | C22: =IF(C8<>"",C8,"") | D22: =IFERROR(VLOOKUP(C22,Setup!$B$5:$C$140,2,FALSE),"") | E22: =IF(C22<>"",IFERROR(VLOOKUP(MartRef&C22,GroceryMartRef,4,FALSE),""),"") | F22: =IF(C22<>"",IFERROR(VLOOKUP(MartRef&C22,GroceryMartRef,7,FALSE),""),"") | G22: =IF(C22<>"",IFERROR(VLOOKUP(MartRef&C22,GroceryMartRef,9,FALSE),""),"")
B23: 4 | C23: =IF(C9<>"",C9,"") | D23: =IFERROR(VLOOKUP(C23,Setup!$B$5:$C$140,2,FALSE),"") | E23: =IF(C23<>"",IFERROR(VLOOKUP(MartRef&C23,GroceryMartRef,4,FALSE),""),"") | F23: =IF(C23<>"",IFERROR(VLOOKUP(MartRef&C23,GroceryMartRef,7,FALSE),""),"") | G23: =IF(C23<>"",IFERROR(VLOOKUP(MartRef&C23,GroceryMartRef,9,FALSE),""),"")
B24: 5 | C24: =IF(C10<>"",C10,"") | D24: =IFERROR(VLOOKUP(C24,Setup!$B$5:$C$140,2,FALSE),"") | E24: =IF(C24<>"",IFERROR(VLOOKUP(MartRef&C24,GroceryMartRef,4,FALSE),""),"") | F24: =IF(C24<>"",IFERROR(VLOOKUP(MartRef&C24,GroceryMartRef,7,FALSE),""),"") | G24: =IF(C24<>"",IFERROR(VLOOKUP(MartRef&C24,GroceryMartRef,9,FALSE),""),"")
B25: 6 | C25: =IF(C11<>"",C11,"") | D25: =IFERROR(VLOOKUP(C25,Setup!$B$5:$C$140,2,FALSE),"") | E25: =IF(C25<>"",IFERROR(VLOOKUP(MartRef&C25,GroceryMartRef,4,FALSE),""),"") | F25: =IF(C25<>"",IFERROR(VLOOKUP(MartRef&C25,GroceryMartRef,7,FALSE),""),"") | G25: =IF(C25<>"",IFERROR(VLOOKUP(MartRef&C25,GroceryMartRef,9,FALSE),""),"")
B26: 7 | C26: =IF(C12<>"",C12,"") | D26: =IFERROR(VLOOKUP(C26,Setup!$B$5:$C$140,2,FALSE),"") | E26: =IF(C26<>"",IFERROR(VLOOKUP(MartRef&C26,GroceryMartRef,4,FALSE),""),"") | F26: =IF(C26<>"",IFERROR(VLOOKUP(MartRef&C26,GroceryMartRef,7,FALSE),""),"") | G26: =IF(C26<>"",IFERROR(VLOOKUP(MartRef&C26,GroceryMartRef,9,FALSE),""),"")
B27: 8 | C27: =IF(C13<>"",C13,"") | D27: =IFERROR(VLOOKUP(C27,Setup!$B$5:$C$140,2,FALSE),"") | E27: =IF(C27<>"",IFERROR(VLOOKUP(MartRef&C27,GroceryMartRef,4,FALSE),""),"") | F27: =IF(C27<>"",IFERROR(VLOOKUP(MartRef&C27,GroceryMartRef,7,FALSE),""),"") | G27: =IF(C27<>"",IFERROR(VLOOKUP(MartRef&C27,GroceryMartRef,9,FALSE),""),"")
B28: 9 | C28: =IF(C14<>"",C14,"") | D28: =IFERROR(VLOOKUP(C28,Setup!$B$5:$C$140,2,FALSE),"") | E28: =IF(C28<>"",IFERROR(VLOOKUP(MartRef&C28,GroceryMartRef,4,FALSE),""),"") | F28: =IF(C28<>"",IFERROR(VLOOKUP(MartRef&C28,GroceryMartRef,7,FALSE),""),"") | G28: =IF(C28<>"",IFERROR(VLOOKUP(MartRef&C28,GroceryMartRef,9,FALSE),""),"")
B29: 10 | C29: =IF(C15<>"",C15,"") | D29: =IFERROR(VLOOKUP(C29,Setup!$B$5:$C$140,2,FALSE),"") | E29: =IF(C29<>"",IFERROR(VLOOKUP(MartRef&C29,GroceryMartRef,4,FALSE),""),"") | F29: =IF(C29<>"",IFERROR(VLOOKUP(MartRef&C29,GroceryMartRef,7,FALSE),""),"") | G29: =IF(C29<>"",IFERROR(VLOOKUP(MartRef&C29,GroceryMartRef,9,FALSE),""),"")
B30: Total | G30: =SUM(G20:G29) -> 0.17857143
B32: © 2021 - exceltemplate.net

Sheet Grocery List
D2: Grocery Cost Table
D4: Item | E4: Category | F4: Brand | G4: Purchase | K4: Price Per Unit
G5: Qty | H5: Unit | I5: Store | J5: Price
A6: =SUMPRODUCT(($D$6:$D$154=D6)*($K$6:$K$154<K6)*1) -> 2 | B6: =A6&D6 -> 2Laundry Detergent | C6: =I6&D6 -> Mart 1Laundry Detergent | D6: Laundry Detergent | E6: =IFERROR(VLOOKUP(D6,Setup!$B$5:$C4140,2,FALSE),"") -> Cleaning | F6: Brand 1 | G6: 32 | H6: loads | I6: Mart 1 | J6: 1 | K6: =IFERROR(J6/G6,0) -> 0.03125
A7: =SUMPRODUCT(($D$6:$D$154=D7)*($K$6:$K$154<K7)*1) -> 1 | B7: =A7&D7 -> 1Laundry Detergent | C7: =I7&D7 -> Mart 1Laundry Detergent | D7: Laundry Detergent | E7: =IFERROR(VLOOKUP(D7,Setup!$B$5:$C4141,2,FALSE),"") -> Cleaning | F7: Brand 2 | G7: 32 | H7: loads | I7: Mart 1 | J7: 0.55 | K7: =IFERROR(J7/G7,0) -> 0.0171875
A8: =SUMPRODUCT(($D$6:$D$154=D8)*($K$6:$K$154<K8)*1) -> 0 | B8: =A8&D8 -> 0Laundry Detergent | C8: =I8&D8 -> Mart 1Laundry Detergent | D8: Laundry Detergent | E8: =IFERROR(VLOOKUP(D8,Setup!$B$5:$C4142,2,FALSE),"") -> Cleaning | F8: Brand 3 | G8: 30 | H8: loads | I8: Mart 1 | J8: 0.25 | K8: =IFERROR(J8/G8,0) -> 0.0083333333
A9: =SUMPRODUCT(($D$6:$D$154=D9)*($K$6:$K$154<K9)*1) -> 3 | B9: =A9&D9 -> 3Laundry Detergent | C9: =I9&D9 -> Mart 2Laundry Detergent | D9: Laundry Detergent | E9: =IFERROR(VLOOKUP(D9,Setup!$B$5:$C4143,2,FALSE),"") -> Cleaning | F9: Brand 1 | G9: 30 | H9: loads | I9: Mart 2 | J9: 2.98 | K9: =IFERROR(J9/G9,0) -> 0.099333333
A10: =SUMPRODUCT(($D$6:$D$154=D10)*($K$6:$K$154<K10)*1) -> 4 | B10: =A10&D10 -> 4Laundry Detergent | C10: =I10&D10 -> Mart 3Laundry Detergent | D10: Laundry Detergent | E10: =IFERROR(VLOOKUP(D10,Setup!$B$5:$C4144,2,FALSE),"") -> Cleaning | F10: Brand 1 | G10: 28 | H10: loads | I10: Mart 3 | J10: 5 | K10: =IFERROR(J10/G10,0) -> 0.17857143
A11: =SUMPRODUCT(($D$6:$D$154=D11)*($K$6:$K$154<K11)*1) -> 0 | B11: =A11&D11 -> 0Paper Towels | C11: =I11&D11 -> Mart 1Paper Towels | D11: Paper Towels | E11: =IFERROR(VLOOKUP(D11,Setup!$B$5:$C4145,2,FALSE),"") -> Cleaning | F11: Brand 1 | G11: 1 | H11: roll | I11: Mart 1 | J11: 0.55 | K11: =IFERROR(J11/G11,0) -> 0.55
A12: =SUMPRODUCT(($D$6:$D$154=D12)*($K$6:$K$154<K12)*1) -> 0 | B12: =A12&D12 -> 0Toilet Paper | C12: =I12&D12 -> Mart 1Toilet Paper | D12: Toilet Paper | E12: =IFERROR(VLOOKUP(D12,Setup!$B$5:$C4146,2,FALSE),"") -> Cleaning | F12: Brand 1 | G12: 1 | H12: roll | I12: Mart 1 | J12: 0.25 | K12: =IFERROR(J12/G12,0) -> 0.25
A13: =SUMPRODUCT(($D$6:$D$154=D13)*($K$6:$K$154<K13)*1) -> 0 | B13: =A13&D13 -> 0Kitchen Trash Bags | C13: =I13&D13 -> Mart 1Kitchen Trash Bags | D13: Kitchen Trash Bags | E13: =IFERROR(VLOOKUP(D13,Setup!$B$5:$C4147,2,FALSE),"") -> Cleaning | F13: Brand 1 | G13: 32 | H13: bags | I13: Mart 1 | J13: 2.98 | K13: =IFERROR(J13/G13,0) -> 0.093125
A14: =SUMPRODUCT(($D$6:$D$154=D14)*($K$6:$K$154<K14)*1) -> 0 | B14: =A14&D14 -> 0Diapers | C14: =I14&D14 -> Mart 1Diapers | D14: Diapers | E14: =IFERROR(VLOOKUP(D14,Setup!$B$5:$C4148,2,FALSE),"") -> Cleaning | F14: Brand 1 | G14: 6 | H14: Pack | I14: Mart 1 | J14: 5 | K14: =IFERROR(J14/G14,0) -> 0.83333333
A15: =SUMPRODUCT(($D$6:$D$154=D15)*($K$6:$K$154<K15)*1) -> 0 | B15: =A15&D15 -> 0Wipes | C15: =I15&D15 -> Mart 1Wipes | D15: Wipes | E15: =IFERROR(VLOOKUP(D15,Setup!$B$5:$C4149,2,FALSE),"") -> Cleaning | F15: Brand 1 | G15: 64 | H15: ct | I15: Mart 1 | J15: 1 | K15: =IFERROR(J15/G15,0) -> 0.015625
A16: =SUMPRODUCT(($D$6:$D$154=D16)*($K$6:$K$154<K16)*1) -> 0 | B16: =A16&D16 -> 0Bread | C16: =I16&D16 -> Mart 1Bread | D16: Bread | E16: =IFERROR(VLOOKUP(D16,Setup!$B$5:$C4150,2,FALSE),"") -> Dry/Canned Goods | F16: Brand 1 | G16: 8 | H16: slices | I16: Mart 1 | J16: 1 | K16: =IFERROR(J16/G16,0) -> 0.125
A17: =SUMPRODUCT(($D$6:$D$154=D17)*($K$6:$K$154<K17)*1) -> 0 | B17: =A17&D17 -> 0Brownie Mix | C17: =I17&D17 -> Mart 1Brownie Mix | D17: Brownie Mix | E17: =IFERROR(VLOOKUP(D17,Setup!$B$5:$C4151,2,FALSE),"") -> Dry/Canned Goods | F17: Brand 1 | G17: 1 | H17: box | I17: Mart 1 | J17: 0.75 | K17: =IFERROR(J17/G17,0) -> 0.75
... A91: =SUMPRODUCT(($D$6:$D$154=D91)*($K$6:$K$154<K91)*1) -> 0 | B91: =A91&D91 -> 0Yogurt | C91: =I91&D91 -> Mart 1Yogurt | D91: Yogurt | E91: =IFERROR(VLOOKUP(D91,Setup!$B$5:$C4225,2,FALSE),"") -> Refrigerated Items | F91: Brand 1 | G91: 1 | H91: srv | I91: Mart 1 | J91: 0.25 | K91: =IFERROR(J91/G91,0) -> 0.25
A92: =SUMPRODUCT(($D$6:$D$154=D92)*($K$6:$K$154<K92)*1) -> 0 | B92: =A92&D92 -> 0 | C92: =I92&D92 | E92: =IFERROR(VLOOKUP(D92,Setup!$B$5:$C4226,2,FALSE),"") | K92: =IFERROR(J92/G92,0) -> 0
A93: =SUMPRODUCT(($D$6:$D$154=D93)*($K$6:$K$154<K93)*1) -> 0 | B93: =A93&D93 -> 0 | C93: =I93&D93 | E93: =IFERROR(VLOOKUP(D93,Setup!$B$5:$C4227,2,FALSE),"") | K93: =IFERROR(J93/G93,0) -> 0
A94: =SUMPRODUCT(($D$6:$D$154=D94)*($K$6:$K$154<K94)*1) -> 0 | B94: =A94&D94 -> 0 | C94: =I94&D94 | E94: =IFERROR(VLOOKUP(D94,Setup!$B$5:$C4228,2,FALSE),"") | K94: =IFERROR(J94/G94,0) -> 0
A95: =SUMPRODUCT(($D$6:$D$154=D95)*($K$6:$K$154<K95)*1) -> 0 | B95: =A95&D95 -> 0 | C95: =I95&D95 | E95: =IFERROR(VLOOKUP(D95,Setup!$B$5:$C4229,2,FALSE),"") | K95: =IFERROR(J95/G95,0) -> 0
A96: =SUMPRODUCT(($D$6:$D$154=D96)*($K$6:$K$154<K96)*1) -> 0 | B96: =A96&D96 -> 0 | C96: =I96&D96 | E96: =IFERROR(VLOOKUP(D96,Setup!$B$5:$C4230,2,FALSE),"") | K96: =IFERROR(J96/G96,0) -> 0
A97: =SUMPRODUCT(($D$6:$D$154=D97)*($K$6:$K$154<K97)*1) -> 0 | B97: =A97&D97 -> 0 | C97: =I97&D97 | E97: =IFERROR(VLOOKUP(D97,Setup!$B$5:$C4231,2,FALSE),"") | K97: =IFERROR(J97/G97,0) -> 0
A98: =SUMPRODUCT(($D$6:$D$154=D98)*($K$6:$K$154<K98)*1) -> 0 | B98: =A98&D98 -> 0 | C98: =I98&D98 | E98: =IFERROR(VLOOKUP(D98,Setup!$B$5:$C4232,2,FALSE),"") | K98: =IFERROR(J98/G98,0) -> 0
A99: =SUMPRODUCT(($D$6:$D$154=D99)*($K$6:$K$154<K99)*1) -> 0 | B99: =A99&D99 -> 0 | C99: =I99&D99 | E99: =IFERROR(VLOOKUP(D99,Setup!$B$5:$C4233,2,FALSE),"") | K99: =IFERROR(J99/G99,0) -> 0
A100: =SUMPRODUCT(($D$6:$D$154=D100)*($K$6:$K$154<K100)*1) -> 0 | B100: =A100&D100 -> 0 | C100: =I100&D100 | E100: =IFERROR(VLOOKUP(D100,Setup!$B$5:$C4234,2,FALSE),"") | K100: =IFERROR(J100/G100,0) -> 0
A101: =SUMPRODUCT(($D$6:$D$154=D101)*($K$6:$K$154<K101)*1) -> 0 | B101: =A101&D101 -> 0 | C101: =I101&D101 | E101: =IFERROR(VLOOKUP(D101,Setup!$B$5:$C4235,2,FALSE),"") | K101: =IFERROR(J101/G101,0) -> 0
A102: =SUMPRODUCT(($D$6:$D$154=D102)*($K$6:$K$154<K102)*1) -> 0 | B102: =A102&D102 -> 0 | C102: =I102&D102 | E102: =IFERROR(VLOOKUP(D102,Setup!$B$5:$C4236,2,FALSE),"") | K102: =IFERROR(J102/G102,0) -> 0
A103: =SUMPRODUCT(($D$6:$D$154=D103)*($K$6:$K$154<K103)*1) -> 0 | B103: =A103&D103 -> 0 | C103: =I103&D103 | E103: =IFERROR(VLOOKUP(D103,Setup!$B$5:$C4237,2,FALSE),"") | K103: =IFERROR(J103/G103,0) -> 0
... A154: =SUMPRODUCT(($D$6:$D$154=D154)*($K$6:$K$154<K154)*1) -> 0 | B154: =A154&D154 -> 0 | C154: =I154&D154 | E154: =IFERROR(VLOOKUP(D154,Setup!$B$5:$C4288,2,FALSE),"") | K154: =IFERROR(J154/G154,0) -> 0

Sheet Setup
B2: Setup
B4: Item Name | C4: Category | E4: Category | G4: Brand | I4: Unit | K4: Store
B5: Laundry Detergent | C5: Cleaning | E5: Refrigerated Item | G5: Brand 1 | I5: bags | K5: Mart 1
B6: Paper Towels | C6: Cleaning | E6: Fruits | G6: Brand 2 | I6: box | K6: Mart 2
B7: Toilet Paper | C7: Cleaning | E7: Frozen Food | G7: Brand 3 | I7: carton | K7: Mart 3
B8: Kitchen Trash Bags | C8: Cleaning | E8: Meat | G8: Brand 4 | I8: ct | K8: Mart 4
B9: Diapers | C9: Cleaning | E9: Dry/Canned Goods | G9: Brand 5 | I9: dozen | K9: Mart 5
B10: Wipes | C10: Cleaning | E10: Cleaning | G10: Brand 6 | I10: gallon | K10: Mart 6
B11: Bread | C11: Dry/Canned Goods | G11: Brand 7 | I11: head | K11: Mart 7
B12: Brownie Mix | C12: Dry/Canned Goods | G12: Brand 8 | I12: lb
B13: Tuna | C13: Dry/Canned Goods | G13: Brand 9 | I13: lbs
B14: Canned Vegetables | C14: Dry/Canned Goods | G14: Brand 10 | I14: litler
B15: Cereal | C15: Dry/Canned Goods | G15: Brand 11 | I15: loads
B16: Chips | C16: Dry/Canned Goods | G16: Brand 12 | I16: oz
B17: Chocolate chips | C17: Dry/Canned Goods | G17: Brand 13 | I17: Pack
B18: Crackers | C18: Dry/Canned Goods | G18: Brand 14 | I18: pk
B19: Flour | C19: Dry/Canned Goods | G19: Brand 15 | I19: roll
B20: Fruit Snacks | C20: Dry/Canned Goods | G20: Brand 16 | I20: slices
B21: Hamburger/ Hot Dog Buns | C21: Dry/Canned Goods | G21: Brand 17 | I21: srv
B22: Jelly/Jam | C22: Dry/Canned Goods | G22: Brand 18 | I22: tub
B23: Ketchup | C23: Dry/Canned Goods | G23: Brand 19
B24: Mayo | C24: Dry/Canned Goods | G24: Brand 20
B25: Yellow Mustard | C25: Dry/Canned Goods
B26: Oats | C26: Dry/Canned Goods
B27: Oil (vegetable) | C27: Dry/Canned Goods
B28: Olive Oil | C28: Dry/Canned Goods
B29: Pasta | C29: Dry/Canned Goods
B30: Peanut butter | C30: Dry/Canned Goods
B31: Salad Dressing | C31: Dry/Canned Goods
B32: Soda (can) | C32: Dry/Canned Goods
B33: Soda (bottle) | C33: Dry/Canned Goods
B34: Soup (canned) | C34: Dry/Canned Goods
B35: Spaghetti Sauce | C35: Dry/Canned Goods
B36: Sugar | C36: Dry/Canned Goods | E36: © 2021 - exceltemplate.net
B37: Tomato Paste | C37: Dry/Canned Goods
B38: Tomato Sauce | C38: Dry/Canned Goods
B39: Tortillas | C39: Dry/Canned Goods
B40: Frozen Veggies | C40: Frozen Food
B41: Ice Cream | C41: Frozen Food
B42: Pizza | C42: Frozen Food
...

Sheet Copyright
A40: Need help? Please see this page for information:
A41: https://exceltemplate.net/support/

Sheet Copyright-2
A40: Need help? Please see this page for information:
A41: https://exceltemplate.net/support/
