Workbook
Name monthNames: {"January";"February";"March";"April";"May";"June";"July";"August";"September";"October";"November";"December"}
Name valuevx: 42.314159
Name vertex42_copyright: "© 2020 by Vertex42.com"
Name vertex42_id: "employee-leave-tracker.xlsx"
Name vertex42_title: "Employee Leave Tracker"
Name list_totals: YearToDate!$A$8:$H$39

Sheet YearToDate
A1: Employee Leave Tracker | I1: MeledathStudio
A3: Year: | B3: 2025 | K3: ◄ STEP 1: Update the Year
A5: V = Vacation, S = Sick, P = Personal, D = Disability, O = Other Paid, U = Unpaid | K5: ◄ STEP 2a: Define the Types of Leave
A7: Employee | C7: Year Totals
A8: ID | B8: Name | C8: V | D8: S | E8: P | F8: D | G8: O | H8: U | I8: Total | K8: ◄ STEP 2b: Update the Labels for the Types of Leave
A9: 1 | B9: Name 1 | C9: {=IFERROR(INDEX(Aug!AH$6:AH$38,MATCH($A9,Aug!$A$6:$A$38,0)),0)+IFERROR(INDEX(Sep!AH$6:AH$38,MATCH($A9,Sep!$A$6:$A$38,0)),0)+IFERROR(INDEX(Oct!AH$6:AH$38,MATCH($A9,Oct!$A$6:$A$38,0)),0)+IFERROR(INDEX(Nov!AH$6:AH$38,MATCH($A9,Nov!$A$6:$A$38,0)),0)+IFERROR(INDEX(Dec!AH$6:AH$38,MATCH($A9,Dec!$A$6:$A$38,0)),0)+IFERROR(INDEX(Jan!AH$6:AH$38,MATCH($A9,Jan!$A$6:$A$38,0)),0)+IFERROR(INDEX(Feb!AH$6:AH$38,MATCH($A9,Feb!$A$6:$A$38,0)),0)+IFERROR(INDEX(Mar!AH$6:AH$38,MATCH($A9,Mar!$A$6:$A$38,0)),0)+IFERROR(INDEX(Apr!AH$6:AH$38,MATCH($A9,Apr!$A$6:$A$38,0)),0)+IFERROR(INDEX(May!AH$6:AH$38,MATCH($A9,May!$A$6:$A$38,0)),0)+IFERROR(INDEX(Jun!AH$6:AH$38,MATCH($A9,Jun!$A$6:$A$38,0)),0)+IFERROR(INDEX(Jul!AH$6:AH$38,MATCH($A9,Jul!$A$6:$A$38,0)),0)} -> 1.5 | D9: {=IFERROR(INDEX(Aug!AI$6:AI$38,MATCH($A9,Aug!$A$6:$A$38,0)),0)+IFERROR(INDEX(Sep!AI$6:AI$38,MATCH($A9,Sep!$A$6:$A$38,0)),0)+IFERROR(INDEX(Oct!AI$6:AI$38,MATCH($A9,Oct!$A$6:$A$38,0)),0)+IFERROR(INDEX(Nov!AI$6:AI$38,MATCH($A9,Nov!$A$6:$A$38,0)),0)+IFERROR(INDEX(Dec!AI$6:AI$38,MATCH($A9,Dec!$A$6:$A$38,0)),0)+IFERROR(INDEX(Jan!AI$6:AI$38,MATCH($A9,Jan!$A$6:$A$38,0)),0)+IFERROR(INDEX(Feb!AI$6:AI$38,MATCH($A9,Feb!$A$6:$A$38,0)),0)+IFERROR(INDEX(Mar!AI$6:AI$38,MATCH($A9,Mar!$A$6:$A$38,0)),0)+IFERROR(INDEX(Apr!AI$6:AI$38,MATCH($A9,Apr!$A$6:$A$38,0)),0)+IFERROR(INDEX(May!AI$6:AI$38,MATCH($A9,May!$A$6:$A$38,0)),0)+IFERROR(INDEX(Jun!AI$6:AI$38,MATCH($A9,Jun!$A$6:$A$38,0)),0)+IFERROR(INDEX(Jul!AI$6:AI$38,MATCH($A9,Jul!$A$6:$A$38,0)),0)} -> 3.5 | E9: {=IFERROR(INDEX(Aug!AJ$6:AJ$38,MATCH($A9,Aug!$A$6:$A$38,0)),0)+IFERROR(INDEX(Sep!AJ$6:AJ$38,MATCH($A9,Sep!$A$6:$A$38,0)),0)+IFERROR(INDEX(Oct!AJ$6:AJ$38,MATCH($A9,Oct!$A$6:$A$38,0)),0)+IFERROR(INDEX(Nov!AJ$6:AJ$38,MATCH($A9,Nov!$A$6:$A$38,0)),0)+IFERROR(INDEX(Dec!AJ$6:AJ$38,MATCH($A9,Dec!$A$6:$A$38,0)),0)+IFERROR(INDEX(Jan!AJ$6:AJ$38,MATCH($A9,Jan!$A$6:$A$38,0)),0)+IFERROR(INDEX(Feb!AJ$6:AJ$38,MATCH($A9,Feb!$A$6:$A$38,0)),0)+IFERROR(INDEX(Mar!AJ$6:AJ$38,MATCH($A9,Mar!$A$6:$A$38,0)),0)+IFERROR(INDEX(Apr!AJ$6:AJ$38,MATCH($A9,Apr!$A$6:$A$38,0)),0)+IFERROR(INDEX(May!AJ$6:AJ$38,MATCH($A9,May!$A$6:$A$38,0)),0)+IFERROR(INDEX(Jun!AJ$6:AJ$38,MATCH($A9,Jun!$A$6:$A$38,0)),0)+IFERROR(INDEX(Jul!AJ$6:AJ$38,MATCH($A9,Jul!$A$6:$A$38,0)),0)} -> 0 | F9: {=IFERROR(INDEX(Aug!AK$6:AK$38,MATCH($A9,Aug!$A$6:$A$38,0)),0)+IFERROR(INDEX(Sep!AK$6:AK$38,MATCH($A9,Sep!$A$6:$A$38,0)),0)+IFERROR(INDEX(Oct!AK$6:AK$38,MATCH($A9,Oct!$A$6:$A$38,0)),0)+IFERROR(INDEX(Nov!AK$6:AK$38,MATCH($A9,Nov!$A$6:$A$38,0)),0)+IFERROR(INDEX(Dec!AK$6:AK$38,MATCH($A9,Dec!$A$6:$A$38,0)),0)+IFERROR(INDEX(Jan!AK$6:AK$38,MATCH($A9,Jan!$A$6:$A$38,0)),0)+IFERROR(INDEX(Feb!AK$6:AK$38,MATCH($A9,Feb!$A$6:$A$38,0)),0)+IFERROR(INDEX(Mar!AK$6:AK$38,MATCH($A9,Mar!$A$6:$A$38,0)),0)+IFERROR(INDEX(Apr!AK$6:AK$38,MATCH($A9,Apr!$A$6:$A$38,0)),0)+IFERROR(INDEX(May!AK$6:AK$38,MATCH($A9,May!$A$6:$A$38,0)),0)+IFERROR(INDEX(Jun!AK$6:AK$38,MATCH($A9,Jun!$A$6:$A$38,0)),0)+IFERROR(INDEX(Jul!AK$6:AK$38,MATCH($A9,Jul!$A$6:$A$38,0)),0)} -> 0 | G9: {=IFERROR(INDEX(Aug!AL$6:AL$38,MATCH($A9,Aug!$A$6:$A$38,0)),0)+IFERROR(INDEX(Sep!AL$6:AL$38,MATCH($A9,Sep!$A$6:$A$38,0)),0)+IFERROR(INDEX(Oct!AL$6:AL$38,MATCH($A9,Oct!$A$6:$A$38,0)),0)+IFERROR(INDEX(Nov!AL$6:AL$38,MATCH($A9,Nov!$A$6:$A$38,0)),0)+IFERROR(INDEX(Dec!AL$6:AL$38,MATCH($A9,Dec!$A$6:$A$38,0)),0)+IFERROR(INDEX(Jan!AL$6:AL$38,MATCH($A9,Jan!$A$6:$A$38,0)),0)+IFERROR(INDEX(Feb!AL$6:AL$38,MATCH($A9,Feb!$A$6:$A$38,0)),0)+IFERROR(INDEX(Mar!AL$6:AL$38,MATCH($A9,Mar!$A$6:$A$38,0)),0)+IFERROR(INDEX(Apr!AL$6:AL$38,MATCH($A9,Apr!$A$6:$A$38,0)),0)+IFERROR(INDEX(May!AL$6:AL$38,MATCH($A9,May!$A$6:$A$38,0)),0)+IFERROR(INDEX(Jun!AL$6:AL$38,MATCH($A9,Jun!$A$6:$A$38,0)),0)+IFERROR(INDEX(Jul!AL$6:AL$38,MATCH($A9,Jul!$A$6:$A$38,0)),0)} -> 0 | H9: {=IFERROR(INDEX(Aug!AM$6:AM$38,MATCH($A9,Aug!$A$6:$A$38,0)),0)+IFERROR(INDEX(Sep!AM$6:AM$38,MATCH($A9,Sep!$A$6:$A$38,0)),0)+IFERROR(INDEX(Oct!AM$6:AM$38,MATCH($A9,Oct!$A$6:$A$38,0)),0)+IFERROR(INDEX(Nov!AM$6:AM$38,MATCH($A9,Nov!$A$6:$A$38,0)),0)+IFERROR(INDEX(Dec!AM$6:AM$38,MATCH($A9,Dec!$A$6:$A$38,0)),0)+IFERROR(INDEX(Jan!AM$6:AM$38,MATCH($A9,Jan!$A$6:$A$38,0)),0)+IFERROR(INDEX(Feb!AM$6:AM$38,MATCH($A9,Feb!$A$6:$A$38,0)),0)+IFERROR(INDEX(Mar!AM$6:AM$38,MATCH($A9,Mar!$A$6:$A$38,0)),0)+IFERROR(INDEX(Apr!AM$6:AM$38,MATCH($A9,Apr!$A$6:$A$38,0)),0)+IFERROR(INDEX(May!AM$6:AM$38,MATCH($A9,May!$A$6:$A$38,0)),0)+IFERROR(INDEX(Jun!AM$6:AM$38,MATCH($A9,Jun!$A$6:$A$38,0)),0)+IFERROR(INDEX(Jul!AM$6:AM$38,MATCH($A9,Jul!$A$6:$A$38,0)),0)} -> 0 | I9: =SUM(C9:H9) -> 5
A10: 2 | B10: Name 2 | C10: {=IFERROR(INDEX(Aug!AH$6:AH$38,MATCH($A10,Aug!$A$6:$A$38,0)),0)+IFERROR(INDEX(Sep!AH$6:AH$38,MATCH($A10,Sep!$A$6:$A$38,0)),0)+IFERROR(INDEX(Oct!AH$6:AH$38,MATCH($A10,Oct!$A$6:$A$38,0)),0)+IFERROR(INDEX(Nov!AH$6:AH$38,MATCH($A10,Nov!$A$6:$A$38,0)),0)+IFERROR(INDEX(Dec!AH$6:AH$38,MATCH($A10,Dec!$A$6:$A$38,0)),0)+IFERROR(INDEX(Jan!AH$6:AH$38,MATCH($A10,Jan!$A$6:$A$38,0)),0)+IFERROR(INDEX(Feb!AH$6:AH$38,MATCH($A10,Feb!$A$6:$A$38,0)),0)+IFERROR(INDEX(Mar!AH$6:AH$38,MATCH($A10,Mar!$A$6:$A$38,0)),0)+IFERROR(INDEX(Apr!AH$6:AH$38,MATCH($A10,Apr!$A$6:$A$38,0)),0)+IFERROR(INDEX(May!AH$6:AH$38,MATCH($A10,May!$A$6:$A$38,0)),0)+IFERROR(INDEX(Jun!AH$6:AH$38,MATCH($A10,Jun!$A$6:$A$38,0)),0)+IFERROR(INDEX(Jul!AH$6:AH$38,MATCH($A10,Jul!$A$6:$A$38,0)),0)} -> 0 | D10: {=IFERROR(INDEX(Aug!AI$6:AI$38,MATCH($A10,Aug!$A$6:$A$38,0)),0)+IFERROR(INDEX(Sep!AI$6:AI$38,MATCH($A10,Sep!$A$6:$A$38,0)),0)+IFERROR(INDEX(Oct!AI$6:AI$38,MATCH($A10,Oct!$A$6:$A$38,0)),0)+IFERROR(INDEX(Nov!AI$6:AI$38,MATCH($A10,Nov!$A$6:$A$38,0)),0)+IFERROR(INDEX(Dec!AI$6:AI$38,MATCH($A10,Dec!$A$6:$A$38,0)),0)+IFERROR(INDEX(Jan!AI$6:AI$38,MATCH($A10,Jan!$A$6:$A$38,0)),0)+IFERROR(INDEX(Feb!AI$6:AI$38,MATCH($A10,Feb!$A$6:$A$38,0)),0)+IFERROR(INDEX(Mar!AI$6:AI$38,MATCH($A10,Mar!$A$6:$A$38,0)),0)+IFERROR(INDEX(Apr!AI$6:AI$38,MATCH($A10,Apr!$A$6:$A$38,0)),0)+IFERROR(INDEX(May!AI$6:AI$38,MATCH($A10,May!$A$6:$A$38,0)),0)+IFERROR(INDEX(Jun!AI$6:AI$38,MATCH($A10,Jun!$A$6:$A$38,0)),0)+IFERROR(INDEX(Jul!AI$6:AI$38,MATCH($A10,Jul!$A$6:$A$38,0)),0)} -> 0 | E10: {=IFERROR(INDEX(Aug!AJ$6:AJ$38,MATCH($A10,Aug!$A$6:$A$38,0)),0)+IFERROR(INDEX(Sep!AJ$6:AJ$38,MATCH($A10,Sep!$A$6:$A$38,0)),0)+IFERROR(INDEX(Oct!AJ$6:AJ$38,MATCH($A10,Oct!$A$6:$A$38,0)),0)+IFERROR(INDEX(Nov!AJ$6:AJ$38,MATCH($A10,Nov!$A$6:$A$38,0)),0)+IFERROR(INDEX(Dec!AJ$6:AJ$38,MATCH($A10,Dec!$A$6:$A$38,0)),0)+IFERROR(INDEX(Jan!AJ$6:AJ$38,MATCH($A10,Jan!$A$6:$A$38,0)),0)+IFERROR(INDEX(Feb!AJ$6:AJ$38,MATCH($A10,Feb!$A$6:$A$38,0)),0)+IFERROR(INDEX(Mar!AJ$6:AJ$38,MATCH($A10,Mar!$A$6:$A$38,0)),0)+IFERROR(INDEX(Apr!AJ$6:AJ$38,MATCH($A10,Apr!$A$6:$A$38,0)),0)+IFERROR(INDEX(May!AJ$6:AJ$38,MATCH($A10,May!$A$6:$A$38,0)),0)+IFERROR(INDEX(Jun!AJ$6:AJ$38,MATCH($A10,Jun!$A$6:$A$38,0)),0)+IFERROR(INDEX(Jul!AJ$6:AJ$38,MATCH($A10,Jul!$A$6:$A$38,0)),0)} -> 3 | F10: {=IFERROR(INDEX(Aug!AK$6:AK$38,MATCH($A10,Aug!$A$6:$A$38,0)),0)+IFERROR(INDEX(Sep!AK$6:AK$38,MATCH($A10,Sep!$A$6:$A$38,0)),0)+IFERROR(INDEX(Oct!AK$6:AK$38,MATCH($A10,Oct!$A$6:$A$38,0)),0)+IFERROR(INDEX(Nov!AK$6:AK$38,MATCH($A10,Nov!$A$6:$A$38,0)),0)+IFERROR(INDEX(Dec!AK$6:AK$38,MATCH($A10,Dec!$A$6:$A$38,0)),0)+IFERROR(INDEX(Jan!AK$6:AK$38,MATCH($A10,Jan!$A$6:$A$38,0)),0)+IFERROR(INDEX(Feb!AK$6:AK$38,MATCH($A10,Feb!$A$6:$A$38,0)),0)+IFERROR(INDEX(Mar!AK$6:AK$38,MATCH($A10,Mar!$A$6:$A$38,0)),0)+IFERROR(INDEX(Apr!AK$6:AK$38,MATCH($A10,Apr!$A$6:$A$38,0)),0)+IFERROR(INDEX(May!AK$6:AK$38,MATCH($A10,May!$A$6:$A$38,0)),0)+IFERROR(INDEX(Jun!AK$6:AK$38,MATCH($A10,Jun!$A$6:$A$38,0)),0)+IFERROR(INDEX(Jul!AK$6:AK$38,MATCH($A10,Jul!$A$6:$A$38,0)),0)} -> 0 | G10: {=IFERROR(INDEX(Aug!AL$6:AL$38,MATCH($A10,Aug!$A$6:$A$38,0)),0)+IFERROR(INDEX(Sep!AL$6:AL$38,MATCH($A10,Sep!$A$6:$A$38,0)),0)+IFERROR(INDEX(Oct!AL$6:AL$38,MATCH($A10,Oct!$A$6:$A$38,0)),0)+IFERROR(INDEX(Nov!AL$6:AL$38,MATCH($A10,Nov!$A$6:$A$38,0)),0)+IFERROR(INDEX(Dec!AL$6:AL$38,MATCH($A10,Dec!$A$6:$A$38,0)),0)+IFERROR(INDEX(Jan!AL$6:AL$38,MATCH($A10,Jan!$A$6:$A$38,0)),0)+IFERROR(INDEX(Feb!AL$6:AL$38,MATCH($A10,Feb!$A$6:$A$38,0)),0)+IFERROR(INDEX(Mar!AL$6:AL$38,MATCH($A10,Mar!$A$6:$A$38,0)),0)+IFERROR(INDEX(Apr!AL$6:AL$38,MATCH($A10,Apr!$A$6:$A$38,0)),0)+IFERROR(INDEX(May!AL$6:AL$38,MATCH($A10,May!$A$6:$A$38,0)),0)+IFERROR(INDEX(Jun!AL$6:AL$38,MATCH($A10,Jun!$A$6:$A$38,0)),0)+IFERROR(INDEX(Jul!AL$6:AL$38,MATCH($A10,Jul!$A$6:$A$38,0)),0)} -> 0 | H10: {=IFERROR(INDEX(Aug!AM$6:AM$38,MATCH($A10,Aug!$A$6:$A$38,0)),0)+IFERROR(INDEX(Sep!AM$6:AM$38,MATCH($A10,Sep!$A$6:$A$38,0)),0)+IFERROR(INDEX(Oct!AM$6:AM$38,MATCH($A10,Oct!$A$6:$A$38,0)),0)+IFERROR(INDEX(Nov!AM$6:AM$38,MATCH($A10,Nov!$A$6:$A$38,0)),0)+IFERROR(INDEX(Dec!AM$6:AM$38,MATCH($A10,Dec!$A$6:$A$38,0)),0)+IFERROR(INDEX(Jan!AM$6:AM$38,MATCH($A10,Jan!$A$6:$A$38,0)),0)+IFERROR(INDEX(Feb!AM$6:AM$38,MATCH($A10,Feb!$A$6:$A$38,0)),0)+IFERROR(INDEX(Mar!AM$6:AM$38,MATCH($A10,Mar!$A$6:$A$38,0)),0)+IFERROR(INDEX(Apr!AM$6:AM$38,MATCH($A10,Apr!$A$6:$A$38,0)),0)+IFERROR(INDEX(May!AM$6:AM$38,MATCH($A10,May!$A$6:$A$38,0)),0)+IFERROR(INDEX(Jun!AM$6:AM$38,MATCH($A10,Jun!$A$6:$A$38,0)),0)+IFERROR(INDEX(Jul!AM$6:AM$38,MATCH($A10,Jul!$A$6:$A$38,0)),0)} -> 0 | I10: =SUM(C10:H10) -> 3 | K10: ◄ STEP 3: Edit the list of Employees
A11: 3 | B11: Name 3 | C11: {=IFERROR(INDEX(Aug!AH$6:AH$38,MATCH($A11,Aug!$A$6:$A$38,0)),0)+IFERROR(INDEX(Sep!AH$6:AH$38,MATCH($A11,Sep!$A$6:$A$38,0)),0)+IFERROR(INDEX(Oct!AH$6:AH$38,MATCH($A11,Oct!$A$6:$A$38,0)),0)+IFERROR(INDEX(Nov!AH$6:AH$38,MATCH($A11,Nov!$A$6:$A$38,0)),0)+IFERROR(INDEX(Dec!AH$6:AH$38,MATCH($A11,Dec!$A$6:$A$38,0)),0)+IFERROR(INDEX(Jan!AH$6:AH$38,MATCH($A11,Jan!$A$6:$A$38,0)),0)+IFERROR(INDEX(Feb!AH$6:AH$38,MATCH($A11,Feb!$A$6:$A$38,0)),0)+IFERROR(INDEX(Mar!AH$6:AH$38,MATCH($A11,Mar!$A$6:$A$38,0)),0)+IFERROR(INDEX(Apr!AH$6:AH$38,MATCH($A11,Apr!$A$6:$A$38,0)),0)+IFERROR(INDEX(May!AH$6:AH$38,MATCH($A11,May!$A$6:$A$38,0)),0)+IFERROR(INDEX(Jun!AH$6:AH$38,MATCH($A11,Jun!$A$6:$A$38,0)),0)+IFERROR(INDEX(Jul!AH$6:AH$38,MATCH($A11,Jul!$A$6:$A$38,0)),0)} -> 0 | D11: {=IFERROR(INDEX(Aug!AI$6:AI$38,MATCH($A11,Aug!$A$6:$A$38,0)),0)+IFERROR(INDEX(Sep!AI$6:AI$38,MATCH($A11,Sep!$A$6:$A$38,0)),0)+IFERROR(INDEX(Oct!AI$6:AI$38,MATCH($A11,Oct!$A$6:$A$38,0)),0)+IFERROR(INDEX(Nov!AI$6:AI$38,MATCH($A11,Nov!$A$6:$A$38,0)),0)+IFERROR(INDEX(Dec!AI$6:AI$38,MATCH($A11,Dec!$A$6:$A$38,0)),0)+IFERROR(INDEX(Jan!AI$6:AI$38,MATCH($A11,Jan!$A$6:$A$38,0)),0)+IFERROR(INDEX(Feb!AI$6:AI$38,MATCH($A11,Feb!$A$6:$A$38,0)),0)+IFERROR(INDEX(Mar!AI$6:AI$38,MATCH($A11,Mar!$A$6:$A$38,0)),0)+IFERROR(INDEX(Apr!AI$6:AI$38,MATCH($A11,Apr!$A$6:$A$38,0)),0)+IFERROR(INDEX(May!AI$6:AI$38,MATCH($A11,May!$A$6:$A$38,0)),0)+IFERROR(INDEX(Jun!AI$6:AI$38,MATCH($A11,Jun!$A$6:$A$38,0)),0)+IFERROR(INDEX(Jul!AI$6:AI$38,MATCH($A11,Jul!$A$6:$A$38,0)),0)} -> 2 | E11: {=IFERROR(INDEX(Aug!AJ$6:AJ$38,MATCH($A11,Aug!$A$6:$A$38,0)),0)+IFERROR(INDEX(Sep!AJ$6:AJ$38,MATCH($A11,Sep!$A$6:$A$38,0)),0)+IFERROR(INDEX(Oct!AJ$6:AJ$38,MATCH($A11,Oct!$A$6:$A$38,0)),0)+IFERROR(INDEX(Nov!AJ$6:AJ$38,MATCH($A11,Nov!$A$6:$A$38,0)),0)+IFERROR(INDEX(Dec!AJ$6:AJ$38,MATCH($A11,Dec!$A$6:$A$38,0)),0)+IFERROR(INDEX(Jan!AJ$6:AJ$38,MATCH($A11,Jan!$A$6:$A$38,0)),0)+IFERROR(INDEX(Feb!AJ$6:AJ$38,MATCH($A11,Feb!$A$6:$A$38,0)),0)+IFERROR(INDEX(Mar!AJ$6:AJ$38,MATCH($A11,Mar!$A$6:$A$38,0)),0)+IFERROR(INDEX(Apr!AJ$6:AJ$38,MATCH($A11,Apr!$A$6:$A$38,0)),0)+IFERROR(INDEX(May!AJ$6:AJ$38,MATCH($A11,May!$A$6:$A$38,0)),0)+IFERROR(INDEX(Jun!AJ$6:AJ$38,MATCH($A11,Jun!$A$6:$A$38,0)),0)+IFERROR(INDEX(Jul!AJ$6:AJ$38,MATCH($A11,Jul!$A$6:$A$38,0)),0)} -> 0 | F11: {=IFERROR(INDEX(Aug!AK$6:AK$38,MATCH($A11,Aug!$A$6:$A$38,0)),0)+IFERROR(INDEX(Sep!AK$6:AK$38,MATCH($A11,Sep!$A$6:$A$38,0)),0)+IFERROR(INDEX(Oct!AK$6:AK$38,MATCH($A11,Oct!$A$6:$A$38,0)),0)+IFERROR(INDEX(Nov!AK$6:AK$38,MATCH($A11,Nov!$A$6:$A$38,0)),0)+IFERROR(INDEX(Dec!AK$6:AK$38,MATCH($A11,Dec!$A$6:$A$38,0)),0)+IFERROR(INDEX(Jan!AK$6:AK$38,MATCH($A11,Jan!$A$6:$A$38,0)),0)+IFERROR(INDEX(Feb!AK$6:AK$38,MATCH($A11,Feb!$A$6:$A$38,0)),0)+IFERROR(INDEX(Mar!AK$6:AK$38,MATCH($A11,Mar!$A$6:$A$38,0)),0)+IFERROR(INDEX(Apr!AK$6:AK$38,MATCH($A11,Apr!$A$6:$A$38,0)),0)+IFERROR(INDEX(May!AK$6:AK$38,MATCH($A11,May!$A$6:$A$38,0)),0)+IFERROR(INDEX(Jun!AK$6:AK$38,MATCH($A11,Jun!$A$6:$A$38,0)),0)+IFERROR(INDEX(Jul!AK$6:AK$38,MATCH($A11,Jul!$A$6:$A$38,0)),0)} -> 0 | G11: {=IFERROR(INDEX(Aug!AL$6:AL$38,MATCH($A11,Aug!$A$6:$A$38,0)),0)+IFERROR(INDEX(Sep!AL$6:AL$38,MATCH($A11,Sep!$A$6:$A$38,0)),0)+IFERROR(INDEX(Oct!AL$6:AL$38,MATCH($A11,Oct!$A$6:$A$38,0)),0)+IFERROR(INDEX(Nov!AL$6:AL$38,MATCH($A11,Nov!$A$6:$A$38,0)),0)+IFERROR(INDEX(Dec!AL$6:AL$38,MATCH($A11,Dec!$A$6:$A$38,0)),0)+IFERROR(INDEX(Jan!AL$6:AL$38,MATCH($A11,Jan!$A$6:$A$38,0)),0)+IFERROR(INDEX(Feb!AL$6:AL$38,MATCH($A11,Feb!$A$6:$A$38,0)),0)+IFERROR(INDEX(Mar!AL$6:AL$38,MATCH($A11,Mar!$A$6:$A$38,0)),0)+IFERROR(INDEX(Apr!AL$6:AL$38,MATCH($A11,Apr!$A$6:$A$38,0)),0)+IFERROR(INDEX(May!AL$6:AL$38,MATCH($A11,May!$A$6:$A$38,0)),0)+IFERROR(INDEX(Jun!AL$6:AL$38,MATCH($A11,Jun!$A$6:$A$38,0)),0)+IFERROR(INDEX(Jul!AL$6:AL$38,MATCH($A11,Jul!$A$6:$A$38,0)),0)} -> 0 | H11: {=IFERROR(INDEX(Aug!AM$6:AM$38,MATCH($A11,Aug!$A$6:$A$38,0)),0)+IFERROR(INDEX(Sep!AM$6:AM$38,MATCH($A11,Sep!$A$6:$A$38,0)),0)+IFERROR(INDEX(Oct!AM$6:AM$38,MATCH($A11,Oct!$A$6:$A$38,0)),0)+IFERROR(INDEX(Nov!AM$6:AM$38,MATCH($A11,Nov!$A$6:$A$38,0)),0)+IFERROR(INDEX(Dec!AM$6:AM$38,MATCH($A11,Dec!$A$6:$A$38,0)),0)+IFERROR(INDEX(Jan!AM$6:AM$38,MATCH($A11,Jan!$A$6:$A$38,0)),0)+IFERROR(INDEX(Feb!AM$6:AM$38,MATCH($A11,Feb!$A$6:$A$38,0)),0)+IFERROR(INDEX(Mar!AM$6:AM$38,MATCH($A11,Mar!$A$6:$A$38,0)),0)+IFERROR(INDEX(Apr!AM$6:AM$38,MATCH($A11,Apr!$A$6:$A$38,0)),0)+IFERROR(INDEX(May!AM$6:AM$38,MATCH($A11,May!$A$6:$A$38,0)),0)+IFERROR(INDEX(Jun!AM$6:AM$38,MATCH($A11,Jun!$A$6:$A$38,0)),0)+IFERROR(INDEX(Jul!AM$6:AM$38,MATCH($A11,Jul!$A$6:$A$38,0)),0)} -> 0 | I11: =SUM(C11:H11) -> 2
A12: 4 | B12: Name 4 | C12: {=IFERROR(INDEX(Aug!AH$6:AH$38,MATCH($A12,Aug!$A$6:$A$38,0)),0)+IFERROR(INDEX(Sep!AH$6:AH$38,MATCH($A12,Sep!$A$6:$A$38,0)),0)+IFERROR(INDEX(Oct!AH$6:AH$38,MATCH($A12,Oct!$A$6:$A$38,0)),0)+IFERROR(INDEX(Nov!AH$6:AH$38,MATCH($A12,Nov!$A$6:$A$38,0)),0)+IFERROR(INDEX(Dec!AH$6:AH$38,MATCH($A12,Dec!$A$6:$A$38,0)),0)+IFERROR(INDEX(Jan!AH$6:AH$38,MATCH($A12,Jan!$A$6:$A$38,0)),0)+IFERROR(INDEX(Feb!AH$6:AH$38,MATCH($A12,Feb!$A$6:$A$38,0)),0)+IFERROR(INDEX(Mar!AH$6:AH$38,MATCH($A12,Mar!$A$6:$A$38,0)),0)+IFERROR(INDEX(Apr!AH$6:AH$38,MATCH($A12,Apr!$A$6:$A$38,0)),0)+IFERROR(INDEX(May!AH$6:AH$38,MATCH($A12,May!$A$6:$A$38,0)),0)+IFERROR(INDEX(Jun!AH$6:AH$38,MATCH($A12,Jun!$A$6:$A$38,0)),0)+IFERROR(INDEX(Jul!AH$6:AH$38,MATCH($A12,Jul!$A$6:$A$38,0)),0)} -> 0 | D12: {=IFERROR(INDEX(Aug!AI$6:AI$38,MATCH($A12,Aug!$A$6:$A$38,0)),0)+IFERROR(INDEX(Sep!AI$6:AI$38,MATCH($A12,Sep!$A$6:$A$38,0)),0)+IFERROR(INDEX(Oct!AI$6:AI$38,MATCH($A12,Oct!$A$6:$A$38,0)),0)+IFERROR(INDEX(Nov!AI$6:AI$38,MATCH($A12,Nov!$A$6:$A$38,0)),0)+IFERROR(INDEX(Dec!AI$6:AI$38,MATCH($A12,Dec!$A$6:$A$38,0)),0)+IFERROR(INDEX(Jan!AI$6:AI$38,MATCH($A12,Jan!$A$6:$A$38,0)),0)+IFERROR(INDEX(Feb!AI$6:AI$38,MATCH($A12,Feb!$A$6:$A$38,0)),0)+IFERROR(INDEX(Mar!AI$6:AI$38,MATCH($A12,Mar!$A$6:$A$38,0)),0)+IFERROR(INDEX(Apr!AI$6:AI$38,MATCH($A12,Apr!$A$6:$A$38,0)),0)+IFERROR(INDEX(May!AI$6:AI$38,MATCH($A12,May!$A$6:$A$38,0)),0)+IFERROR(INDEX(Jun!AI$6:AI$38,MATCH($A12,Jun!$A$6:$A$38,0)),0)+IFERROR(INDEX(Jul!AI$6:AI$38,MATCH($A12,Jul!$A$6:$A$38,0)),0)} -> 0 | E12: {=IFERROR(INDEX(Aug!AJ$6:AJ$38,MATCH($A12,Aug!$A$6:$A$38,0)),0)+IFERROR(INDEX(Sep!AJ$6:AJ$38,MATCH($A12,Sep!$A$6:$A$38,0)),0)+IFERROR(INDEX(Oct!AJ$6:AJ$38,MATCH($A12,Oct!$A$6:$A$38,0)),0)+IFERROR(INDEX(Nov!AJ$6:AJ$38,MATCH($A12,Nov!$A$6:$A$38,0)),0)+IFERROR(INDEX(Dec!AJ$6:AJ$38,MATCH($A12,Dec!$A$6:$A$38,0)),0)+IFERROR(INDEX(Jan!AJ$6:AJ$38,MATCH($A12,Jan!$A$6:$A$38,0)),0)+IFERROR(INDEX(Feb!AJ$6:AJ$38,MATCH($A12,Feb!$A$6:$A$38,0)),0)+IFERROR(INDEX(Mar!AJ$6:AJ$38,MATCH($A12,Mar!$A$6:$A$38,0)),0)+IFERROR(INDEX(Apr!AJ$6:AJ$38,MATCH($A12,Apr!$A$6:$A$38,0)),0)+IFERROR(INDEX(May!AJ$6:AJ$38,MATCH($A12,May!$A$6:$A$38,0)),0)+IFERROR(INDEX(Jun!AJ$6:AJ$38,MATCH($A12,Jun!$A$6:$A$38,0)),0)+IFERROR(INDEX(Jul!AJ$6:AJ$38,MATCH($A12,Jul!$A$6:$A$38,0)),0)} -> 0 | F12: {=IFERROR(INDEX(Aug!AK$6:AK$38,MATCH($A12,Aug!$A$6:$A$38,0)),0)+IFERROR(INDEX(Sep!AK$6:AK$38,MATCH($A12,Sep!$A$6:$A$38,0)),0)+IFERROR(INDEX(Oct!AK$6:AK$38,MATCH($A12,Oct!$A$6:$A$38,0)),0)+IFERROR(INDEX(Nov!AK$6:AK$38,MATCH($A12,Nov!$A$6:$A$38,0)),0)+IFERROR(INDEX(Dec!AK$6:AK$38,MATCH($A12,Dec!$A$6:$A$38,0)),0)+IFERROR(INDEX(Jan!AK$6:AK$38,MATCH($A12,Jan!$A$6:$A$38,0)),0)+IFERROR(INDEX(Feb!AK$6:AK$38,MATCH($A12,Feb!$A$6:$A$38,0)),0)+IFERROR(INDEX(Mar!AK$6:AK$38,MATCH($A12,Mar!$A$6:$A$38,0)),0)+IFERROR(INDEX(Apr!AK$6:AK$38,MATCH($A12,Apr!$A$6:$A$38,0)),0)+IFERROR(INDEX(May!AK$6:AK$38,MATCH($A12,May!$A$6:$A$38,0)),0)+IFERROR(INDEX(Jun!AK$6:AK$38,MATCH($A12,Jun!$A$6:$A$38,0)),0)+IFERROR(INDEX(Jul!AK$6:AK$38,MATCH($A12,Jul!$A$6:$A$38,0)),0)} -> 0 | G12: {=IFERROR(INDEX(Aug!AL$6:AL$38,MATCH($A12,Aug!$A$6:$A$38,0)),0)+IFERROR(INDEX(Sep!AL$6:AL$38,MATCH($A12,Sep!$A$6:$A$38,0)),0)+IFERROR(INDEX(Oct!AL$6:AL$38,MATCH($A12,Oct!$A$6:$A$38,0)),0)+IFERROR(INDEX(Nov!AL$6:AL$38,MATCH($A12,Nov!$A$6:$A$38,0)),0)+IFERROR(INDEX(Dec!AL$6:AL$38,MATCH($A12,Dec!$A$6:$A$38,0)),0)+IFERROR(INDEX(Jan!AL$6:AL$38,MATCH($A12,Jan!$A$6:$A$38,0)),0)+IFERROR(INDEX(Feb!AL$6:AL$38,MATCH($A12,Feb!$A$6:$A$38,0)),0)+IFERROR(INDEX(Mar!AL$6:AL$38,MATCH($A12,Mar!$A$6:$A$38,0)),0)+IFERROR(INDEX(Apr!AL$6:AL$38,MATCH($A12,Apr!$A$6:$A$38,0)),0)+IFERROR(INDEX(May!AL$6:AL$38,MATCH($A12,May!$A$6:$A$38,0)),0)+IFERROR(INDEX(Jun!AL$6:AL$38,MATCH($A12,Jun!$A$6:$A$38,0)),0)+IFERROR(INDEX(Jul!AL$6:AL$38,MATCH($A12,Jul!$A$6:$A$38,0)),0)} -> 0 | H12: {=IFERROR(INDEX(Aug!AM$6:AM$38,MATCH($A12,Aug!$A$6:$A$38,0)),0)+IFERROR(INDEX(Sep!AM$6:AM$38,MATCH($A12,Sep!$A$6:$A$38,0)),0)+IFERROR(INDEX(Oct!AM$6:AM$38,MATCH($A12,Oct!$A$6:$A$38,0)),0)+IFERROR(INDEX(Nov!AM$6:AM$38,MATCH($A12,Nov!$A$6:$A$38,0)),0)+IFERROR(INDEX(Dec!AM$6:AM$38,MATCH($A12,Dec!$A$6:$A$38,0)),0)+IFERROR(INDEX(Jan!AM$6:AM$38,MATCH($A12,Jan!$A$6:$A$38,0)),0)+IFERROR(INDEX(Feb!AM$6:AM$38,MATCH($A12,Feb!$A$6:$A$38,0)),0)+IFERROR(INDEX(Mar!AM$6:AM$38,MATCH($A12,Mar!$A$6:$A$38,0)),0)+IFERROR(INDEX(Apr!AM$6:AM$38,MATCH($A12,Apr!$A$6:$A$38,0)),0)+IFERROR(INDEX(May!AM$6:AM$38,MATCH($A12,May!$A$6:$A$38,0)),0)+IFERROR(INDEX(Jun!AM$6:AM$38,MATCH($A12,Jun!$A$6:$A$38,0)),0)+IFERROR(INDEX(Jul!AM$6:AM$38,MATCH($A12,Jul!$A$6:$A$38,0)),0)} -> 0 | I12: =SUM(C12:H12) -> 0 | K12: STEP 4: Use Monthly worksheets to Enter Leave
A13: 5 | B13: Name 5 | C13: {=IFERROR(INDEX(Aug!AH$6:AH$38,MATCH($A13,Aug!$A$6:$A$38,0)),0)+IFERROR(INDEX(Sep!AH$6:AH$38,MATCH($A13,Sep!$A$6:$A$38,0)),0)+IFERROR(INDEX(Oct!AH$6:AH$38,MATCH($A13,Oct!$A$6:$A$38,0)),0)+IFERROR(INDEX(Nov!AH$6:AH$38,MATCH($A13,Nov!$A$6:$A$38,0)),0)+IFERROR(INDEX(Dec!AH$6:AH$38,MATCH($A13,Dec!$A$6:$A$38,0)),0)+IFERROR(INDEX(Jan!AH$6:AH$38,MATCH($A13,Jan!$A$6:$A$38,0)),0)+IFERROR(INDEX(Feb!AH$6:AH$38,MATCH($A13,Feb!$A$6:$A$38,0)),0)+IFERROR(INDEX(Mar!AH$6:AH$38,MATCH($A13,Mar!$A$6:$A$38,0)),0)+IFERROR(INDEX(Apr!AH$6:AH$38,MATCH($A13,Apr!$A$6:$A$38,0)),0)+IFERROR(INDEX(May!AH$6:AH$38,MATCH($A13,May!$A$6:$A$38,0)),0)+IFERROR(INDEX(Jun!AH$6:AH$38,MATCH($A13,Jun!$A$6:$A$38,0)),0)+IFERROR(INDEX(Jul!AH$6:AH$38,MATCH($A13,Jul!$A$6:$A$38,0)),0)} -> 0 | D13: {=IFERROR(INDEX(Aug!AI$6:AI$38,MATCH($A13,Aug!$A$6:$A$38,0)),0)+IFERROR(INDEX(Sep!AI$6:AI$38,MATCH($A13,Sep!$A$6:$A$38,0)),0)+IFERROR(INDEX(Oct!AI$6:AI$38,MATCH($A13,Oct!$A$6:$A$38,0)),0)+IFERROR(INDEX(Nov!AI$6:AI$38,MATCH($A13,Nov!$A$6:$A$38,0)),0)+IFERROR(INDEX(Dec!AI$6:AI$38,MATCH($A13,Dec!$A$6:$A$38,0)),0)+IFERROR(INDEX(Jan!AI$6:AI$38,MATCH($A13,Jan!$A$6:$A$38,0)),0)+IFERROR(INDEX(Feb!AI$6:AI$38,MATCH($A13,Feb!$A$6:$A$38,0)),0)+IFERROR(INDEX(Mar!AI$6:AI$38,MATCH($A13,Mar!$A$6:$A$38,0)),0)+IFERROR(INDEX(Apr!AI$6:AI$38,MATCH($A13,Apr!$A$6:$A$38,0)),0)+IFERROR(INDEX(May!AI$6:AI$38,MATCH($A13,May!$A$6:$A$38,0)),0)+IFERROR(INDEX(Jun!AI$6:AI$38,MATCH($A13,Jun!$A$6:$A$38,0)),0)+IFERROR(INDEX(Jul!AI$6:AI$38,MATCH($A13,Jul!$A$6:$A$38,0)),0)} -> 0 | E13: {=IFERROR(INDEX(Aug!AJ$6:AJ$38,MATCH($A13,Aug!$A$6:$A$38,0)),0)+IFERROR(INDEX(Sep!AJ$6:AJ$38,MATCH($A13,Sep!$A$6:$A$38,0)),0)+IFERROR(INDEX(Oct!AJ$6:AJ$38,MATCH($A13,Oct!$A$6:$A$38,0)),0)+IFERROR(INDEX(Nov!AJ$6:AJ$38,MATCH($A13,Nov!$A$6:$A$38,0)),0)+IFERROR(INDEX(Dec!AJ$6:AJ$38,MATCH($A13,Dec!$A$6:$A$38,0)),0)+IFERROR(INDEX(Jan!AJ$6:AJ$38,MATCH($A13,Jan!$A$6:$A$38,0)),0)+IFERROR(INDEX(Feb!AJ$6:AJ$38,MATCH($A13,Feb!$A$6:$A$38,0)),0)+IFERROR(INDEX(Mar!AJ$6:AJ$38,MATCH($A13,Mar!$A$6:$A$38,0)),0)+IFERROR(INDEX(Apr!AJ$6:AJ$38,MATCH($A13,Apr!$A$6:$A$38,0)),0)+IFERROR(INDEX(May!AJ$6:AJ$38,MATCH($A13,May!$A$6:$A$38,0)),0)+IFERROR(INDEX(Jun!AJ$6:AJ$38,MATCH($A13,Jun!$A$6:$A$38,0)),0)+IFERROR(INDEX(Jul!AJ$6:AJ$38,MATCH($A13,Jul!$A$6:$A$38,0)),0)} -> 0 | F13: {=IFERROR(INDEX(Aug!AK$6:AK$38,MATCH($A13,Aug!$A$6:$A$38,0)),0)+IFERROR(INDEX(Sep!AK$6:AK$38,MATCH($A13,Sep!$A$6:$A$38,0)),0)+IFERROR(INDEX(Oct!AK$6:AK$38,MATCH($A13,Oct!$A$6:$A$38,0)),0)+IFERROR(INDEX(Nov!AK$6:AK$38,MATCH($A13,Nov!$A$6:$A$38,0)),0)+IFERROR(INDEX(Dec!AK$6:AK$38,MATCH($A13,Dec!$A$6:$A$38,0)),0)+IFERROR(INDEX(Jan!AK$6:AK$38,MATCH($A13,Jan!$A$6:$A$38,0)),0)+IFERROR(INDEX(Feb!AK$6:AK$38,MATCH($A13,Feb!$A$6:$A$38,0)),0)+IFERROR(INDEX(Mar!AK$6:AK$38,MATCH($A13,Mar!$A$6:$A$38,0)),0)+IFERROR(INDEX(Apr!AK$6:AK$38,MATCH($A13,Apr!$A$6:$A$38,0)),0)+IFERROR(INDEX(May!AK$6:AK$38,MATCH($A13,May!$A$6:$A$38,0)),0)+IFERROR(INDEX(Jun!AK$6:AK$38,MATCH($A13,Jun!$A$6:$A$38,0)),0)+IFERROR(INDEX(Jul!AK$6:AK$38,MATCH($A13,Jul!$A$6:$A$38,0)),0)} -> 0 | G13: {=IFERROR(INDEX(Aug!AL$6:AL$38,MATCH($A13,Aug!$A$6:$A$38,0)),0)+IFERROR(INDEX(Sep!AL$6:AL$38,MATCH($A13,Sep!$A$6:$A$38,0)),0)+IFERROR(INDEX(Oct!AL$6:AL$38,MATCH($A13,Oct!$A$6:$A$38,0)),0)+IFERROR(INDEX(Nov!AL$6:AL$38,MATCH($A13,Nov!$A$6:$A$38,0)),0)+IFERROR(INDEX(Dec!AL$6:AL$38,MATCH($A13,Dec!$A$6:$A$38,0)),0)+IFERROR(INDEX(Jan!AL$6:AL$38,MATCH($A13,Jan!$A$6:$A$38,0)),0)+IFERROR(INDEX(Feb!AL$6:AL$38,MATCH($A13,Feb!$A$6:$A$38,0)),0)+IFERROR(INDEX(Mar!AL$6:AL$38,MATCH($A13,Mar!$A$6:$A$38,0)),0)+IFERROR(INDEX(Apr!AL$6:AL$38,MATCH($A13,Apr!$A$6:$A$38,0)),0)+IFERROR(INDEX(May!AL$6:AL$38,MATCH($A13,May!$A$6:$A$38,0)),0)+IFERROR(INDEX(Jun!AL$6:AL$38,MATCH($A13,Jun!$A$6:$A$38,0)),0)+IFERROR(INDEX(Jul!AL$6:AL$38,MATCH($A13,Jul!$A$6:$A$38,0)),0)} -> 0 | H13: {=IFERROR(INDEX(Aug!AM$6:AM$38,MATCH($A13,Aug!$A$6:$A$38,0)),0)+IFERROR(INDEX(Sep!AM$6:AM$38,MATCH($A13,Sep!$A$6:$A$38,0)),0)+IFERROR(INDEX(Oct!AM$6:AM$38,MATCH($A13,Oct!$A$6:$A$38,0)),0)+IFERROR(INDEX(Nov!AM$6:AM$38,MATCH($A13,Nov!$A$6:$A$38,0)),0)+IFERROR(INDEX(Dec!AM$6:AM$38,MATCH($A13,Dec!$A$6:$A$38,0)),0)+IFERROR(INDEX(Jan!AM$6:AM$38,MATCH($A13,Jan!$A$6:$A$38,0)),0)+IFERROR(INDEX(Feb!AM$6:AM$38,MATCH($A13,Feb!$A$6:$A$38,0)),0)+IFERROR(INDEX(Mar!AM$6:AM$38,MATCH($A13,Mar!$A$6:$A$38,0)),0)+IFERROR(INDEX(Apr!AM$6:AM$38,MATCH($A13,Apr!$A$6:$A$38,0)),0)+IFERROR(INDEX(May!AM$6:AM$38,MATCH($A13,May!$A$6:$A$38,0)),0)+IFERROR(INDEX(Jun!AM$6:AM$38,MATCH($A13,Jun!$A$6:$A$38,0)),0)+IFERROR(INDEX(Jul!AM$6:AM$38,MATCH($A13,Jul!$A$6:$A$38,0)),0)} -> 18 | I13: =SUM(C13:H13) -> 18
A14: 6 | C14: {=IFERROR(INDEX(Aug!AH$6:AH$38,MATCH($A14,Aug!$A$6:$A$38,0)),0)+IFERROR(INDEX(Sep!AH$6:AH$38,MATCH($A14,Sep!$A$6:$A$38,0)),0)+IFERROR(INDEX(Oct!AH$6:AH$38,MATCH($A14,Oct!$A$6:$A$38,0)),0)+IFERROR(INDEX(Nov!AH$6:AH$38,MATCH($A14,Nov!$A$6:$A$38,0)),0)+IFERROR(INDEX(Dec!AH$6:AH$38,MATCH($A14,Dec!$A$6:$A$38,0)),0)+IFERROR(INDEX(Jan!AH$6:AH$38,MATCH($A14,Jan!$A$6:$A$38,0)),0)+IFERROR(INDEX(Feb!AH$6:AH$38,MATCH($A14,Feb!$A$6:$A$38,0)),0)+IFERROR(INDEX(Mar!AH$6:AH$38,MATCH($A14,Mar!$A$6:$A$38,0)),0)+IFERROR(INDEX(Apr!AH$6:AH$38,MATCH($A14,Apr!$A$6:$A$38,0)),0)+IFERROR(INDEX(May!AH$6:AH$38,MATCH($A14,May!$A$6:$A$38,0)),0)+IFERROR(INDEX(Jun!AH$6:AH$38,MATCH($A14,Jun!$A$6:$A$38,0)),0)+IFERROR(INDEX(Jul!AH$6:AH$38,MATCH($A14,Jul!$A$6:$A$38,0)),0)} -> 0 | D14: {=IFERROR(INDEX(Aug!AI$6:AI$38,MATCH($A14,Aug!$A$6:$A$38,0)),0)+IFERROR(INDEX(Sep!AI$6:AI$38,MATCH($A14,Sep!$A$6:$A$38,0)),0)+IFERROR(INDEX(Oct!AI$6:AI$38,MATCH($A14,Oct!$A$6:$A$38,0)),0)+IFERROR(INDEX(Nov!AI$6:AI$38,MATCH($A14,Nov!$A$6:$A$38,0)),0)+IFERROR(INDEX(Dec!AI$6:AI$38,MATCH($A14,Dec!$A$6:$A$38,0)),0)+IFERROR(INDEX(Jan!AI$6:AI$38,MATCH($A14,Jan!$A$6:$A$38,0)),0)+IFERROR(INDEX(Feb!AI$6:AI$38,MATCH($A14,Feb!$A$6:$A$38,0)),0)+IFERROR(INDEX(Mar!AI$6:AI$38,MATCH($A14,Mar!$A$6:$A$38,0)),0)+IFERROR(INDEX(Apr!AI$6:AI$38,MATCH($A14,Apr!$A$6:$A$38,0)),0)+IFERROR(INDEX(May!AI$6:AI$38,MATCH($A14,May!$A$6:$A$38,0)),0)+IFERROR(INDEX(Jun!AI$6:AI$38,MATCH($A14,Jun!$A$6:$A$38,0)),0)+IFERROR(INDEX(Jul!AI$6:AI$38,MATCH($A14,Jul!$A$6:$A$38,0)),0)} -> 0 | E14: {=IFERROR(INDEX(Aug!AJ$6:AJ$38,MATCH($A14,Aug!$A$6:$A$38,0)),0)+IFERROR(INDEX(Sep!AJ$6:AJ$38,MATCH($A14,Sep!$A$6:$A$38,0)),0)+IFERROR(INDEX(Oct!AJ$6:AJ$38,MATCH($A14,Oct!$A$6:$A$38,0)),0)+IFERROR(INDEX(Nov!AJ$6:AJ$38,MATCH($A14,Nov!$A$6:$A$38,0)),0)+IFERROR(INDEX(Dec!AJ$6:AJ$38,MATCH($A14,Dec!$A$6:$A$38,0)),0)+IFERROR(INDEX(Jan!AJ$6:AJ$38,MATCH($A14,Jan!$A$6:$A$38,0)),0)+IFERROR(INDEX(Feb!AJ$6:AJ$38,MATCH($A14,Feb!$A$6:$A$38,0)),0)+IFERROR(INDEX(Mar!AJ$6:AJ$38,MATCH($A14,Mar!$A$6:$A$38,0)),0)+IFERROR(INDEX(Apr!AJ$6:AJ$38,MATCH($A14,Apr!$A$6:$A$38,0)),0)+IFERROR(INDEX(May!AJ$6:AJ$38,MATCH($A14,May!$A$6:$A$38,0)),0)+IFERROR(INDEX(Jun!AJ$6:AJ$38,MATCH($A14,Jun!$A$6:$A$38,0)),0)+IFERROR(INDEX(Jul!AJ$6:AJ$38,MATCH($A14,Jul!$A$6:$A$38,0)),0)} -> 0 | F14: {=IFERROR(INDEX(Aug!AK$6:AK$38,MATCH($A14,Aug!$A$6:$A$38,0)),0)+IFERROR(INDEX(Sep!AK$6:AK$38,MATCH($A14,Sep!$A$6:$A$38,0)),0)+IFERROR(INDEX(Oct!AK$6:AK$38,MATCH($A14,Oct!$A$6:$A$38,0)),0)+IFERROR(INDEX(Nov!AK$6:AK$38,MATCH($A14,Nov!$A$6:$A$38,0)),0)+IFERROR(INDEX(Dec!AK$6:AK$38,MATCH($A14,Dec!$A$6:$A$38,0)),0)+IFERROR(INDEX(Jan!AK$6:AK$38,MATCH($A14,Jan!$A$6:$A$38,0)),0)+IFERROR(INDEX(Feb!AK$6:AK$38,MATCH($A14,Feb!$A$6:$A$38,0)),0)+IFERROR(INDEX(Mar!AK$6:AK$38,MATCH($A14,Mar!$A$6:$A$38,0)),0)+IFERROR(INDEX(Apr!AK$6:AK$38,MATCH($A14,Apr!$A$6:$A$38,0)),0)+IFERROR(INDEX(May!AK$6:AK$38,MATCH($A14,May!$A$6:$A$38,0)),0)+IFERROR(INDEX(Jun!AK$6:AK$38,MATCH($A14,Jun!$A$6:$A$38,0)),0)+IFERROR(INDEX(Jul!AK$6:AK$38,MATCH($A14,Jul!$A$6:$A$38,0)),0)} -> 0 | G14: {=IFERROR(INDEX(Aug!AL$6:AL$38,MATCH($A14,Aug!$A$6:$A$38,0)),0)+IFERROR(INDEX(Sep!AL$6:AL$38,MATCH($A14,Sep!$A$6:$A$38,0)),0)+IFERROR(INDEX(Oct!AL$6:AL$38,MATCH($A14,Oct!$A$6:$A$38,0)),0)+IFERROR(INDEX(Nov!AL$6:AL$38,MATCH($A14,Nov!$A$6:$A$38,0)),0)+IFERROR(INDEX(Dec!AL$6:AL$38,MATCH($A14,Dec!$A$6:$A$38,0)),0)+IFERROR(INDEX(Jan!AL$6:AL$38,MATCH($A14,Jan!$A$6:$A$38,0)),0)+IFERROR(INDEX(Feb!AL$6:AL$38,MATCH($A14,Feb!$A$6:$A$38,0)),0)+IFERROR(INDEX(Mar!AL$6:AL$38,MATCH($A14,Mar!$A$6:$A$38,0)),0)+IFERROR(INDEX(Apr!AL$6:AL$38,MATCH($A14,Apr!$A$6:$A$38,0)),0)+IFERROR(INDEX(May!AL$6:AL$38,MATCH($A14,May!$A$6:$A$38,0)),0)+IFERROR(INDEX(Jun!AL$6:AL$38,MATCH($A14,Jun!$A$6:$A$38,0)),0)+IFERROR(INDEX(Jul!AL$6:AL$38,MATCH($A14,Jul!$A$6:$A$38,0)),0)} -> 0 | H14: {=IFERROR(INDEX(Aug!AM$6:AM$38,MATCH($A14,Aug!$A$6:$A$38,0)),0)+IFERROR(INDEX(Sep!AM$6:AM$38,MATCH($A14,Sep!$A$6:$A$38,0)),0)+IFERROR(INDEX(Oct!AM$6:AM$38,MATCH($A14,Oct!$A$6:$A$38,0)),0)+IFERROR(INDEX(Nov!AM$6:AM$38,MATCH($A14,Nov!$A$6:$A$38,0)),0)+IFERROR(INDEX(Dec!AM$6:AM$38,MATCH($A14,Dec!$A$6:$A$38,0)),0)+IFERROR(INDEX(Jan!AM$6:AM$38,MATCH($A14,Jan!$A$6:$A$38,0)),0)+IFERROR(INDEX(Feb!AM$6:AM$38,MATCH($A14,Feb!$A$6:$A$38,0)),0)+IFERROR(INDEX(Mar!AM$6:AM$38,MATCH($A14,Mar!$A$6:$A$38,0)),0)+IFERROR(INDEX(Apr!AM$6:AM$38,MATCH($A14,Apr!$A$6:$A$38,0)),0)+IFERROR(INDEX(May!AM$6:AM$38,MATCH($A14,May!$A$6:$A$38,0)),0)+IFERROR(INDEX(Jun!AM$6:AM$38,MATCH($A14,Jun!$A$6:$A$38,0)),0)+IFERROR(INDEX(Jul!AM$6:AM$38,MATCH($A14,Jul!$A$6:$A$38,0)),0)} -> 0 | I14: =SUM(C14:H14) -> 0 | K14: The Year Totals use lookup functions based on the employee ID.
A15: 7 | C15: {=IFERROR(INDEX(Aug!AH$6:AH$38,MATCH($A15,Aug!$A$6:$A$38,0)),0)+IFERROR(INDEX(Sep!AH$6:AH$38,MATCH($A15,Sep!$A$6:$A$38,0)),0)+IFERROR(INDEX(Oct!AH$6:AH$38,MATCH($A15,Oct!$A$6:$A$38,0)),0)+IFERROR(INDEX(Nov!AH$6:AH$38,MATCH($A15,Nov!$A$6:$A$38,0)),0)+IFERROR(INDEX(Dec!AH$6:AH$38,MATCH($A15,Dec!$A$6:$A$38,0)),0)+IFERROR(INDEX(Jan!AH$6:AH$38,MATCH($A15,Jan!$A$6:$A$38,0)),0)+IFERROR(INDEX(Feb!AH$6:AH$38,MATCH($A15,Feb!$A$6:$A$38,0)),0)+IFERROR(INDEX(Mar!AH$6:AH$38,MATCH($A15,Mar!$A$6:$A$38,0)),0)+IFERROR(INDEX(Apr!AH$6:AH$38,MATCH($A15,Apr!$A$6:$A$38,0)),0)+IFERROR(INDEX(May!AH$6:AH$38,MATCH($A15,May!$A$6:$A$38,0)),0)+IFERROR(INDEX(Jun!AH$6:AH$38,MATCH($A15,Jun!$A$6:$A$38,0)),0)+IFERROR(INDEX(Jul!AH$6:AH$38,MATCH($A15,Jul!$A$6:$A$38,0)),0)} -> 0 | D15: {=IFERROR(INDEX(Aug!AI$6:AI$38,MATCH($A15,Aug!$A$6:$A$38,0)),0)+IFERROR(INDEX(Sep!AI$6:AI$38,MATCH($A15,Sep!$A$6:$A$38,0)),0)+IFERROR(INDEX(Oct!AI$6:AI$38,MATCH($A15,Oct!$A$6:$A$38,0)),0)+IFERROR(INDEX(Nov!AI$6:AI$38,MATCH($A15,Nov!$A$6:$A$38,0)),0)+IFERROR(INDEX(Dec!AI$6:AI$38,MATCH($A15,Dec!$A$6:$A$38,0)),0)+IFERROR(INDEX(Jan!AI$6:AI$38,MATCH($A15,Jan!$A$6:$A$38,0)),0)+IFERROR(INDEX(Feb!AI$6:AI$38,MATCH($A15,Feb!$A$6:$A$38,0)),0)+IFERROR(INDEX(Mar!AI$6:AI$38,MATCH($A15,Mar!$A$6:$A$38,0)),0)+IFERROR(INDEX(Apr!AI$6:AI$38,MATCH($A15,Apr!$A$6:$A$38,0)),0)+IFERROR(INDEX(May!AI$6:AI$38,MATCH($A15,May!$A$6:$A$38,0)),0)+IFERROR(INDEX(Jun!AI$6:AI$38,MATCH($A15,Jun!$A$6:$A$38,0)),0)+IFERROR(INDEX(Jul!AI$6:AI$38,MATCH($A15,Jul!$A$6:$A$38,0)),0)} -> 0 | E15: {=IFERROR(INDEX(Aug!AJ$6:AJ$38,MATCH($A15,Aug!$A$6:$A$38,0)),0)+IFERROR(INDEX(Sep!AJ$6:AJ$38,MATCH($A15,Sep!$A$6:$A$38,0)),0)+IFERROR(INDEX(Oct!AJ$6:AJ$38,MATCH($A15,Oct!$A$6:$A$38,0)),0)+IFERROR(INDEX(Nov!AJ$6:AJ$38,MATCH($A15,Nov!$A$6:$A$38,0)),0)+IFERROR(INDEX(Dec!AJ$6:AJ$38,MATCH($A15,Dec!$A$6:$A$38,0)),0)+IFERROR(INDEX(Jan!AJ$6:AJ$38,MATCH($A15,Jan!$A$6:$A$38,0)),0)+IFERROR(INDEX(Feb!AJ$6:AJ$38,MATCH($A15,Feb!$A$6:$A$38,0)),0)+IFERROR(INDEX(Mar!AJ$6:AJ$38,MATCH($A15,Mar!$A$6:$A$38,0)),0)+IFERROR(INDEX(Apr!AJ$6:AJ$38,MATCH($A15,Apr!$A$6:$A$38,0)),0)+IFERROR(INDEX(May!AJ$6:AJ$38,MATCH($A15,May!$A$6:$A$38,0)),0)+IFERROR(INDEX(Jun!AJ$6:AJ$38,MATCH($A15,Jun!$A$6:$A$38,0)),0)+IFERROR(INDEX(Jul!AJ$6:AJ$38,MATCH($A15,Jul!$A$6:$A$38,0)),0)} -> 0 | F15: {=IFERROR(INDEX(Aug!AK$6:AK$38,MATCH($A15,Aug!$A$6:$A$38,0)),0)+IFERROR(INDEX(Sep!AK$6:AK$38,MATCH($A15,Sep!$A$6:$A$38,0)),0)+IFERROR(INDEX(Oct!AK$6:AK$38,MATCH($A15,Oct!$A$6:$A$38,0)),0)+IFERROR(INDEX(Nov!AK$6:AK$38,MATCH($A15,Nov!$A$6:$A$38,0)),0)+IFERROR(INDEX(Dec!AK$6:AK$38,MATCH($A15,Dec!$A$6:$A$38,0)),0)+IFERROR(INDEX(Jan!AK$6:AK$38,MATCH($A15,Jan!$A$6:$A$38,0)),0)+IFERROR(INDEX(Feb!AK$6:AK$38,MATCH($A15,Feb!$A$6:$A$38,0)),0)+IFERROR(INDEX(Mar!AK$6:AK$38,MATCH($A15,Mar!$A$6:$A$38,0)),0)+IFERROR(INDEX(Apr!AK$6:AK$38,MATCH($A15,Apr!$A$6:$A$38,0)),0)+IFERROR(INDEX(May!AK$6:AK$38,MATCH($A15,May!$A$6:$A$38,0)),0)+IFERROR(INDEX(Jun!AK$6:AK$38,MATCH($A15,Jun!$A$6:$A$38,0)),0)+IFERROR(INDEX(Jul!AK$6:AK$38,MATCH($A15,Jul!$A$6:$A$38,0)),0)} -> 0 | G15: {=IFERROR(INDEX(Aug!AL$6:AL$38,MATCH($A15,Aug!$A$6:$A$38,0)),0)+IFERROR(INDEX(Sep!AL$6:AL$38,MATCH($A15,Sep!$A$6:$A$38,0)),0)+IFERROR(INDEX(Oct!AL$6:AL$38,MATCH($A15,Oct!$A$6:$A$38,0)),0)+IFERROR(INDEX(Nov!AL$6:AL$38,MATCH($A15,Nov!$A$6:$A$38,0)),0)+IFERROR(INDEX(Dec!AL$6:AL$38,MATCH($A15,Dec!$A$6:$A$38,0)),0)+IFERROR(INDEX(Jan!AL$6:AL$38,MATCH($A15,Jan!$A$6:$A$38,0)),0)+IFERROR(INDEX(Feb!AL$6:AL$38,MATCH($A15,Feb!$A$6:$A$38,0)),0)+IFERROR(INDEX(Mar!AL$6:AL$38,MATCH($A15,Mar!$A$6:$A$38,0)),0)+IFERROR(INDEX(Apr!AL$6:AL$38,MATCH($A15,Apr!$A$6:$A$38,0)),0)+IFERROR(INDEX(May!AL$6:AL$38,MATCH($A15,May!$A$6:$A$38,0)),0)+IFERROR(INDEX(Jun!AL$6:AL$38,MATCH($A15,Jun!$A$6:$A$38,0)),0)+IFERROR(INDEX(Jul!AL$6:AL$38,MATCH($A15,Jul!$A$6:$A$38,0)),0)} -> 0 | H15: {=IFERROR(INDEX(Aug!AM$6:AM$38,MATCH($A15,Aug!$A$6:$A$38,0)),0)+IFERROR(INDEX(Sep!AM$6:AM$38,MATCH($A15,Sep!$A$6:$A$38,0)),0)+IFERROR(INDEX(Oct!AM$6:AM$38,MATCH($A15,Oct!$A$6:$A$38,0)),0)+IFERROR(INDEX(Nov!AM$6:AM$38,MATCH($A15,Nov!$A$6:$A$38,0)),0)+IFERROR(INDEX(Dec!AM$6:AM$38,MATCH($A15,Dec!$A$6:$A$38,0)),0)+IFERROR(INDEX(Jan!AM$6:AM$38,MATCH($A15,Jan!$A$6:$A$38,0)),0)+IFERROR(INDEX(Feb!AM$6:AM$38,MATCH($A15,Feb!$A$6:$A$38,0)),0)+IFERROR(INDEX(Mar!AM$6:AM$38,MATCH($A15,Mar!$A$6:$A$38,0)),0)+IFERROR(INDEX(Apr!AM$6:AM$38,MATCH($A15,Apr!$A$6:$A$38,0)),0)+IFERROR(INDEX(May!AM$6:AM$38,MATCH($A15,May!$A$6:$A$38,0)),0)+IFERROR(INDEX(Jun!AM$6:AM$38,MATCH($A15,Jun!$A$6:$A$38,0)),0)+IFERROR(INDEX(Jul!AM$6:AM$38,MATCH($A15,Jul!$A$6:$A$38,0)),0)} -> 0 | I15: =SUM(C15:H15) -> 0 | K15: Make sure the employee IDs are unique.
A16: 8 | C16: {=IFERROR(INDEX(Aug!AH$6:AH$38,MATCH($A16,Aug!$A$6:$A$38,0)),0)+IFERROR(INDEX(Sep!AH$6:AH$38,MATCH($A16,Sep!$A$6:$A$38,0)),0)+IFERROR(INDEX(Oct!AH$6:AH$38,MATCH($A16,Oct!$A$6:$A$38,0)),0)+IFERROR(INDEX(Nov!AH$6:AH$38,MATCH($A16,Nov!$A$6:$A$38,0)),0)+IFERROR(INDEX(Dec!AH$6:AH$38,MATCH($A16,Dec!$A$6:$A$38,0)),0)+IFERROR(INDEX(Jan!AH$6:AH$38,MATCH($A16,Jan!$A$6:$A$38,0)),0)+IFERROR(INDEX(Feb!AH$6:AH$38,MATCH($A16,Feb!$A$6:$A$38,0)),0)+IFERROR(INDEX(Mar!AH$6:AH$38,MATCH($A16,Mar!$A$6:$A$38,0)),0)+IFERROR(INDEX(Apr!AH$6:AH$38,MATCH($A16,Apr!$A$6:$A$38,0)),0)+IFERROR(INDEX(May!AH$6:AH$38,MATCH($A16,May!$A$6:$A$38,0)),0)+IFERROR(INDEX(Jun!AH$6:AH$38,MATCH($A16,Jun!$A$6:$A$38,0)),0)+IFERROR(INDEX(Jul!AH$6:AH$38,MATCH($A16,Jul!$A$6:$A$38,0)),0)} -> 0 | D16: {=IFERROR(INDEX(Aug!AI$6:AI$38,MATCH($A16,Aug!$A$6:$A$38,0)),0)+IFERROR(INDEX(Sep!AI$6:AI$38,MATCH($A16,Sep!$A$6:$A$38,0)),0)+IFERROR(INDEX(Oct!AI$6:AI$38,MATCH($A16,Oct!$A$6:$A$38,0)),0)+IFERROR(INDEX(Nov!AI$6:AI$38,MATCH($A16,Nov!$A$6:$A$38,0)),0)+IFERROR(INDEX(Dec!AI$6:AI$38,MATCH($A16,Dec!$A$6:$A$38,0)),0)+IFERROR(INDEX(Jan!AI$6:AI$38,MATCH($A16,Jan!$A$6:$A$38,0)),0)+IFERROR(INDEX(Feb!AI$6:AI$38,MATCH($A16,Feb!$A$6:$A$38,0)),0)+IFERROR(INDEX(Mar!AI$6:AI$38,MATCH($A16,Mar!$A$6:$A$38,0)),0)+IFERROR(INDEX(Apr!AI$6:AI$38,MATCH($A16,Apr!$A$6:$A$38,0)),0)+IFERROR(INDEX(May!AI$6:AI$38,MATCH($A16,May!$A$6:$A$38,0)),0)+IFERROR(INDEX(Jun!AI$6:AI$38,MATCH($A16,Jun!$A$6:$A$38,0)),0)+IFERROR(INDEX(Jul!AI$6:AI$38,MATCH($A16,Jul!$A$6:$A$38,0)),0)} -> 0 | E16: {=IFERROR(INDEX(Aug!AJ$6:AJ$38,MATCH($A16,Aug!$A$6:$A$38,0)),0)+IFERROR(INDEX(Sep!AJ$6:AJ$38,MATCH($A16,Sep!$A$6:$A$38,0)),0)+IFERROR(INDEX(Oct!AJ$6:AJ$38,MATCH($A16,Oct!$A$6:$A$38,0)),0)+IFERROR(INDEX(Nov!AJ$6:AJ$38,MATCH($A16,Nov!$A$6:$A$38,0)),0)+IFERROR(INDEX(Dec!AJ$6:AJ$38,MATCH($A16,Dec!$A$6:$A$38,0)),0)+IFERROR(INDEX(Jan!AJ$6:AJ$38,MATCH($A16,Jan!$A$6:$A$38,0)),0)+IFERROR(INDEX(Feb!AJ$6:AJ$38,MATCH($A16,Feb!$A$6:$A$38,0)),0)+IFERROR(INDEX(Mar!AJ$6:AJ$38,MATCH($A16,Mar!$A$6:$A$38,0)),0)+IFERROR(INDEX(Apr!AJ$6:AJ$38,MATCH($A16,Apr!$A$6:$A$38,0)),0)+IFERROR(INDEX(May!AJ$6:AJ$38,MATCH($A16,May!$A$6:$A$38,0)),0)+IFERROR(INDEX(Jun!AJ$6:AJ$38,MATCH($A16,Jun!$A$6:$A$38,0)),0)+IFERROR(INDEX(Jul!AJ$6:AJ$38,MATCH($A16,Jul!$A$6:$A$38,0)),0)} -> 0 | F16: {=IFERROR(INDEX(Aug!AK$6:AK$38,MATCH($A16,Aug!$A$6:$A$38,0)),0)+IFERROR(INDEX(Sep!AK$6:AK$38,MATCH($A16,Sep!$A$6:$A$38,0)),0)+IFERROR(INDEX(Oct!AK$6:AK$38,MATCH($A16,Oct!$A$6:$A$38,0)),0)+IFERROR(INDEX(Nov!AK$6:AK$38,MATCH($A16,Nov!$A$6:$A$38,0)),0)+IFERROR(INDEX(Dec!AK$6:AK$38,MATCH($A16,Dec!$A$6:$A$38,0)),0)+IFERROR(INDEX(Jan!AK$6:AK$38,MATCH($A16,Jan!$A$6:$A$38,0)),0)+IFERROR(INDEX(Feb!AK$6:AK$38,MATCH($A16,Feb!$A$6:$A$38,0)),0)+IFERROR(INDEX(Mar!AK$6:AK$38,MATCH($A16,Mar!$A$6:$A$38,0)),0)+IFERROR(INDEX(Apr!AK$6:AK$38,MATCH($A16,Apr!$A$6:$A$38,0)),0)+IFERROR(INDEX(May!AK$6:AK$38,MATCH($A16,May!$A$6:$A$38,0)),0)+IFERROR(INDEX(Jun!AK$6:AK$38,MATCH($A16,Jun!$A$6:$A$38,0)),0)+IFERROR(INDEX(Jul!AK$6:AK$38,MATCH($A16,Jul!$A$6:$A$38,0)),0)} -> 0 | G16: {=IFERROR(INDEX(Aug!AL$6:AL$38,MATCH($A16,Aug!$A$6:$A$38,0)),0)+IFERROR(INDEX(Sep!AL$6:AL$38,MATCH($A16,Sep!$A$6:$A$38,0)),0)+IFERROR(INDEX(Oct!AL$6:AL$38,MATCH($A16,Oct!$A$6:$A$38,0)),0)+IFERROR(INDEX(Nov!AL$6:AL$38,MATCH($A16,Nov!$A$6:$A$38,0)),0)+IFERROR(INDEX(Dec!AL$6:AL$38,MATCH($A16,Dec!$A$6:$A$38,0)),0)+IFERROR(INDEX(Jan!AL$6:AL$38,MATCH($A16,Jan!$A$6:$A$38,0)),0)+IFERROR(INDEX(Feb!AL$6:AL$38,MATCH($A16,Feb!$A$6:$A$38,0)),0)+IFERROR(INDEX(Mar!AL$6:AL$38,MATCH($A16,Mar!$A$6:$A$38,0)),0)+IFERROR(INDEX(Apr!AL$6:AL$38,MATCH($A16,Apr!$A$6:$A$38,0)),0)+IFERROR(INDEX(May!AL$6:AL$38,MATCH($A16,May!$A$6:$A$38,0)),0)+IFERROR(INDEX(Jun!AL$6:AL$38,MATCH($A16,Jun!$A$6:$A$38,0)),0)+IFERROR(INDEX(Jul!AL$6:AL$38,MATCH($A16,Jul!$A$6:$A$38,0)),0)} -> 0 | H16: {=IFERROR(INDEX(Aug!AM$6:AM$38,MATCH($A16,Aug!$A$6:$A$38,0)),0)+IFERROR(INDEX(Sep!AM$6:AM$38,MATCH($A16,Sep!$A$6:$A$38,0)),0)+IFERROR(INDEX(Oct!AM$6:AM$38,MATCH($A16,Oct!$A$6:$A$38,0)),0)+IFERROR(INDEX(Nov!AM$6:AM$38,MATCH($A16,Nov!$A$6:$A$38,0)),0)+IFERROR(INDEX(Dec!AM$6:AM$38,MATCH($A16,Dec!$A$6:$A$38,0)),0)+IFERROR(INDEX(Jan!AM$6:AM$38,MATCH($A16,Jan!$A$6:$A$38,0)),0)+IFERROR(INDEX(Feb!AM$6:AM$38,MATCH($A16,Feb!$A$6:$A$38,0)),0)+IFERROR(INDEX(Mar!AM$6:AM$38,MATCH($A16,Mar!$A$6:$A$38,0)),0)+IFERROR(INDEX(Apr!AM$6:AM$38,MATCH($A16,Apr!$A$6:$A$38,0)),0)+IFERROR(INDEX(May!AM$6:AM$38,MATCH($A16,May!$A$6:$A$38,0)),0)+IFERROR(INDEX(Jun!AM$6:AM$38,MATCH($A16,Jun!$A$6:$A$38,0)),0)+IFERROR(INDEX(Jul!AM$6:AM$38,MATCH($A16,Jul!$A$6:$A$38,0)),0)} -> 0 | I16: =SUM(C16:H16) -> 0
A17: 9 | C17: {=IFERROR(INDEX(Aug!AH$6:AH$38,MATCH($A17,Aug!$A$6:$A$38,0)),0)+IFERROR(INDEX(Sep!AH$6:AH$38,MATCH($A17,Sep!$A$6:$A$38,0)),0)+IFERROR(INDEX(Oct!AH$6:AH$38,MATCH($A17,Oct!$A$6:$A$38,0)),0)+IFERROR(INDEX(Nov!AH$6:AH$38,MATCH($A17,Nov!$A$6:$A$38,0)),0)+IFERROR(INDEX(Dec!AH$6:AH$38,MATCH($A17,Dec!$A$6:$A$38,0)),0)+IFERROR(INDEX(Jan!AH$6:AH$38,MATCH($A17,Jan!$A$6:$A$38,0)),0)+IFERROR(INDEX(Feb!AH$6:AH$38,MATCH($A17,Feb!$A$6:$A$38,0)),0)+IFERROR(INDEX(Mar!AH$6:AH$38,MATCH($A17,Mar!$A$6:$A$38,0)),0)+IFERROR(INDEX(Apr!AH$6:AH$38,MATCH($A17,Apr!$A$6:$A$38,0)),0)+IFERROR(INDEX(May!AH$6:AH$38,MATCH($A17,May!$A$6:$A$38,0)),0)+IFERROR(INDEX(Jun!AH$6:AH$38,MATCH($A17,Jun!$A$6:$A$38,0)),0)+IFERROR(INDEX(Jul!AH$6:AH$38,MATCH($A17,Jul!$A$6:$A$38,0)),0)} -> 0 | D17: {=IFERROR(INDEX(Aug!AI$6:AI$38,MATCH($A17,Aug!$A$6:$A$38,0)),0)+IFERROR(INDEX(Sep!AI$6:AI$38,MATCH($A17,Sep!$A$6:$A$38,0)),0)+IFERROR(INDEX(Oct!AI$6:AI$38,MATCH($A17,Oct!$A$6:$A$38,0)),0)+IFERROR(INDEX(Nov!AI$6:AI$38,MATCH($A17,Nov!$A$6:$A$38,0)),0)+IFERROR(INDEX(Dec!AI$6:AI$38,MATCH($A17,Dec!$A$6:$A$38,0)),0)+IFERROR(INDEX(Jan!AI$6:AI$38,MATCH($A17,Jan!$A$6:$A$38,0)),0)+IFERROR(INDEX(Feb!AI$6:AI$38,MATCH($A17,Feb!$A$6:$A$38,0)),0)+IFERROR(INDEX(Mar!AI$6:AI$38,MATCH($A17,Mar!$A$6:$A$38,0)),0)+IFERROR(INDEX(Apr!AI$6:AI$38,MATCH($A17,Apr!$A$6:$A$38,0)),0)+IFERROR(INDEX(May!AI$6:AI$38,MATCH($A17,May!$A$6:$A$38,0)),0)+IFERROR(INDEX(Jun!AI$6:AI$38,MATCH($A17,Jun!$A$6:$A$38,0)),0)+IFERROR(INDEX(Jul!AI$6:AI$38,MATCH($A17,Jul!$A$6:$A$38,0)),0)} -> 0 | E17: {=IFERROR(INDEX(Aug!AJ$6:AJ$38,MATCH($A17,Aug!$A$6:$A$38,0)),0)+IFERROR(INDEX(Sep!AJ$6:AJ$38,MATCH($A17,Sep!$A$6:$A$38,0)),0)+IFERROR(INDEX(Oct!AJ$6:AJ$38,MATCH($A17,Oct!$A$6:$A$38,0)),0)+IFERROR(INDEX(Nov!AJ$6:AJ$38,MATCH($A17,Nov!$A$6:$A$38,0)),0)+IFERROR(INDEX(Dec!AJ$6:AJ$38,MATCH($A17,Dec!$A$6:$A$38,0)),0)+IFERROR(INDEX(Jan!AJ$6:AJ$38,MATCH($A17,Jan!$A$6:$A$38,0)),0)+IFERROR(INDEX(Feb!AJ$6:AJ$38,MATCH($A17,Feb!$A$6:$A$38,0)),0)+IFERROR(INDEX(Mar!AJ$6:AJ$38,MATCH($A17,Mar!$A$6:$A$38,0)),0)+IFERROR(INDEX(Apr!AJ$6:AJ$38,MATCH($A17,Apr!$A$6:$A$38,0)),0)+IFERROR(INDEX(May!AJ$6:AJ$38,MATCH($A17,May!$A$6:$A$38,0)),0)+IFERROR(INDEX(Jun!AJ$6:AJ$38,MATCH($A17,Jun!$A$6:$A$38,0)),0)+IFERROR(INDEX(Jul!AJ$6:AJ$38,MATCH($A17,Jul!$A$6:$A$38,0)),0)} -> 0 | F17: {=IFERROR(INDEX(Aug!AK$6:AK$38,MATCH($A17,Aug!$A$6:$A$38,0)),0)+IFERROR(INDEX(Sep!AK$6:AK$38,MATCH($A17,Sep!$A$6:$A$38,0)),0)+IFERROR(INDEX(Oct!AK$6:AK$38,MATCH($A17,Oct!$A$6:$A$38,0)),0)+IFERROR(INDEX(Nov!AK$6:AK$38,MATCH($A17,Nov!$A$6:$A$38,0)),0)+IFERROR(INDEX(Dec!AK$6:AK$38,MATCH($A17,Dec!$A$6:$A$38,0)),0)+IFERROR(INDEX(Jan!AK$6:AK$38,MATCH($A17,Jan!$A$6:$A$38,0)),0)+IFERROR(INDEX(Feb!AK$6:AK$38,MATCH($A17,Feb!$A$6:$A$38,0)),0)+IFERROR(INDEX(Mar!AK$6:AK$38,MATCH($A17,Mar!$A$6:$A$38,0)),0)+IFERROR(INDEX(Apr!AK$6:AK$38,MATCH($A17,Apr!$A$6:$A$38,0)),0)+IFERROR(INDEX(May!AK$6:AK$38,MATCH($A17,May!$A$6:$A$38,0)),0)+IFERROR(INDEX(Jun!AK$6:AK$38,MATCH($A17,Jun!$A$6:$A$38,0)),0)+IFERROR(INDEX(Jul!AK$6:AK$38,MATCH($A17,Jul!$A$6:$A$38,0)),0)} -> 0 | G17: {=IFERROR(INDEX(Aug!AL$6:AL$38,MATCH($A17,Aug!$A$6:$A$38,0)),0)+IFERROR(INDEX(Sep!AL$6:AL$38,MATCH($A17,Sep!$A$6:$A$38,0)),0)+IFERROR(INDEX(Oct!AL$6:AL$38,MATCH($A17,Oct!$A$6:$A$38,0)),0)+IFERROR(INDEX(Nov!AL$6:AL$38,MATCH($A17,Nov!$A$6:$A$38,0)),0)+IFERROR(INDEX(Dec!AL$6:AL$38,MATCH($A17,Dec!$A$6:$A$38,0)),0)+IFERROR(INDEX(Jan!AL$6:AL$38,MATCH($A17,Jan!$A$6:$A$38,0)),0)+IFERROR(INDEX(Feb!AL$6:AL$38,MATCH($A17,Feb!$A$6:$A$38,0)),0)+IFERROR(INDEX(Mar!AL$6:AL$38,MATCH($A17,Mar!$A$6:$A$38,0)),0)+IFERROR(INDEX(Apr!AL$6:AL$38,MATCH($A17,Apr!$A$6:$A$38,0)),0)+IFERROR(INDEX(May!AL$6:AL$38,MATCH($A17,May!$A$6:$A$38,0)),0)+IFERROR(INDEX(Jun!AL$6:AL$38,MATCH($A17,Jun!$A$6:$A$38,0)),0)+IFERROR(INDEX(Jul!AL$6:AL$38,MATCH($A17,Jul!$A$6:$A$38,0)),0)} -> 0 | H17: {=IFERROR(INDEX(Aug!AM$6:AM$38,MATCH($A17,Aug!$A$6:$A$38,0)),0)+IFERROR(INDEX(Sep!AM$6:AM$38,MATCH($A17,Sep!$A$6:$A$38,0)),0)+IFERROR(INDEX(Oct!AM$6:AM$38,MATCH($A17,Oct!$A$6:$A$38,0)),0)+IFERROR(INDEX(Nov!AM$6:AM$38,MATCH($A17,Nov!$A$6:$A$38,0)),0)+IFERROR(INDEX(Dec!AM$6:AM$38,MATCH($A17,Dec!$A$6:$A$38,0)),0)+IFERROR(INDEX(Jan!AM$6:AM$38,MATCH($A17,Jan!$A$6:$A$38,0)),0)+IFERROR(INDEX(Feb!AM$6:AM$38,MATCH($A17,Feb!$A$6:$A$38,0)),0)+IFERROR(INDEX(Mar!AM$6:AM$38,MATCH($A17,Mar!$A$6:$A$38,0)),0)+IFERROR(INDEX(Apr!AM$6:AM$38,MATCH($A17,Apr!$A$6:$A$38,0)),0)+IFERROR(INDEX(May!AM$6:AM$38,MATCH($A17,May!$A$6:$A$38,0)),0)+IFERROR(INDEX(Jun!AM$6:AM$38,MATCH($A17,Jun!$A$6:$A$38,0)),0)+IFERROR(INDEX(Jul!AM$6:AM$38,MATCH($A17,Jul!$A$6:$A$38,0)),0)} -> 0 | I17: =SUM(C17:H17) -> 0 | K17: If you need to add more names, you will need to insert
A18: 10 | C18: {=IFERROR(INDEX(Aug!AH$6:AH$38,MATCH($A18,Aug!$A$6:$A$38,0)),0)+IFERROR(INDEX(Sep!AH$6:AH$38,MATCH($A18,Sep!$A$6:$A$38,0)),0)+IFERROR(INDEX(Oct!AH$6:AH$38,MATCH($A18,Oct!$A$6:$A$38,0)),0)+IFERROR(INDEX(Nov!AH$6:AH$38,MATCH($A18,Nov!$A$6:$A$38,0)),0)+IFERROR(INDEX(Dec!AH$6:AH$38,MATCH($A18,Dec!$A$6:$A$38,0)),0)+IFERROR(INDEX(Jan!AH$6:AH$38,MATCH($A18,Jan!$A$6:$A$38,0)),0)+IFERROR(INDEX(Feb!AH$6:AH$38,MATCH($A18,Feb!$A$6:$A$38,0)),0)+IFERROR(INDEX(Mar!AH$6:AH$38,MATCH($A18,Mar!$A$6:$A$38,0)),0)+IFERROR(INDEX(Apr!AH$6:AH$38,MATCH($A18,Apr!$A$6:$A$38,0)),0)+IFERROR(INDEX(May!AH$6:AH$38,MATCH($A18,May!$A$6:$A$38,0)),0)+IFERROR(INDEX(Jun!AH$6:AH$38,MATCH($A18,Jun!$A$6:$A$38,0)),0)+IFERROR(INDEX(Jul!AH$6:AH$38,MATCH($A18,Jul!$A$6:$A$38,0)),0)} -> 0 | D18: {=IFERROR(INDEX(Aug!AI$6:AI$38,MATCH($A18,Aug!$A$6:$A$38,0)),0)+IFERROR(INDEX(Sep!AI$6:AI$38,MATCH($A18,Sep!$A$6:$A$38,0)),0)+IFERROR(INDEX(Oct!AI$6:AI$38,MATCH($A18,Oct!$A$6:$A$38,0)),0)+IFERROR(INDEX(Nov!AI$6:AI$38,MATCH($A18,Nov!$A$6:$A$38,0)),0)+IFERROR(INDEX(Dec!AI$6:AI$38,MATCH($A18,Dec!$A$6:$A$38,0)),0)+IFERROR(INDEX(Jan!AI$6:AI$38,MATCH($A18,Jan!$A$6:$A$38,0)),0)+IFERROR(INDEX(Feb!AI$6:AI$38,MATCH($A18,Feb!$A$6:$A$38,0)),0)+IFERROR(INDEX(Mar!AI$6:AI$38,MATCH($A18,Mar!$A$6:$A$38,0)),0)+IFERROR(INDEX(Apr!AI$6:AI$38,MATCH($A18,Apr!$A$6:$A$38,0)),0)+IFERROR(INDEX(May!AI$6:AI$38,MATCH($A18,May!$A$6:$A$38,0)),0)+IFERROR(INDEX(Jun!AI$6:AI$38,MATCH($A18,Jun!$A$6:$A$38,0)),0)+IFERROR(INDEX(Jul!AI$6:AI$38,MATCH($A18,Jul!$A$6:$A$38,0)),0)} -> 0 | E18: {=IFERROR(INDEX(Aug!AJ$6:AJ$38,MATCH($A18,Aug!$A$6:$A$38,0)),0)+IFERROR(INDEX(Sep!AJ$6:AJ$38,MATCH($A18,Sep!$A$6:$A$38,0)),0)+IFERROR(INDEX(Oct!AJ$6:AJ$38,MATCH($A18,Oct!$A$6:$A$38,0)),0)+IFERROR(INDEX(Nov!AJ$6:AJ$38,MATCH($A18,Nov!$A$6:$A$38,0)),0)+IFERROR(INDEX(Dec!AJ$6:AJ$38,MATCH($A18,Dec!$A$6:$A$38,0)),0)+IFERROR(INDEX(Jan!AJ$6:AJ$38,MATCH($A18,Jan!$A$6:$A$38,0)),0)+IFERROR(INDEX(Feb!AJ$6:AJ$38,MATCH($A18,Feb!$A$6:$A$38,0)),0)+IFERROR(INDEX(Mar!AJ$6:AJ$38,MATCH($A18,Mar!$A$6:$A$38,0)),0)+IFERROR(INDEX(Apr!AJ$6:AJ$38,MATCH($A18,Apr!$A$6:$A$38,0)),0)+IFERROR(INDEX(May!AJ$6:AJ$38,MATCH($A18,May!$A$6:$A$38,0)),0)+IFERROR(INDEX(Jun!AJ$6:AJ$38,MATCH($A18,Jun!$A$6:$A$38,0)),0)+IFERROR(INDEX(Jul!AJ$6:AJ$38,MATCH($A18,Jul!$A$6:$A$38,0)),0)} -> 0 | F18: {=IFERROR(INDEX(Aug!AK$6:AK$38,MATCH($A18,Aug!$A$6:$A$38,0)),0)+IFERROR(INDEX(Sep!AK$6:AK$38,MATCH($A18,Sep!$A$6:$A$38,0)),0)+IFERROR(INDEX(Oct!AK$6:AK$38,MATCH($A18,Oct!$A$6:$A$38,0)),0)+IFERROR(INDEX(Nov!AK$6:AK$38,MATCH($A18,Nov!$A$6:$A$38,0)),0)+IFERROR(INDEX(Dec!AK$6:AK$38,MATCH($A18,Dec!$A$6:$A$38,0)),0)+IFERROR(INDEX(Jan!AK$6:AK$38,MATCH($A18,Jan!$A$6:$A$38,0)),0)+IFERROR(INDEX(Feb!AK$6:AK$38,MATCH($A18,Feb!$A$6:$A$38,0)),0)+IFERROR(INDEX(Mar!AK$6:AK$38,MATCH($A18,Mar!$A$6:$A$38,0)),0)+IFERROR(INDEX(Apr!AK$6:AK$38,MATCH($A18,Apr!$A$6:$A$38,0)),0)+IFERROR(INDEX(May!AK$6:AK$38,MATCH($A18,May!$A$6:$A$38,0)),0)+IFERROR(INDEX(Jun!AK$6:AK$38,MATCH($A18,Jun!$A$6:$A$38,0)),0)+IFERROR(INDEX(Jul!AK$6:AK$38,MATCH($A18,Jul!$A$6:$A$38,0)),0)} -> 0 | G18: {=IFERROR(INDEX(Aug!AL$6:AL$38,MATCH($A18,Aug!$A$6:$A$38,0)),0)+IFERROR(INDEX(Sep!AL$6:AL$38,MATCH($A18,Sep!$A$6:$A$38,0)),0)+IFERROR(INDEX(Oct!AL$6:AL$38,MATCH($A18,Oct!$A$6:$A$38,0)),0)+IFERROR(INDEX(Nov!AL$6:AL$38,MATCH($A18,Nov!$A$6:$A$38,0)),0)+IFERROR(INDEX(Dec!AL$6:AL$38,MATCH($A18,Dec!$A$6:$A$38,0)),0)+IFERROR(INDEX(Jan!AL$6:AL$38,MATCH($A18,Jan!$A$6:$A$38,0)),0)+IFERROR(INDEX(Feb!AL$6:AL$38,MATCH($A18,Feb!$A$6:$A$38,0)),0)+IFERROR(INDEX(Mar!AL$6:AL$38,MATCH($A18,Mar!$A$6:$A$38,0)),0)+IFERROR(INDEX(Apr!AL$6:AL$38,MATCH($A18,Apr!$A$6:$A$38,0)),0)+IFERROR(INDEX(May!AL$6:AL$38,MATCH($A18,May!$A$6:$A$38,0)),0)+IFERROR(INDEX(Jun!AL$6:AL$38,MATCH($A18,Jun!$A$6:$A$38,0)),0)+IFERROR(INDEX(Jul!AL$6:AL$38,MATCH($A18,Jul!$A$6:$A$38,0)),0)} -> 0 | H18: {=IFERROR(INDEX(Aug!AM$6:AM$38,MATCH($A18,Aug!$A$6:$A$38,0)),0)+IFERROR(INDEX(Sep!AM$6:AM$38,MATCH($A18,Sep!$A$6:$A$38,0)),0)+IFERROR(INDEX(Oct!AM$6:AM$38,MATCH($A18,Oct!$A$6:$A$38,0)),0)+IFERROR(INDEX(Nov!AM$6:AM$38,MATCH($A18,Nov!$A$6:$A$38,0)),0)+IFERROR(INDEX(Dec!AM$6:AM$38,MATCH($A18,Dec!$A$6:$A$38,0)),0)+IFERROR(INDEX(Jan!AM$6:AM$38,MATCH($A18,Jan!$A$6:$A$38,0)),0)+IFERROR(INDEX(Feb!AM$6:AM$38,MATCH($A18,Feb!$A$6:$A$38,0)),0)+IFERROR(INDEX(Mar!AM$6:AM$38,MATCH($A18,Mar!$A$6:$A$38,0)),0)+IFERROR(INDEX(Apr!AM$6:AM$38,MATCH($A18,Apr!$A$6:$A$38,0)),0)+IFERROR(INDEX(May!AM$6:AM$38,MATCH($A18,May!$A$6:$A$38,0)),0)+IFERROR(INDEX(Jun!AM$6:AM$38,MATCH($A18,Jun!$A$6:$A$38,0)),0)+IFERROR(INDEX(Jul!AM$6:AM$38,MATCH($A18,Jul!$A$6:$A$38,0)),0)} -> 0 | I18: =SUM(C18:H18) -> 0 | K18: new rows ABOVE the last row in the tables (the gray row).
A19: 11 | C19: {=IFERROR(INDEX(Aug!AH$6:AH$38,MATCH($A19,Aug!$A$6:$A$38,0)),0)+IFERROR(INDEX(Sep!AH$6:AH$38,MATCH($A19,Sep!$A$6:$A$38,0)),0)+IFERROR(INDEX(Oct!AH$6:AH$38,MATCH($A19,Oct!$A$6:$A$38,0)),0)+IFERROR(INDEX(Nov!AH$6:AH$38,MATCH($A19,Nov!$A$6:$A$38,0)),0)+IFERROR(INDEX(Dec!AH$6:AH$38,MATCH($A19,Dec!$A$6:$A$38,0)),0)+IFERROR(INDEX(Jan!AH$6:AH$38,MATCH($A19,Jan!$A$6:$A$38,0)),0)+IFERROR(INDEX(Feb!AH$6:AH$38,MATCH($A19,Feb!$A$6:$A$38,0)),0)+IFERROR(INDEX(Mar!AH$6:AH$38,MATCH($A19,Mar!$A$6:$A$38,0)),0)+IFERROR(INDEX(Apr!AH$6:AH$38,MATCH($A19,Apr!$A$6:$A$38,0)),0)+IFERROR(INDEX(May!AH$6:AH$38,MATCH($A19,May!$A$6:$A$38,0)),0)+IFERROR(INDEX(Jun!AH$6:AH$38,MATCH($A19,Jun!$A$6:$A$38,0)),0)+IFERROR(INDEX(Jul!AH$6:AH$38,MATCH($A19,Jul!$A$6:$A$38,0)),0)} -> 0 | D19: {=IFERROR(INDEX(Aug!AI$6:AI$38,MATCH($A19,Aug!$A$6:$A$38,0)),0)+IFERROR(INDEX(Sep!AI$6:AI$38,MATCH($A19,Sep!$A$6:$A$38,0)),0)+IFERROR(INDEX(Oct!AI$6:AI$38,MATCH($A19,Oct!$A$6:$A$38,0)),0)+IFERROR(INDEX(Nov!AI$6:AI$38,MATCH($A19,Nov!$A$6:$A$38,0)),0)+IFERROR(INDEX(Dec!AI$6:AI$38,MATCH($A19,Dec!$A$6:$A$38,0)),0)+IFERROR(INDEX(Jan!AI$6:AI$38,MATCH($A19,Jan!$A$6:$A$38,0)),0)+IFERROR(INDEX(Feb!AI$6:AI$38,MATCH($A19,Feb!$A$6:$A$38,0)),0)+IFERROR(INDEX(Mar!AI$6:AI$38,MATCH($A19,Mar!$A$6:$A$38,0)),0)+IFERROR(INDEX(Apr!AI$6:AI$38,MATCH($A19,Apr!$A$6:$A$38,0)),0)+IFERROR(INDEX(May!AI$6:AI$38,MATCH($A19,May!$A$6:$A$38,0)),0)+IFERROR(INDEX(Jun!AI$6:AI$38,MATCH($A19,Jun!$A$6:$A$38,0)),0)+IFERROR(INDEX(Jul!AI$6:AI$38,MATCH($A19,Jul!$A$6:$A$38,0)),0)} -> 0 | E19: {=IFERROR(INDEX(Aug!AJ$6:AJ$38,MATCH($A19,Aug!$A$6:$A$38,0)),0)+IFERROR(INDEX(Sep!AJ$6:AJ$38,MATCH($A19,Sep!$A$6:$A$38,0)),0)+IFERROR(INDEX(Oct!AJ$6:AJ$38,MATCH($A19,Oct!$A$6:$A$38,0)),0)+IFERROR(INDEX(Nov!AJ$6:AJ$38,MATCH($A19,Nov!$A$6:$A$38,0)),0)+IFERROR(INDEX(Dec!AJ$6:AJ$38,MATCH($A19,Dec!$A$6:$A$38,0)),0)+IFERROR(INDEX(Jan!AJ$6:AJ$38,MATCH($A19,Jan!$A$6:$A$38,0)),0)+IFERROR(INDEX(Feb!AJ$6:AJ$38,MATCH($A19,Feb!$A$6:$A$38,0)),0)+IFERROR(INDEX(Mar!AJ$6:AJ$38,MATCH($A19,Mar!$A$6:$A$38,0)),0)+IFERROR(INDEX(Apr!AJ$6:AJ$38,MATCH($A19,Apr!$A$6:$A$38,0)),0)+IFERROR(INDEX(May!AJ$6:AJ$38,MATCH($A19,May!$A$6:$A$38,0)),0)+IFERROR(INDEX(Jun!AJ$6:AJ$38,MATCH($A19,Jun!$A$6:$A$38,0)),0)+IFERROR(INDEX(Jul!AJ$6:AJ$38,MATCH($A19,Jul!$A$6:$A$38,0)),0)} -> 0 | F19: {=IFERROR(INDEX(Aug!AK$6:AK$38,MATCH($A19,Aug!$A$6:$A$38,0)),0)+IFERROR(INDEX(Sep!AK$6:AK$38,MATCH($A19,Sep!$A$6:$A$38,0)),0)+IFERROR(INDEX(Oct!AK$6:AK$38,MATCH($A19,Oct!$A$6:$A$38,0)),0)+IFERROR(INDEX(Nov!AK$6:AK$38,MATCH($A19,Nov!$A$6:$A$38,0)),0)+IFERROR(INDEX(Dec!AK$6:AK$38,MATCH($A19,Dec!$A$6:$A$38,0)),0)+IFERROR(INDEX(Jan!AK$6:AK$38,MATCH($A19,Jan!$A$6:$A$38,0)),0)+IFERROR(INDEX(Feb!AK$6:AK$38,MATCH($A19,Feb!$A$6:$A$38,0)),0)+IFERROR(INDEX(Mar!AK$6:AK$38,MATCH($A19,Mar!$A$6:$A$38,0)),0)+IFERROR(INDEX(Apr!AK$6:AK$38,MATCH($A19,Apr!$A$6:$A$38,0)),0)+IFERROR(INDEX(May!AK$6:AK$38,MATCH($A19,May!$A$6:$A$38,0)),0)+IFERROR(INDEX(Jun!AK$6:AK$38,MATCH($A19,Jun!$A$6:$A$38,0)),0)+IFERROR(INDEX(Jul!AK$6:AK$38,MATCH($A19,Jul!$A$6:$A$38,0)),0)} -> 0 | G19: {=IFERROR(INDEX(Aug!AL$6:AL$38,MATCH($A19,Aug!$A$6:$A$38,0)),0)+IFERROR(INDEX(Sep!AL$6:AL$38,MATCH($A19,Sep!$A$6:$A$38,0)),0)+IFERROR(INDEX(Oct!AL$6:AL$38,MATCH($A19,Oct!$A$6:$A$38,0)),0)+IFERROR(INDEX(Nov!AL$6:AL$38,MATCH($A19,Nov!$A$6:$A$38,0)),0)+IFERROR(INDEX(Dec!AL$6:AL$38,MATCH($A19,Dec!$A$6:$A$38,0)),0)+IFERROR(INDEX(Jan!AL$6:AL$38,MATCH($A19,Jan!$A$6:$A$38,0)),0)+IFERROR(INDEX(Feb!AL$6:AL$38,MATCH($A19,Feb!$A$6:$A$38,0)),0)+IFERROR(INDEX(Mar!AL$6:AL$38,MATCH($A19,Mar!$A$6:$A$38,0)),0)+IFERROR(INDEX(Apr!AL$6:AL$38,MATCH($A19,Apr!$A$6:$A$38,0)),0)+IFERROR(INDEX(May!AL$6:AL$38,MATCH($A19,May!$A$6:$A$38,0)),0)+IFERROR(INDEX(Jun!AL$6:AL$38,MATCH($A19,Jun!$A$6:$A$38,0)),0)+IFERROR(INDEX(Jul!AL$6:AL$38,MATCH($A19,Jul!$A$6:$A$38,0)),0)} -> 0 | H19: {=IFERROR(INDEX(Aug!AM$6:AM$38,MATCH($A19,Aug!$A$6:$A$38,0)),0)+IFERROR(INDEX(Sep!AM$6:AM$38,MATCH($A19,Sep!$A$6:$A$38,0)),0)+IFERROR(INDEX(Oct!AM$6:AM$38,MATCH($A19,Oct!$A$6:$A$38,0)),0)+IFERROR(INDEX(Nov!AM$6:AM$38,MATCH($A19,Nov!$A$6:$A$38,0)),0)+IFERROR(INDEX(Dec!AM$6:AM$38,MATCH($A19,Dec!$A$6:$A$38,0)),0)+IFERROR(INDEX(Jan!AM$6:AM$38,MATCH($A19,Jan!$A$6:$A$38,0)),0)+IFERROR(INDEX(Feb!AM$6:AM$38,MATCH($A19,Feb!$A$6:$A$38,0)),0)+IFERROR(INDEX(Mar!AM$6:AM$38,MATCH($A19,Mar!$A$6:$A$38,0)),0)+IFERROR(INDEX(Apr!AM$6:AM$38,MATCH($A19,Apr!$A$6:$A$38,0)),0)+IFERROR(INDEX(May!AM$6:AM$38,MATCH($A19,May!$A$6:$A$38,0)),0)+IFERROR(INDEX(Jun!AM$6:AM$38,MATCH($A19,Jun!$A$6:$A$38,0)),0)+IFERROR(INDEX(Jul!AM$6:AM$38,MATCH($A19,Jul!$A$6:$A$38,0)),0)} -> 0 | I19: =SUM(C19:H19) -> 0 | K19: Then, copy formulas down from the previous row. You'll
A20: 12 | C20: {=IFERROR(INDEX(Aug!AH$6:AH$38,MATCH($A20,Aug!$A$6:$A$38,0)),0)+IFERROR(INDEX(Sep!AH$6:AH$38,MATCH($A20,Sep!$A$6:$A$38,0)),0)+IFERROR(INDEX(Oct!AH$6:AH$38,MATCH($A20,Oct!$A$6:$A$38,0)),0)+IFERROR(INDEX(Nov!AH$6:AH$38,MATCH($A20,Nov!$A$6:$A$38,0)),0)+IFERROR(INDEX(Dec!AH$6:AH$38,MATCH($A20,Dec!$A$6:$A$38,0)),0)+IFERROR(INDEX(Jan!AH$6:AH$38,MATCH($A20,Jan!$A$6:$A$38,0)),0)+IFERROR(INDEX(Feb!AH$6:AH$38,MATCH($A20,Feb!$A$6:$A$38,0)),0)+IFERROR(INDEX(Mar!AH$6:AH$38,MATCH($A20,Mar!$A$6:$A$38,0)),0)+IFERROR(INDEX(Apr!AH$6:AH$38,MATCH($A20,Apr!$A$6:$A$38,0)),0)+IFERROR(INDEX(May!AH$6:AH$38,MATCH($A20,May!$A$6:$A$38,0)),0)+IFERROR(INDEX(Jun!AH$6:AH$38,MATCH($A20,Jun!$A$6:$A$38,0)),0)+IFERROR(INDEX(Jul!AH$6:AH$38,MATCH($A20,Jul!$A$6:$A$38,0)),0)} -> 0 | D20: {=IFERROR(INDEX(Aug!AI$6:AI$38,MATCH($A20,Aug!$A$6:$A$38,0)),0)+IFERROR(INDEX(Sep!AI$6:AI$38,MATCH($A20,Sep!$A$6:$A$38,0)),0)+IFERROR(INDEX(Oct!AI$6:AI$38,MATCH($A20,Oct!$A$6:$A$38,0)),0)+IFERROR(INDEX(Nov!AI$6:AI$38,MATCH($A20,Nov!$A$6:$A$38,0)),0)+IFERROR(INDEX(Dec!AI$6:AI$38,MATCH($A20,Dec!$A$6:$A$38,0)),0)+IFERROR(INDEX(Jan!AI$6:AI$38,MATCH($A20,Jan!$A$6:$A$38,0)),0)+IFERROR(INDEX(Feb!AI$6:AI$38,MATCH($A20,Feb!$A$6:$A$38,0)),0)+IFERROR(INDEX(Mar!AI$6:AI$38,MATCH($A20,Mar!$A$6:$A$38,0)),0)+IFERROR(INDEX(Apr!AI$6:AI$38,MATCH($A20,Apr!$A$6:$A$38,0)),0)+IFERROR(INDEX(May!AI$6:AI$38,MATCH($A20,May!$A$6:$A$38,0)),0)+IFERROR(INDEX(Jun!AI$6:AI$38,MATCH($A20,Jun!$A$6:$A$38,0)),0)+IFERROR(INDEX(Jul!AI$6:AI$38,MATCH($A20,Jul!$A$6:$A$38,0)),0)} -> 0 | E20: {=IFERROR(INDEX(Aug!AJ$6:AJ$38,MATCH($A20,Aug!$A$6:$A$38,0)),0)+IFERROR(INDEX(Sep!AJ$6:AJ$38,MATCH($A20,Sep!$A$6:$A$38,0)),0)+IFERROR(INDEX(Oct!AJ$6:AJ$38,MATCH($A20,Oct!$A$6:$A$38,0)),0)+IFERROR(INDEX(Nov!AJ$6:AJ$38,MATCH($A20,Nov!$A$6:$A$38,0)),0)+IFERROR(INDEX(Dec!AJ$6:AJ$38,MATCH($A20,Dec!$A$6:$A$38,0)),0)+IFERROR(INDEX(Jan!AJ$6:AJ$38,MATCH($A20,Jan!$A$6:$A$38,0)),0)+IFERROR(INDEX(Feb!AJ$6:AJ$38,MATCH($A20,Feb!$A$6:$A$38,0)),0)+IFERROR(INDEX(Mar!AJ$6:AJ$38,MATCH($A20,Mar!$A$6:$A$38,0)),0)+IFERROR(INDEX(Apr!AJ$6:AJ$38,MATCH($A20,Apr!$A$6:$A$38,0)),0)+IFERROR(INDEX(May!AJ$6:AJ$38,MATCH($A20,May!$A$6:$A$38,0)),0)+IFERROR(INDEX(Jun!AJ$6:AJ$38,MATCH($A20,Jun!$A$6:$A$38,0)),0)+IFERROR(INDEX(Jul!AJ$6:AJ$38,MATCH($A20,Jul!$A$6:$A$38,0)),0)} -> 0 | F20: {=IFERROR(INDEX(Aug!AK$6:AK$38,MATCH($A20,Aug!$A$6:$A$38,0)),0)+IFERROR(INDEX(Sep!AK$6:AK$38,MATCH($A20,Sep!$A$6:$A$38,0)),0)+IFERROR(INDEX(Oct!AK$6:AK$38,MATCH($A20,Oct!$A$6:$A$38,0)),0)+IFERROR(INDEX(Nov!AK$6:AK$38,MATCH($A20,Nov!$A$6:$A$38,0)),0)+IFERROR(INDEX(Dec!AK$6:AK$38,MATCH($A20,Dec!$A$6:$A$38,0)),0)+IFERROR(INDEX(Jan!AK$6:AK$38,MATCH($A20,Jan!$A$6:$A$38,0)),0)+IFERROR(INDEX(Feb!AK$6:AK$38,MATCH($A20,Feb!$A$6:$A$38,0)),0)+IFERROR(INDEX(Mar!AK$6:AK$38,MATCH($A20,Mar!$A$6:$A$38,0)),0)+IFERROR(INDEX(Apr!AK$6:AK$38,MATCH($A20,Apr!$A$6:$A$38,0)),0)+IFERROR(INDEX(May!AK$6:AK$38,MATCH($A20,May!$A$6:$A$38,0)),0)+IFERROR(INDEX(Jun!AK$6:AK$38,MATCH($A20,Jun!$A$6:$A$38,0)),0)+IFERROR(INDEX(Jul!AK$6:AK$38,MATCH($A20,Jul!$A$6:$A$38,0)),0)} -> 0 | G20: {=IFERROR(INDEX(Aug!AL$6:AL$38,MATCH($A20,Aug!$A$6:$A$38,0)),0)+IFERROR(INDEX(Sep!AL$6:AL$38,MATCH($A20,Sep!$A$6:$A$38,0)),0)+IFERROR(INDEX(Oct!AL$6:AL$38,MATCH($A20,Oct!$A$6:$A$38,0)),0)+IFERROR(INDEX(Nov!AL$6:AL$38,MATCH($A20,Nov!$A$6:$A$38,0)),0)+IFERROR(INDEX(Dec!AL$6:AL$38,MATCH($A20,Dec!$A$6:$A$38,0)),0)+IFERROR(INDEX(Jan!AL$6:AL$38,MATCH($A20,Jan!$A$6:$A$38,0)),0)+IFERROR(INDEX(Feb!AL$6:AL$38,MATCH($A20,Feb!$A$6:$A$38,0)),0)+IFERROR(INDEX(Mar!AL$6:AL$38,MATCH($A20,Mar!$A$6:$A$38,0)),0)+IFERROR(INDEX(Apr!AL$6:AL$38,MATCH($A20,Apr!$A$6:$A$38,0)),0)+IFERROR(INDEX(May!AL$6:AL$38,MATCH($A20,May!$A$6:$A$38,0)),0)+IFERROR(INDEX(Jun!AL$6:AL$38,MATCH($A20,Jun!$A$6:$A$38,0)),0)+IFERROR(INDEX(Jul!AL$6:AL$38,MATCH($A20,Jul!$A$6:$A$38,0)),0)} -> 0 | H20: {=IFERROR(INDEX(Aug!AM$6:AM$38,MATCH($A20,Aug!$A$6:$A$38,0)),0)+IFERROR(INDEX(Sep!AM$6:AM$38,MATCH($A20,Sep!$A$6:$A$38,0)),0)+IFERROR(INDEX(Oct!AM$6:AM$38,MATCH($A20,Oct!$A$6:$A$38,0)),0)+IFERROR(INDEX(Nov!AM$6:AM$38,MATCH($A20,Nov!$A$6:$A$38,0)),0)+IFERROR(INDEX(Dec!AM$6:AM$38,MATCH($A20,Dec!$A$6:$A$38,0)),0)+IFERROR(INDEX(Jan!AM$6:AM$38,MATCH($A20,Jan!$A$6:$A$38,0)),0)+IFERROR(INDEX(Feb!AM$6:AM$38,MATCH($A20,Feb!$A$6:$A$38,0)),0)+IFERROR(INDEX(Mar!AM$6:AM$38,MATCH($A20,Mar!$A$6:$A$38,0)),0)+IFERROR(INDEX(Apr!AM$6:AM$38,MATCH($A20,Apr!$A$6:$A$38,0)),0)+IFERROR(INDEX(May!AM$6:AM$38,MATCH($A20,May!$A$6:$A$38,0)),0)+IFERROR(INDEX(Jun!AM$6:AM$38,MATCH($A20,Jun!$A$6:$A$38,0)),0)+IFERROR(INDEX(Jul!AM$6:AM$38,MATCH($A20,Jul!$A$6:$A$38,0)),0)} -> 0 | I20: =SUM(C20:H20) -> 0 | K20: need to do this in all other worksheets.
