Workbook
Name CountryList: 'Lists'!$B$1:$AG$1
Name CountryISO: 'Lists'!$B$2:$AG$2
Name Incoterms: 'Lists'!$B$4:$AG$4
Name TransportMode: 'Lists'!$B$5:$AG$5
Name Currency: 'Lists'!$B$6:$AG$6
Name Units: 'Lists'!$B$7:$AG$7
Name ProcedureCode: 'Lists'!$B$8:$AG$8
Name LangCodes: 'Lists'!$B$10:$AG$10
Name VATTypeList: 'Lists'!$B$198:$AG$198
Name CountryLang_Country: 'Lists'!$A$13:$A$45
Name CountryLang_Code: 'Lists'!$B$13:$B$45
Name VAT_Country: 'Lists'!$A$202:$A$233
Name VAT_Standard: 'Lists'!$B$202:$B$233
Name VAT_Reduced1: 'Lists'!$C$202:$C$233
Name VAT_Reduced2: 'Lists'!$D$202:$D$233

Sheet Cover
A1: EU Customs Declaration — Master Template (Import/Export)
A3: One file for all EU countries + UK/NO/CH/IS/LI with auto VAT, localization, and print-ready pages.
A5: Highlights
A6: • Country selector (auto language EN/EE/DE/FR based on country)
A7: • Import / Export selector (SAD-style fields)
A8: • Items with duty/VAT/total auto-calculation
A9: • Default VAT: Standard + Reduced1 + Reduced2 (editable)
A10: • Per-line VAT Type (Standard/Reduced/Manual)
A11: • Professional formatting + print to PDF (macro module included)

Sheet Instructions
A1: EU Customs Declaration Master Template (Import/Export)
A2: Version: 2025-08-17 • Author: Imprint • Languages: EN/EE/DE/FR
A4: Pick Country and Flow on 'Declaration'. Items on 'Items'. Totals on 'Summary'. Default VAT loads by Country. You can localize labels by editing 'Translations' and language mapping on 'Lists'.

Sheet Declaration
A1: Customs Declaration (SAD-style) — Master | H1: Country | I1: =B3
H2: Flow | I2: =B4
A3: =INDEX(Translations!$B:$E, MATCH("Select Country", Translations!$A:$A, 0), MATCH($I$3, Lists!$B$10:$E$10, 0)) | H3: Language | I3: =IFERROR(XLOOKUP(B3, CountryLang_Country, CountryLang_Code), "EN")
A4: =INDEX(Translations!$B:$E, MATCH("Select Flow", Translations!$A:$A, 0), MATCH($I$3, Lists!$B$10:$E$10, 0))
A6: =INDEX(Translations!$B:$E, MATCH("Declarant (Company Name)", Translations!$A:$A, 0), MATCH($I$3, Lists!$B$10:$E$10, 0))
A7: =INDEX(Translations!$B:$E, MATCH("Registry code / EORI / VAT", Translations!$A:$A, 0), MATCH($I$3, Lists!$B$10:$E$10, 0))
A8: =INDEX(Translations!$B:$E, MATCH("Address", Translations!$A:$A, 0), MATCH($I$3, Lists!$B$10:$E$10, 0))
A9: =INDEX(Translations!$B:$E, MATCH("Contact person", Translations!$A:$A, 0), MATCH($I$3, Lists!$B$10:$E$10, 0))
A10: =INDEX(Translations!$B:$E, MATCH("Contact email", Translations!$A:$A, 0), MATCH($I$3, Lists!$B$10:$E$10, 0))
A11: =INDEX(Translations!$B:$E, MATCH("Contact phone", Translations!$A:$A, 0), MATCH($I$3, Lists!$B$10:$E$10, 0))
A13: =INDEX(Translations!$B:$E, MATCH("Consignor (Seller / Exporter)", Translations!$A:$A, 0), MATCH($I$3, Lists!$B$10:$E$10, 0))
A14: =INDEX(Translations!$B:$E, MATCH("Consignee (Buyer / Importer)", Translations!$A:$A, 0), MATCH($I$3, Lists!$B$10:$E$10, 0))
A15: =INDEX(Translations!$B:$E, MATCH("Consignor VAT/EORI", Translations!$A:$A, 0), MATCH($I$3, Lists!$B$10:$E$10, 0))
A16: =INDEX(Translations!$B:$E, MATCH("Consignee VAT/EORI", Translations!$A:$A, 0), MATCH($I$3, Lists!$B$10:$E$10, 0))
A18: =INDEX(Translations!$B:$E, MATCH("Shipment & Procedure", Translations!$A:$A, 0), MATCH($I$3, Lists!$B$10:$E$10, 0))
A20: =INDEX(Translations!$B:$E, MATCH("Procedure code", Translations!$A:$A, 0), MATCH($I$3, Lists!$B$10:$E$10, 0))
A21: =INDEX(Translations!$B:$E, MATCH("Incoterms", Translations!$A:$A, 0), MATCH($I$3, Lists!$B$10:$E$10, 0))
A22: =INDEX(Translations!$B:$E, MATCH("Country of dispatch/destination (ISO)", Translations!$A:$A, 0), MATCH($I$3, Lists!$B$10:$E$10, 0))
A23: =INDEX(Translations!$B:$E, MATCH("Mode of transport at border", Translations!$A:$A, 0), MATCH($I$3, Lists!$B$10:$E$10, 0))
A24: =INDEX(Translations!$B:$E, MATCH("Border crossing point / Vehicle No.", Translations!$A:$A, 0), MATCH($I$3, Lists!$B$10:$E$10, 0))
A25: =INDEX(Translations!$B:$E, MATCH("Invoice number / date", Translations!$A:$A, 0), MATCH($I$3, Lists!$B$10:$E$10, 0))
A26: =INDEX(Translations!$B:$E, MATCH("Reference / Order No.", Translations!$A:$A, 0), MATCH($I$3, Lists!$B$10:$E$10, 0))
A28: =INDEX(Translations!$B:$E, MATCH("Totals (from Items)", Translations!$A:$A, 0), MATCH($I$3, Lists!$B$10:$E$10, 0))
A30: =INDEX(Translations!$B:$E, MATCH("Customs Value (EUR)", Translations!$A:$A, 0), MATCH($I$3, Lists!$B$10:$E$10, 0)) | B30: =Summary!B6
A31: =INDEX(Translations!$B:$E, MATCH("Duty (EUR)", Translations!$A:$A, 0), MATCH($I$3, Lists!$B$10:$E$10, 0)) | B31: =Summary!B7
A32: =INDEX(Translations!$B:$E, MATCH("VAT (EUR)", Translations!$A:$A, 0), MATCH($I$3, Lists!$B$10:$E$10, 0)) | B32: =Summary!B8
A33: =INDEX(Translations!$B:$E, MATCH("Total Taxes (EUR)", Translations!$A:$A, 0), MATCH($I$3, Lists!$B$10:$E$10, 0)) | B33: =Summary!B9
A34: =INDEX(Translations!$B:$E, MATCH("Grand Total (EUR)", Translations!$A:$A, 0), MATCH($I$3, Lists!$B$10:$E$10, 0)) | B34: =Summary!B10

Sheet Items
A1: Line | B1: HS Code | C1: Description of goods | D1: Origin (ISO) | E1: Qty | F1: Unit | G1: Net Weight (kg) | H1: Gross Weight (kg) | I1: Currency | J1: Unit Price | K1: Line Value (Currency) | L1: Freight | M1: Insurance | N1: Other Costs | O1: Customs Value (EUR) | P1: Duty Rate (%) | Q1: Duty (EUR) | R1: VAT Type | S1: Manual VAT (%) | T1: VAT Rate (%) | U1: VAT (EUR) | V1: Total Taxes (EUR) | W1: Line Total (EUR)
A2: 1 | K2: =IFERROR(E2*J2,0) | O2: =SUM(L2:N2)+IF(I2="EUR",K2,K2) | Q2: =IFERROR(O2*P2/100,0) | R2: Standard | T2: =IF(R2="Manual", IFERROR(S2, Summary!B5), IF(R2="Reduced1", Summary!C5, IF(R2="Reduced2", Summary!D5, Summary!B5))) | U2: =IFERROR((O2+Q2)*T2/100,0) | V2: =Q2+U2 | W2: =O2+V2
A3: 2 | K3: =IFERROR(E3*J3,0) | O3: =SUM(L3:N3)+IF(I3="EUR",K3,K3) | Q3: =IFERROR(O3*P3/100,0) | R3: Standard | T3: =IF(R3="Manual", IFERROR(S3, Summary!B5), IF(R3="Reduced1", Summary!C5, IF(R3="Reduced2", Summary!D5, Summary!B5))) | U3: =IFERROR((O3+Q3)*T3/100,0) | V3: =Q3+U3 | W3: =O3+V3
A4: 3 | K4: =IFERROR(E4*J4,0) | O4: =SUM(L4:N4)+IF(I4="EUR",K4,K4) | Q4: =IFERROR(O4*P4/100,0) | R4: Standard | T4: =IF(R4="Manual", IFERROR(S4, Summary!B5), IF(R4="Reduced1", Summary!C5, IF(R4="Reduced2", Summary!D5, Summary!B5))) | U4: =IFERROR((O4+Q4)*T4/100,0) | V4: =Q4+U4 | W4: =O4+V4
A5: 4 | K5: =IFERROR(E5*J5,0) | O5: =SUM(L5:N5)+IF(I5="EUR",K5,K5) | Q5: =IFERROR(O5*P5/100,0) | R5: Standard | T5: =IF(R5="Manual", IFERROR(S5, Summary!B5), IF(R5="Reduced1", Summary!C5, IF(R5="Reduced2", Summary!D5, Summary!B5))) | U5: =IFERROR((O5+Q5)*T5/100,0) | V5: =Q5+U5 | W5: =O5+V5
A6: 5 | K6: =IFERROR(E6*J6,0) | O6: =SUM(L6:N6)+IF(I6="EUR",K6,K6) | Q6: =IFERROR(O6*P6/100,0) | R6: Standard | T6: =IF(R6="Manual", IFERROR(S6, Summary!B5), IF(R6="Reduced1", Summary!C5, IF(R6="Reduced2", Summary!D5, Summary!B5))) | U6: =IFERROR((O6+Q6)*T6/100,0) | V6: =Q6+U6 | W6: =O6+V6
A7: 6 | K7: =IFERROR(E7*J7,0) | O7: =SUM(L7:N7)+IF(I7="EUR",K7,K7) | Q7: =IFERROR(O7*P7/100,0) | R7: Standard | T7: =IF(R7="Manual", IFERROR(S7, Summary!B5), IF(R7="Reduced1", Summary!C5, IF(R7="Reduced2", Summary!D5, Summary!B5))) | U7: =IFERROR((O7+Q7)*T7/100,0) | V7: =Q7+U7 | W7: =O7+V7
A8: 7 | K8: =IFERROR(E8*J8,0) | O8: =SUM(L8:N8)+IF(I8="EUR",K8,K8) | Q8: =IFERROR(O8*P8/100,0) | R8: Standard | T8: =IF(R8="Manual", IFERROR(S8, Summary!B5), IF(R8="Reduced1", Summary!C5, IF(R8="Reduced2", Summary!D5, Summary!B5))) | U8: =IFERROR((O8+Q8)*T8/100,0) | V8: =Q8+U8 | W8: =O8+V8
A9: 8 | K9: =IFERROR(E9*J9,0) | O9: =SUM(L9:N9)+IF(I9="EUR",K9,K9) | Q9: =IFERROR(O9*P9/100,0) | R9: Standard | T9: =IF(R9="Manual", IFERROR(S9, Summary!B5), IF(R9="Reduced1", Summary!C5, IF(R9="Reduced2", Summary!D5, Summary!B5))) | U9: =IFERROR((O9+Q9)*T9/100,0) | V9: =Q9+U9 | W9: =O9+V9
A10: 9 | K10: =IFERROR(E10*J10,0) | O10: =SUM(L10:N10)+IF(I10="EUR",K10,K10) | Q10: =IFERROR(O10*P10/100,0) | R10: Standard | T10: =IF(R10="Manual", IFERROR(S10, Summary!B5), IF(R10="Reduced1", Summary!C5, IF(R10="Reduced2", Summary!D5, Summary!B5))) | U10: =IFERROR((O10+Q10)*T10/100,0) | V10: =Q10+U10 | W10: =O10+V10
A11: 10 | K11: =IFERROR(E11*J11,0) | O11: =SUM(L11:N11)+IF(I11="EUR",K11,K11) | Q11: =IFERROR(O11*P11/100,0) | R11: Standard | T11: =IF(R11="Manual", IFERROR(S11, Summary!B5), IF(R11="Reduced1", Summary!C5, IF(R11="Reduced2", Summary!D5, Summary!B5))) | U11: =IFERROR((O11+Q11)*T11/100,0) | V11: =Q11+U11 | W11: =O11+V11
A12: 11 | K12: =IFERROR(E12*J12,0) | O12: =SUM(L12:N12)+IF(I12="EUR",K12,K12) | Q12: =IFERROR(O12*P12/100,0) | R12: Standard | T12: =IF(R12="Manual", IFERROR(S12, Summary!B5), IF(R12="Reduced1", Summary!C5, IF(R12="Reduced2", Summary!D5, Summary!B5))) | U12: =IFERROR((O12+Q12)*T12/100,0) | V12: =Q12+U12 | W12: =O12+V12
A13: 12 | K13: =IFERROR(E13*J13,0) | O13: =SUM(L13:N13)+IF(I13="EUR",K13,K13) | Q13: =IFERROR(O13*P13/100,0) | R13: Standard | T13: =IF(R13="Manual", IFERROR(S13, Summary!B5), IF(R13="Reduced1", Summary!C5, IF(R13="Reduced2", Summary!D5, Summary!B5))) | U13: =IFERROR((O13+Q13)*T13/100,0) | V13: =Q13+U13 | W13: =O13+V13
A14: 13 | K14: =IFERROR(E14*J14,0) | O14: =SUM(L14:N14)+IF(I14="EUR",K14,K14) | Q14: =IFERROR(O14*P14/100,0) | R14: Standard | T14: =IF(R14="Manual", IFERROR(S14, Summary!B5), IF(R14="Reduced1", Summary!C5, IF(R14="Reduced2", Summary!D5, Summary!B5))) | U14: =IFERROR((O14+Q14)*T14/100,0) | V14: =Q14+U14 | W14: =O14+V14
A15: 14 | K15: =IFERROR(E15*J15,0) | O15: =SUM(L15:N15)+IF(I15="EUR",K15,K15) | Q15: =IFERROR(O15*P15/100,0) | R15: Standard | T15: =IF(R15="Manual", IFERROR(S15, Summary!B5), IF(R15="Reduced1", Summary!C5, IF(R15="Reduced2", Summary!D5, Summary!B5))) | U15: =IFERROR((O15+Q15)*T15/100,0) | V15: =Q15+U15 | W15: =O15+V15
A16: 15 | K16: =IFERROR(E16*J16,0) | O16: =SUM(L16:N16)+IF(I16="EUR",K16,K16) | Q16: =IFERROR(O16*P16/100,0) | R16: Standard | T16: =IF(R16="Manual", IFERROR(S16, Summary!B5), IF(R16="Reduced1", Summary!C5, IF(R16="Reduced2", Summary!D5, Summary!B5))) | U16: =IFERROR((O16+Q16)*T16/100,0) | V16: =Q16+U16 | W16: =O16+V16
A17: 16 | K17: =IFERROR(E17*J17,0) | O17: =SUM(L17:N17)+IF(I17="EUR",K17,K17) | Q17: =IFERROR(O17*P17/100,0) | R17: Standard | T17: =IF(R17="Manual", IFERROR(S17, Summary!B5), IF(R17="Reduced1", Summary!C5, IF(R17="Reduced2", Summary!D5, Summary!B5))) | U17: =IFERROR((O17+Q17)*T17/100,0) | V17: =Q17+U17 | W17: =O17+V17
A18: 17 | K18: =IFERROR(E18*J18,0) | O18: =SUM(L18:N18)+IF(I18="EUR",K18,K18) | Q18: =IFERROR(O18*P18/100,0) | R18: Standard | T18: =IF(R18="Manual", IFERROR(S18, Summary!B5), IF(R18="Reduced1", Summary!C5, IF(R18="Reduced2", Summary!D5, Summary!B5))) | U18: =IFERROR((O18+Q18)*T18/100,0) | V18: =Q18+U18 | W18: =O18+V18
A19: 18 | K19: =IFERROR(E19*J19,0) | O19: =SUM(L19:N19)+IF(I19="EUR",K19,K19) | Q19: =IFERROR(O19*P19/100,0) | R19: Standard | T19: =IF(R19="Manual", IFERROR(S19, Summary!B5), IF(R19="Reduced1", Summary!C5, IF(R19="Reduced2", Summary!D5, Summary!B5))) | U19: =IFERROR((O19+Q19)*T19/100,0) | V19: =Q19+U19 | W19: =O19+V19
A20: 19 | K20: =IFERROR(E20*J20,0) | O20: =SUM(L20:N20)+IF(I20="EUR",K20,K20) | Q20: =IFERROR(O20*P20/100,0) | R20: Standard | T20: =IF(R20="Manual", IFERROR(S20, Summary!B5), IF(R20="Reduced1", Summary!C5, IF(R20="Reduced2", Summary!D5, Summary!B5))) | U20: =IFERROR((O20+Q20)*T20/100,0) | V20: =Q20+U20 | W20: =O20+V20
A21: 20 | K21: =IFERROR(E21*J21,0) | O21: =SUM(L21:N21)+IF(I21="EUR",K21,K21) | Q21: =IFERROR(O21*P21/100,0) | R21: Standard | T21: =IF(R21="Manual", IFERROR(S21, Summary!B5), IF(R21="Reduced1", Summary!C5, IF(R21="Reduced2", Summary!D5, Summary!B5))) | U21: =IFERROR((O21+Q21)*T21/100,0) | V21: =Q21+U21 | W21: =O21+V21
A22: 21 | K22: =IFERROR(E22*J22,0) | O22: =SUM(L22:N22)+IF(I22="EUR",K22,K22) | Q22: =IFERROR(O22*P22/100,0) | R22: Standard | T22: =IF(R22="Manual", IFERROR(S22, Summary!B5), IF(R22="Reduced1", Summary!C5, IF(R22="Reduced2", Summary!D5, Summary!B5))) | U22: =IFERROR((O22+Q22)*T22/100,0) | V22: =Q22+U22 | W22: =O22+V22
A23: 22 | K23: =IFERROR(E23*J23,0) | O23: =SUM(L23:N23)+IF(I23="EUR",K23,K23) | Q23: =IFERROR(O23*P23/100,0) | R23: Standard | T23: =IF(R23="Manual", IFERROR(S23, Summary!B5), IF(R23="Reduced1", Summary!C5, IF(R23="Reduced2", Summary!D5, Summary!B5))) | U23: =IFERROR((O23+Q23)*T23/100,0) | V23: =Q23+U23 | W23: =O23+V23
A24: 23 | K24: =IFERROR(E24*J24,0) | O24: =SUM(L24:N24)+IF(I24="EUR",K24,K24) | Q24: =IFERROR(O24*P24/100,0) | R24: Standard | T24: =IF(R24="Manual", IFERROR(S24, Summary!B5), IF(R24="Reduced1", Summary!C5, IF(R24="Reduced2", Summary!D5, Summary!B5))) | U24: =IFERROR((O24+Q24)*T24/100,0) | V24: =Q24+U24 | W24: =O24+V24
A25: 24 | K25: =IFERROR(E25*J25,0) | O25: =SUM(L25:N25)+IF(I25="EUR",K25,K25) | Q25: =IFERROR(O25*P25/100,0) | R25: Standard | T25: =IF(R25="Manual", IFERROR(S25, Summary!B5), IF(R25="Reduced1", Summary!C5, IF(R25="Reduced2", Summary!D5, Summary!B5))) | U25: =IFERROR((O25+Q25)*T25/100,0) | V25: =Q25+U25 | W25: =O25+V25
A26: 25 | K26: =IFERROR(E26*J26,0) | O26: =SUM(L26:N26)+IF(I26="EUR",K26,K26) | Q26: =IFERROR(O26*P26/100,0) | R26: Standard | T26: =IF(R26="Manual", IFERROR(S26, Summary!B5), IF(R26="Reduced1", Summary!C5, IF(R26="Reduced2", Summary!D5, Summary!B5))) | U26: =IFERROR((O26+Q26)*T26/100,0) | V26: =Q26+U26 | W26: =O26+V26
A27: 26 | K27: =IFERROR(E27*J27,0) | O27: =SUM(L27:N27)+IF(I27="EUR",K27,K27) | Q27: =IFERROR(O27*P27/100,0) | R27: Standard | T27: =IF(R27="Manual", IFERROR(S27, Summary!B5), IF(R27="Reduced1", Summary!C5, IF(R27="Reduced2", Summary!D5, Summary!B5))) | U27: =IFERROR((O27+Q27)*T27/100,0) | V27: =Q27+U27 | W27: =O27+V27
A28: 27 | K28: =IFERROR(E28*J28,0) | O28: =SUM(L28:N28)+IF(I28="EUR",K28,K28) | Q28: =IFERROR(O28*P28/100,0) | R28: Standard | T28: =IF(R28="Manual", IFERROR(S28, Summary!B5), IF(R28="Reduced1", Summary!C5, IF(R28="Reduced2", Summary!D5, Summary!B5))) | U28: =IFERROR((O28+Q28)*T28/100,0) | V28: =Q28+U28 | W28: =O28+V28
A29: 28 | K29: =IFERROR(E29*J29,0) | O29: =SUM(L29:N29)+IF(I29="EUR",K29,K29) | Q29: =IFERROR(O29*P29/100,0) | R29: Standard | T29: =IF(R29="Manual", IFERROR(S29, Summary!B5), IF(R29="Reduced1", Summary!C5, IF(R29="Reduced2", Summary!D5, Summary!B5))) | U29: =IFERROR((O29+Q29)*T29/100,0) | V29: =Q29+U29 | W29: =O29+V29
A30: 29 | K30: =IFERROR(E30*J30,0) | O30: =SUM(L30:N30)+IF(I30="EUR",K30,K30) | Q30: =IFERROR(O30*P30/100,0) | R30: Standard | T30: =IF(R30="Manual", IFERROR(S30, Summary!B5), IF(R30="Reduced1", Summary!C5, IF(R30="Reduced2", Summary!D5, Summary!B5))) | U30: =IFERROR((O30+Q30)*T30/100,0) | V30: =Q30+U30 | W30: =O30+V30
A31: 30 | K31: =IFERROR(E31*J31,0) | O31: =SUM(L31:N31)+IF(I31="EUR",K31,K31) | Q31: =IFERROR(O31*P31/100,0) | R31: Standard | T31: =IF(R31="Manual", IFERROR(S31, Summary!B5), IF(R31="Reduced1", Summary!C5, IF(R31="Reduced2", Summary!D5, Summary!B5))) | U31: =IFERROR((O31+Q31)*T31/100,0) | V31: =Q31+U31 | W31: =O31+V31
A32: 31 | K32: =IFERROR(E32*J32,0) | O32: =SUM(L32:N32)+IF(I32="EUR",K32,K32) | Q32: =IFERROR(O32*P32/100,0) | R32: Standard | T32: =IF(R32="Manual", IFERROR(S32, Summary!B5), IF(R32="Reduced1", Summary!C5, IF(R32="Reduced2", Summary!D5, Summary!B5))) | U32: =IFERROR((O32+Q32)*T32/100,0) | V32: =Q32+U32 | W32: =O32+V32
A33: 32 | K33: =IFERROR(E33*J33,0) | O33: =SUM(L33:N33)+IF(I33="EUR",K33,K33) | Q33: =IFERROR(O33*P33/100,0) | R33: Standard | T33: =IF(R33="Manual", IFERROR(S33, Summary!B5), IF(R33="Reduced1", Summary!C5, IF(R33="Reduced2", Summary!D5, Summary!B5))) | U33: =IFERROR((O33+Q33)*T33/100,0) | V33: =Q33+U33 | W33: =O33+V33
A34: 33 | K34: =IFERROR(E34*J34,0) | O34: =SUM(L34:N34)+IF(I34="EUR",K34,K34) | Q34: =IFERROR(O34*P34/100,0) | R34: Standard | T34: =IF(R34="Manual", IFERROR(S34, Summary!B5), IF(R34="Reduced1", Summary!C5, IF(R34="Reduced2", Summary!D5, Summary!B5))) | U34: =IFERROR((O34+Q34)*T34/100,0) | V34: =Q34+U34 | W34: =O34+V34
A35: 34 | K35: =IFERROR(E35*J35,0) | O35: =SUM(L35:N35)+IF(I35="EUR",K35,K35) | Q35: =IFERROR(O35*P35/100,0) | R35: Standard | T35: =IF(R35="Manual", IFERROR(S35, Summary!B5), IF(R35="Reduced1", Summary!C5, IF(R35="Reduced2", Summary!D5, Summary!B5))) | U35: =IFERROR((O35+Q35)*T35/100,0) | V35: =Q35+U35 | W35: =O35+V35
A36: 35 | K36: =IFERROR(E36*J36,0) | O36: =SUM(L36:N36)+IF(I36="EUR",K36,K36) | Q36: =IFERROR(O36*P36/100,0) | R36: Standard | T36: =IF(R36="Manual", IFERROR(S36, Summary!B5), IF(R36="Reduced1", Summary!C5, IF(R36="Reduced2", Summary!D5, Summary!B5))) | U36: =IFERROR((O36+Q36)*T36/100,0) | V36: =Q36+U36 | W36: =O36+V36
A37: 36 | K37: =IFERROR(E37*J37,0) | O37: =SUM(L37:N37)+IF(I37="EUR",K37,K37) | Q37: =IFERROR(O37*P37/100,0) | R37: Standard | T37: =IF(R37="Manual", IFERROR(S37, Summary!B5), IF(R37="Reduced1", Summary!C5, IF(R37="Reduced2", Summary!D5, Summary!B5))) | U37: =IFERROR((O37+Q37)*T37/100,0) | V37: =Q37+U37 | W37: =O37+V37
A38: 37 | K38: =IFERROR(E38*J38,0) | O38: =SUM(L38:N38)+IF(I38="EUR",K38,K38) | Q38: =IFERROR(O38*P38/100,0) | R38: Standard | T38: =IF(R38="Manual", IFERROR(S38, Summary!B5), IF(R38="Reduced1", Summary!C5, IF(R38="Reduced2", Summary!D5, Summary!B5))) | U38: =IFERROR((O38+Q38)*T38/100,0) | V38: =Q38+U38 | W38: =O38+V38
A39: 38 | K39: =IFERROR(E39*J39,0) | O39: =SUM(L39:N39)+IF(I39="EUR",K39,K39) | Q39: =IFERROR(O39*P39/100,0) | R39: Standard | T39: =IF(R39="Manual", IFERROR(S39, Summary!B5), IF(R39="Reduced1", Summary!C5, IF(R39="Reduced2", Summary!D5, Summary!B5))) | U39: =IFERROR((O39+Q39)*T39/100,0) | V39: =Q39+U39 | W39: =O39+V39
A40: 39 | K40: =IFERROR(E40*J40,0) | O40: =SUM(L40:N40)+IF(I40="EUR",K40,K40) | Q40: =IFERROR(O40*P40/100,0) | R40: Standard | T40: =IF(R40="Manual", IFERROR(S40, Summary!B5), IF(R40="Reduced1", Summary!C5, IF(R40="Reduced2", Summary!D5, Summary!B5))) | U40: =IFERROR((O40+Q40)*T40/100,0) | V40: =Q40+U40 | W40: =O40+V40
...

Sheet Lists
A1: Country | B1: Austria | C1: Belgium | D1: Bulgaria | E1: Croatia | F1: Cyprus | G1: Czech Republic | H1: Denmark | I1: Estonia | J1: Finland | K1: France | L1: Germany | M1: Greece | N1: Hungary | O1: Ireland | P1: Italy | Q1: Latvia | R1: Lithuania | S1: Luxembourg | T1: Malta | U1: Netherlands | V1: Poland | W1: Portugal | X1: Romania | Y1: Slovakia | Z1: Slovenia | AA1: Spain | AB1: Sweden | AC1: United Kingdom | AD1: Norway | AE1: Switzerland | AF1: Iceland | AG1: Liechtenstein
A2: CountryISO | B2: AT | C2: BE | D2: BG | E2: HR | F2: CY | G2: CZ | H2: DK | I2: EE | J2: FI | K2: FR | L2: DE | M2: GR | N2: HU | O2: IE | P2: IT | Q2: LV | R2: LT | S2: LU | T2: MT | U2: NL | V2: PL | W2: PT | X2: RO | Y2: SK | Z2: SI | AA2: ES | AB2: SE | AC2: GB | AD2: NO | AE2: CH | AF2: IS | AG2: LI
A4: Incoterms | B4: EXW | C4: FCA | D4: CPT | E4: CIP | F4: DAP | G4: DPU | H4: DDP | I4: FAS | J4: FOB | K4: CFR | L4: CIF
A5: TransportMode | B5: 1 - Sea | C5: 2 - Rail | D5: 3 - Road | E5: 4 - Air | F5: 5 - Mail | G5: 6 - Fixed installations | H5: 7 - Inland waterway | I5: 9 - Own propulsion
A6: Currency | B6: EUR | C6: USD | D6: GBP | E6: SEK | F6: NOK | G6: DKK | H6: CHF | I6: PLN | J6: CZK | K6: JPY | L6: CNY
A7: Units | B7: PCE | C7: KG | D7: LTR | E7: MTR | F7: M2 | G7: M3 | H7: SET | I7: PAI
A8: ProcedureCode | B8: 4000 - Release for free circulation | C8: 4200 - Release + onward supply | D8: 1000 - Definitive export | E8: 1040 - Temporary export | F8: 3171 - Transit | G8: 5100 - Inward processing | H8: 6100 - Temporary admission
A10: LangCodes | B10: EN | C10: EE | D10: DE | E10: FR
A12: CountryLanguageMap
A13: Austria | B13: DE
A14: Belgium | B14: FR
A15: Bulgaria | B15: EN
A16: Croatia | B16: EN
A17: Cyprus | B17: EN
A18: Czech Republic | B18: EN
A19: Denmark | B19: EN
A20: Estonia | B20: EE
A21: Finland | B21: EN
A22: France | B22: FR
A23: Germany | B23: DE
A24: Greece | B24: EN
... A44: Liechtenstein | B44: DE
A198: VATType | B198: Standard | C198: Reduced1 | D198: Reduced2 | E198: Manual
A200: VAT_Table
A201: Country | B201: Standard | C201: Reduced1 | D201: Reduced2
A202: Austria | B202: 20 | C202: 10 | D202: 13
A203: Belgium | B203: 21 | C203: 6 | D203: 12
A204: Bulgaria | B204: 20 | C204: 9 | D204: 0
A205: Croatia | B205: 25 | C205: 13 | D205: 5
A206: Cyprus | B206: 19 | C206: 5 | D206: 9
A207: Czech Republic | B207: 21 | C207: 12 | D207: 10
A208: Denmark | B208: 25 | C208: 0 | D208: 0
A209: Estonia | B209: 22 | C209: 9 | D209: 5
A210: Finland | B210: 24 | C210: 14 | D210: 10
A211: France | B211: 20 | C211: 10 | D211: 5.5
A212: Germany | B212: 19 | C212: 7 | D212: 0
A213: Greece | B213: 24 | C213: 13 | D213: 6
... A233: Liechtenstein | B233: 8.1 | C233: 2.6 | D233: 3.8

Sheet Summary
A1: Totals
A3: Selected Country | B3: =Declaration!B3
A4: Language | B4: =Declaration!I3
A5: VAT Rates (%) | B5: =IFERROR(XLOOKUP(B3, VAT_Country, VAT_Standard),"") | C5: =IFERROR(XLOOKUP(B3, VAT_Country, VAT_Reduced1),"") | D5: =IFERROR(XLOOKUP(B3, VAT_Country, VAT_Reduced2),"")
A6: Customs Value (EUR) | B6: =SUM(Items!O2:O1000)
A7: Duty (EUR) | B7: =SUM(Items!Q2:Q1000)
A8: VAT (EUR) | B8: =SUM(Items!U2:U1000)
A9: Total Taxes (EUR) | B9: =SUM(Items!V2:V1000)
A10: Grand Total (EUR) | B10: =SUM(Items!W2:W1000)

Sheet Translations
A1: Key | B1: EN | C1: EE | D1: DE | E1: FR
A2: Select Country | B2: Select Country | C2: Vali riik | D2: Land wählen | E2: Sélectionner le pays
A3: Select Flow | B3: Select Flow | C3: Vali protsess | D3: Vorgang wählen | E3: Sélectionner le flux
A4: Declarant (Company Name) | B4: Declarant (Company Name) | C4: Deklarant (Ettevõtte nimi) | D4: Anmelder (Firmenname) | E4: Déclarant (Raison sociale)
A5: Registry code / EORI / VAT | B5: Registry code / EORI / VAT | C5: Registrikood / EORI / KMKR | D5: Reg.-Nr. / EORI / USt-IdNr. | E5: N° registre / EORI / TVA
A6: Address | B6: Address | C6: Aadress | D6: Adresse | E6: Adresse
A7: Contact person | B7: Contact person | C7: Kontaktisik | D7: Ansprechpartner | E7: Contact
A8: Contact email | B8: Contact email | C8: E-post | D8: E-Mail | E8: E-mail
A9: Contact phone | B9: Contact phone | C9: Telefon | D9: Telefon | E9: Téléphone
A10: Consignor (Seller / Exporter) | B10: Consignor (Seller / Exporter) | C10: Saatja (Müüja / Eksportija) | D10: Versender (Verkäufer / Exporteur) | E10: Expéditeur (Vendeur / Exportateur)
A11: Consignee (Buyer / Importer) | B11: Consignee (Buyer / Importer) | C11: Saaja (Ostja / Importija) | D11: Empfänger (Käufer / Importeur) | E11: Destinataire (Acheteur / Importateur)
A12: Consignor VAT/EORI | B12: Consignor VAT/EORI | C12: Saatja KMKR/EORI | D12: USt-IdNr./EORI des Versenders | E12: TVA/EORI de l’expéditeur
... A28: Language | B28: Language | C28: Keel | D28: Sprache | E28: Langue
