Workbook

Sheet PRE-OPERATING, EQUIPMENT
B1: Initial / Expanding Stock | H1: EQUIPMENT DEPRICIATION TABLE
A2: S/N | B2: Stock / Item | C2: Description | D2: Quantity | E2: Unit Cost | F2: Total | H2: S/N | I2: EQUIPMENT | J2: DESCRIPTION | K2: QTY | L2: UNIT COST (N) | M2: VALUE (N) | N2: LIFE SPAN (MONTHS) | O2: MONTHLY DEPRECIATION N
A3: 1 | B3: A4 Paper | D3: 24 | E3: 5600 | F3: =D3*E3 -> 134400 | H3: 1 | I3: UK used desktop computers | J3: 4 gig ram, 120HDD, 3.9GHz | K3: 4 | L3: 30000 | M3: =K3*L3 -> 120000 | N3: 24 | O3: =M3/N3 -> 5000
A4: 2 | B4: Pen | D4: 3 | E4: 30 | F4: =D4*E4 -> 90 | H4: 2 | I4: Uk used HP laserjet printer | J4: A4 black & white printers | K4: 2 | L4: 60000 | M4: =K4*L4 -> 120000 | N4: 36 | O4: =M4/N4 -> 3333.3333
A5: 3 | B5: Stapple Pin | D5: 12 | E5: 100 | F5: =D5*E5 -> 1200 | H5: 3 | I5: Uk used HP laserjet printer | J5: A3 colour printer | K5: 1 | L5: 150000 | M5: =K5*L5 -> 150000 | N5: 36 | O5: =M5/N5 -> 4166.6667
A6: 4 | B6: Photocopier Toner | D6: 3 | E6: 6000 | F6: =D6*E6 -> 18000 | H6: 4 | I6: VSAT wireless | J6: wifi installation | K6: 1 | L6: 200000 | M6: =K6*L6 -> 200000 | N6: 36 | O6: =M6/N6 -> 5555.5556
A7: 5 | B7: Data | D7: 3 | E7: 12000 | F7: =D7*E7 -> 36000
A8: 6 | B8: Marker | D8: 3 | E8: 700 | F8: =D8*E8 -> 2100 | H8: 6 | I8: Digital personal fingerprint | K8: 1 | L8: 25000 | M8: =K8*L8 -> 25000 | N8: 36 | O8: =M8/N8 -> 694.44444
A9: 7 | B9: Binding Materials | D9: 12 | E9: 3700 | F9: =D9*E9 -> 44400 | H9: 7 | I9: Biometric scanner | K9: 1 | L9: 50000 | M9: =K9*L9 -> 50000 | N9: 36 | O9: =M9/N9 -> 1388.8889
A10: 8 | H10: 8 | I10: Projector/screen | K10: 1 | L10: 70000 | M10: =K10*L10 -> 70000 | N10: 36 | O10: =M10/N10 -> 1944.4444
A11: 9 | B11: DVD RW | D11: 3 | E11: 1800 | F11: =D11*E11 -> 5400 | H11: 9 | I11: 1 KVA inverter | K11: 1 | L11: 150000 | M11: =K11*L11 -> 150000 | N11: 24 | O11: =M11/N11 -> 6250
A12: 10 | B12: DVD Pack | D12: 3 | E12: 500 | F12: =D12*E12 -> 1500 | H12: 10 | I12: Laminating machine | K12: 1 | L12: 8000 | M12: =K12*L12 -> 8000 | N12: 36 | O12: =M12/N12 -> 222.22222
A13: 11 | B13: Laminating Film | D13: 3 | E13: 1500 | F13: =D13*E13 -> 4500 | H13: 11 | I13: Aluminium Show glass | K13: 1 | L13: 50000 | M13: =K13*L13 -> 50000 | N13: 36 | O13: =M13/N13 -> 1388.8889
A14: 12 | B14: GOTv Subscription | D14: 3 | E14: 1800 | F14: =D14*E14 -> 5400 | H14: 12
A15: 13 | B15: Functional Website | C15: online database system | D15: 3 | E15: 12500 | F15: =D15*E15 -> 37500 | H15: 13
A16: 14 | B16: Black Toner Printer | D16: 12 | E16: 1000 | F16: =D16*E16 -> 12000 | H16: 14
A17: 15 | B17: Color Toner Printer | D17: 3 | E17: 10000 | F17: =D17*E17 -> 30000 | H17: 15
A18: 16 | B18: Business Card | D18: 4500 | E18: 10 | F18: =D18*E18 -> 45000 | H18: 16
A19: 17 | B19: Board Cleaner | D19: 1 | E19: 350 | F19: =D19*E19 -> 350 | H19: 17
A20: 18 | B20: Board Cleaner Spirit | D20: 3 | E20: 150 | F20: =D20*E20 -> 450 | H20: 18
A21: 19 | B21: Toileteries | D21: 3 | E21: 1000 | F21: =D21*E21 -> 3000 | H21: 19
A22: 20 | B22: 8 gig USB flashdrives | D22: 30 | E22: 1100 | F22: =D22*E22 -> 33000 | H22: 20
A23: 21 | B23: 16 gig USB flashdrives | D23: 30 | E23: 1500 | F23: =D23*E23 -> 45000 | I23: TOTAL | M23: =SUM(M3:M22) -> 943000 | O23: =SUM(O3:O22) -> 29944.444
A24: 22 | B24: Earpiece | D24: 30 | E24: 500 | F24: =D24*E24 -> 15000
A25: 23 | B25: Headset | D25: 10 | E25: 3800 | F25: =D25*E25 -> 38000
A26: 24 | B26: 8 gig memory card | D26: 30 | E26: 950 | F26: =D26*E26 -> 28500
A27: 25 | B27: 16 gig memory card | D27: 30 | E27: 1300 | F27: =D27*E27 -> 39000 | I27: PRE-OPERATING ACTIVITIES AND EXPENSES
A28: 26 | B28: phone chargers | D28: 30 | E28: 1000 | F28: =D28*E28 -> 30000 | I28: PRE-OPERATING ACTIVITIES | J28: DESCRIPTION/ DETAILS | K28: AMOUNT N
A29: 27 | B29: USB cords | D29: 30 | E29: 350 | F29: =D29*E29 -> 10500 | I29: Rental of store | J29: 2 years rent | K29: 400000
A30: 28 | B30: A3 paper | C30: large format printing | D30: 3 | E30: 2400 | F30: 7200 | I30: Business registration
A31: 29 | F31: =D31*E31 -> 0 | I31: Furniture /Fittings/Installation | J31: Office fittings/furniture | K31: 150000
A32: 30 | F32: =D32*E32 -> 0 | I32: Equipment | J32: value of equipments + 13% of inflation | K32: =13%*M23+M23 -> 1065590
B33: TOTAL | F33: =SUM(F3:F32) -> 627490 | I33: Insurance | J33: 5% of equipment + 5% of Initial stock | K33: =5%*M23 -> 47150
I34: Initial advertisement | K34: 50000
I35: Recruitment of staff | J35: 3 months salary | K35: 150000
I36: TOTAL | K36: =SUM(K29:K35) -> 1862740

Sheet OPERATING EXPENSE
A1: QUATERLY OPERATING EXPENSES
B2: Period 1 | C2: Period 2 | D2: Period 3 | E2: Period 4 | F2: Period 5 | G2: Period 6 | H2: Period 7 | I2: Period 8 | J2: Period 9 | K2: Period 10 | L2: Period 11 | M2: Period 12 | N2: TOTAL
A3: Expenses | B3: Jan- Mar | C3: Apr-June | D3: July-Sept | E3: Oct-Dec | F3: Jan- Mar | G3: Apr-June | H3: July-Sept | I3: Oct-Dec | J3: Jan- Mar | K3: Apr-June | L3: July-Sept | M3: Oct-Dec | N3: Total
A4: Salary | B4: =D34*3 -> 240000 | C4: =B4 -> 240000 | D4: =C4 -> 240000 | E4: =D4 -> 240000 | F4: =5%*E4+E4 -> 252000 | G4: =F4 -> 252000 | H4: =G4 -> 252000 | I4: =H4 -> 252000 | J4: =5%*I4+I4 -> 264600 | K4: =J4 -> 264600 | L4: =K4 -> 264600 | M4: =L4 -> 264600 | N4: =SUM(B4:M4) -> 3026400
A5: Repair & Maintenance | B5: 10000 | C5: 10000 | D5: 10000 | E5: 10000 | F5: 10000 | G5: 10000 | H5: 10000 | I5: 10000 | J5: 10000 | K5: 10000 | L5: 10000 | M5: 10000 | N5: =SUM(B5:M5) -> 120000
A6: Advertising | B6: 50000 | C6: 10000 | D6: 10000 | E6: 10000 | F6: 10000 | G6: 10000 | H6: 10000 | I6: 10000 | J6: 10000 | K6: 10000 | L6: 10000 | M6: 10000 | N6: =SUM(B6:M6) -> 160000
A7: Account/legal | N7: =SUM(B7:M7) -> 0
A8: Consumables | N8: =SUM(B8:M8) -> 0
A9: Delivery | N9: =SUM(B9:M9) -> 0
A10: Fuel/Diesel | B10: 3045 | C10: 3045 | D10: 3045 | E10: 3045 | F10: 3045 | G10: 3045 | H10: 3045 | I10: 3045 | J10: 3045 | K10: 3045 | L10: 3045 | M10: 3045 | N10: =SUM(B10:M10) -> 36540
A11: Telephone | B11: 3000 | C11: 3000 | D11: 3000 | E11: 3000 | F11: 3000 | G11: 3000 | H11: 3000 | I11: 3000 | J11: 3000 | K11: 3000 | L11: 3000 | M11: 3000 | N11: =SUM(B11:M11) -> 36000
A12: Insurance | N12: =SUM(B12:M12) -> 0
A13: Utilities (NEPA /WATER) | N13: =SUM(B13:M13) -> 0
A14: Security fee | N14: =SUM(B14:M14) -> 0
A15: Transport and logistics | B15: 10000 | C15: 10000 | D15: 10000 | E15: 10000 | F15: 10000 | G15: 10000 | H15: 10000 | I15: 10000 | J15: 10000 | K15: 10000 | L15: 10000 | M15: 10000 | N15: =SUM(B15:M15) -> 120000
A16: Total Expense | B16: =SUM(B4:B15) -> 316045 | C16: =SUM(C4:C15) -> 276045 | D16: =SUM(D4:D15) -> 276045 | E16: =SUM(E4:E15) -> 276045 | F16: =SUM(F4:F15) -> 288045 | G16: =SUM(G4:G15) -> 288045 | H16: =SUM(H4:H15) -> 288045 | I16: =SUM(I4:I15) -> 288045 | ... N16: =SUM(N4:N15) -> 3498940
A20: Assumptions:
A21: 1. Salary is assumed to increase by 5% yearly.
B25: SALARY
B26: NAME | C26: DESIGNATION | D26: MONTHLY SALARY(N) | E26: ANNUAL SALARY(N)
B27: Staff 1 | C27: C.E.O | D27: 40000 | E27: =D27*12 -> 480000
B28: Staff 2 | C28: Computer operator 1 | D28: 20000 | E28: =D28*12 -> 240000
B29: Staff 3 | C29: Computer operator 1 | D29: 20000 | E29: =D29*12 -> 240000
B30: Staff 4 | E30: =D30*12 -> 0
B31: Staff 5 | E31: =D31*12 -> 0
B32: Staff 6 | E32: =D32*12 -> 0
B33: Staff 7 | E33: =D33*12 -> 0
C34: TOTAL | D34: =SUM(D27:D33) -> 80000 | E34: =SUM(E27:E33) -> 960000

Sheet LOAN REPAYMENT
A1: Initial/Required Expansion Capital Estimate | E1: Loan Repayment Schedule
A2: ITEMS | B2: AMOUNT | C2: COMMENT | E2: Month | F2: Principal | G2: Monthly Principal | H2: Monthly Interest | I2: Principal + Interest | J2: Cumulative
A3: Pre-operating Expenses | B3: ='PRE-OPERATING, EQUIPMENT'!K36 -> 1862740
A4: Expanding Stock (3 months) | B4: ='PRE-OPERATING, EQUIPMENT'!F33 -> 627490 | E4: 0 | F4: =B9 -> 2525647.5
A5: Initial Operating Expenses -3months | B5: ='OPERATING EXPENSE'!B16 -> 316045 | E5: 1 | F5: =F4-G4 -> 2525647.5 | G5: 0 | H5: =F4*9%/12 -> 18942.356 | I5: =H5 -> 18942.356 | J5: =I5 -> 18942.356
A6: Total Expansion Capital Estimated | B6: =SUM(B3:B5) -> 2806275 | E6: 2 | F6: =F5-G5 -> 2525647.5 | G6: 0 | H6: =H5 -> 18942.356 | I6: =I5 -> 18942.356 | J6: =J5+I6 -> 37884.713
A7: SOURCES OF FUNDS | B7: AMOUNT | C7: % | E7: 3 | F7: =F6-G6 -> 2525647.5 | G7: 0 | H7: =H6 -> 18942.356 | I7: =H7+G7 -> 18942.356 | J7: =J6+I7 -> 56827.069
A8: Personal Fund /Equity | B8: =10%*B6 -> 280627.5 | C8: 0.1 | E8: 4 | F8: =F7-G7 -> 2525647.5 | G8: =F4/33 -> 76534.773 | H8: =H7 -> 18942.356 | I8: =H8+G8 -> 95477.129 | J8: =J7+I8 -> 152304.2
A9: Bank Loan | B9: =B6*90% -> 2525647.5 | C9: 0.9 | E9: 5 | F9: =F8-G8 -> 2449112.7 | G9: =G8 -> 76534.773 | H9: =H8 -> 18942.356 | I9: =H9+G9 -> 95477.129 | J9: =J8+I9 -> 247781.33
A10: Total Funds Sourced | B10: =SUM(B8:B9) -> 2806275 | C10: 1 | E10: 6 | F10: =F9-G9 -> 2372578 | G10: =G9 -> 76534.773 | H10: =H9 -> 18942.356 | I10: =H10+G10 -> 95477.129 | J10: =J9+I10 -> 343258.46
E11: 7 | F11: =F10-G10 -> 2296043.2 | G11: =G10 -> 76534.773 | H11: =H10 -> 18942.356 | I11: =H11+G11 -> 95477.129 | J11: =J10+I11 -> 438735.58
A12: ASSUMPTION | E12: 8 | F12: =F11-G11 -> 2219508.4 | G12: =G11 -> 76534.773 | H12: =H11 -> 18942.356 | I12: =H12+G12 -> 95477.129 | J12: =J11+I12 -> 534212.71
A13: 1. Interest rate is at 9% on an annual reducing balance method. | E13: 9 | F13: =F12-G12 -> 2142973.6 | G13: =G12 -> 76534.773 | H13: =H12 -> 18942.356 | I13: =H13+G13 -> 95477.129 | J13: =J12+I13 -> 629689.84
A14: 2. Moratorium is assumed at three month. | E14: 10 | F14: =F13-G13 -> 2066438.9 | G14: =G13 -> 76534.773 | H14: =H13 -> 18942.356 | I14: =H14+G14 -> 95477.129 | J14: =J13+I14 -> 725166.97
E15: 11 | F15: =F14-G14 -> 1989904.1 | G15: =G14 -> 76534.773 | H15: =H14 -> 18942.356 | I15: =H15+G15 -> 95477.129 | J15: =J14+I15 -> 820644.1
E16: 12 | F16: =F15-G15 -> 1913369.3 | G16: =G15 -> 76534.773 | H16: =H15 -> 18942.356 | I16: =H16+G16 -> 95477.129 | J16: =J15+I16 -> 916121.23
E17: 13 | F17: =F16-G16 -> 1836834.5 | G17: =G16 -> 76534.773 | H17: =9%*F17/12 -> 13776.259 | I17: =H17+G17 -> 90311.032 | J17: =J16+I17 -> 1006432.3
E18: 14 | F18: =F17-G17 -> 1760299.8 | G18: =G17 -> 76534.773 | H18: =H17 -> 13776.259 | I18: =H18+G18 -> 90311.032 | J18: =J17+I18 -> 1096743.3
E19: 15 | F19: =F18-G18 -> 1683765 | G19: =G18 -> 76534.773 | H19: =H18 -> 13776.259 | I19: =H19+G19 -> 90311.032 | J19: =J18+I19 -> 1187054.3
E20: 16 | F20: =F19-G19 -> 1607230.2 | G20: =G19 -> 76534.773 | H20: =H19 -> 13776.259 | I20: =H20+G20 -> 90311.032 | J20: =J19+I20 -> 1277365.4
E21: 17 | F21: =F20-G20 -> 1530695.5 | G21: =G20 -> 76534.773 | H21: =H20 -> 13776.259 | I21: =H21+G21 -> 90311.032 | J21: =J20+I21 -> 1367676.4
E22: 18 | F22: =F21-G21 -> 1454160.7 | G22: =G21 -> 76534.773 | H22: =H21 -> 13776.259 | I22: =H22+G22 -> 90311.032 | J22: =J21+I22 -> 1457987.4
E23: 19 | F23: =F22-G22 -> 1377625.9 | G23: =G22 -> 76534.773 | H23: =H22 -> 13776.259 | I23: =H23+G23 -> 90311.032 | J23: =J22+I23 -> 1548298.5
E24: 20 | F24: =F23-G23 -> 1301091.1 | G24: =G23 -> 76534.773 | H24: =H23 -> 13776.259 | I24: =H24+G24 -> 90311.032 | J24: =J23+I24 -> 1638609.5
E25: 21 | F25: =F24-G24 -> 1224556.4 | G25: =G24 -> 76534.773 | H25: =H24 -> 13776.259 | I25: =H25+G25 -> 90311.032 | J25: =J24+I25 -> 1728920.5
E26: 22 | F26: =F25-G25 -> 1148021.6 | G26: =G25 -> 76534.773 | H26: =H25 -> 13776.259 | I26: =H26+G26 -> 90311.032 | J26: =J25+I26 -> 1819231.5
E27: 23 | F27: =F26-G26 -> 1071486.8 | G27: =G26 -> 76534.773 | H27: =H26 -> 13776.259 | I27: =H27+G27 -> 90311.032 | J27: =J26+I27 -> 1909542.6
E28: 24 | F28: =F27-G27 -> 994952.05 | G28: =G27 -> 76534.773 | H28: =H27 -> 13776.259 | I28: =H28+G28 -> 90311.032 | J28: =J27+I28 -> 1999853.6
E29: 25 | F29: =F28-G28 -> 918417.27 | G29: =G28 -> 76534.773 | H29: =9%*F29/12 -> 6888.1295 | I29: =H29+G29 -> 83422.902 | J29: =J28+I29 -> 2083276.5
E30: 26 | F30: =F29-G29 -> 841882.5 | G30: =G29 -> 76534.773 | H30: =H29 -> 6888.1295 | I30: =H30+G30 -> 83422.902 | J30: =J29+I30 -> 2166699.4
E31: 27 | F31: =F30-G30 -> 765347.73 | G31: =G30 -> 76534.773 | H31: =H30 -> 6888.1295 | I31: =H31+G31 -> 83422.902 | J31: =J30+I31 -> 2250122.3
E32: 28 | F32: =F31-G31 -> 688812.95 | G32: =G31 -> 76534.773 | H32: =H31 -> 6888.1295 | I32: =H32+G32 -> 83422.902 | J32: =J31+I32 -> 2333545.2
E33: 29 | F33: =F32-G32 -> 612278.18 | G33: =G32 -> 76534.773 | H33: =H32 -> 6888.1295 | I33: =H33+G33 -> 83422.902 | J33: =J32+I33 -> 2416968.1
E34: 30 | F34: =F33-G33 -> 535743.41 | G34: =G33 -> 76534.773 | H34: =H33 -> 6888.1295 | I34: =H34+G34 -> 83422.902 | J34: =J33+I34 -> 2500391
E35: 31 | F35: =F34-G34 -> 459208.64 | G35: =G34 -> 76534.773 | H35: =H34 -> 6888.1295 | I35: =H35+G35 -> 83422.902 | J35: =J34+I35 -> 2583813.9
E36: 32 | F36: =F35-G35 -> 382673.86 | G36: =G35 -> 76534.773 | H36: =H35 -> 6888.1295 | I36: =H36+G36 -> 83422.902 | J36: =J35+I36 -> 2667236.8
E37: 33 | F37: =F36-G36 -> 306139.09 | G37: =G36 -> 76534.773 | H37: =H36 -> 6888.1295 | I37: =H37+G37 -> 83422.902 | J37: =J36+I37 -> 2750659.7
E38: 34 | F38: =F37-G37 -> 229604.32 | G38: =G37 -> 76534.773 | H38: =H37 -> 6888.1295 | I38: =H38+G38 -> 83422.902 | J38: =J37+I38 -> 2834082.6
E39: 35 | F39: =F38-G38 -> 153069.55 | G39: =G38 -> 76534.773 | H39: =H38 -> 6888.1295 | I39: =H39+G39 -> 83422.902 | J39: =J38+I39 -> 2917505.5
E40: 36 | F40: =F39-G39 -> 76534.773 | G40: =G39 -> 76534.773 | H40: =H39 -> 6888.1295 | I40: =H40+G40 -> 83422.902 | J40: =J39+I40 -> 3000928.4
...

Sheet PROPOSED PRICING
A1: PROPOSED PRICE LIST
A2: ITEM | B2: DECRIPTION | C2: WHOLE SELL COST PRICE (N) | D2: QTY CONSIDERED | E2: UNIT COST PRICE (N) | F2: WHOLE SALE SELLING PRICE (N) | G2: UNIT SELLING PRICE (N)
A3: Black and White Printing | C3: 67200 | D3: 12 | E3: =C3/D3 -> 5600 | F3: 300000 | G3: =F3/D3 -> 25000
A4: Photocopy | C4: 67200 | D4: 12 | E4: =C4/D4 -> 5600 | F4: 600000 | G4: =F4/D4 -> 50000
A5: Coloured printing | C5: 6000 | D5: 1 | E5: =C5/D5 -> 6000 | F5: 75000 | G5: =F5/D5 -> 75000
A6: Scanning | C6: 450 | D6: 90 | E6: =C6/D6 -> 5 | F6: 4500 | G6: =F6/D6 -> 50
A7: DVD + burning | C7: 6900 | D7: 3 | E7: =C7/D7 -> 2300 | F7: 15000 | G7: =F7/D7 -> 5000
A8: Basic website design | C8: 30000 | D8: 9 | E8: =C8/D8 -> 3333.3333 | F8: 270000 | G8: =F8/D8 -> 30000
A9: Premium website design | C9: 50000 | D9: 3 | E9: =C9/D9 -> 16666.667 | F9: 450000 | G9: =F9/D9 -> 150000
A10: Advanced website design | C10: 150000 | D10: 1 | E10: =C10/D10 -> 150000 | F10: 450000 | G10: =F10/D10 -> 450000
A11: Typesetting | C11: 1500 | D11: 300 | E11: =C11/D11 -> 5 | F11: 30000 | G11: =F11/D11 -> 100
A12: Online registrations | C12: 4500 | D12: 30 | E12: =C12/D12 -> 150 | F12: 15000 | G12: =F12/D12 -> 500
A13: Spiral binding | C13: 22200 | D13: 6 | E13: =C13/D13 -> 3700 | F13: 48000 | G13: =F13/D13 -> 8000
A14: Data analysis | C14: 30000 | D14: 6 | E14: =C14/D14 -> 5000 | F14: 90000 | G14: =F14/D14 -> 15000
... A32: Data analysis | C32: 27000 | D32: 9 | E32: =C32/D32 -> 3000 | F32: 90000 | G32: =F32/D32 -> 10000

Sheet Cost Forecast
A1: QUARTERLY COST FORECAST
C2: P1 | D2: P2 | E2: P3 | F2: P4 | G2: P5 | H2: P6 | I2: P7 | J2: P8 | K2: P9 | L2: P10 | M2: P11 | N2: P12 | O2: TOTAL
C3: Jan- Mar | D3: Apr-June | E3: July-Sept | F3: Oct-Dec | G3: Jan- Mar | H3: Apr-June | I3: July-Sept | J3: Oct-Dec | K3: Jan- Mar | L3: Apr-June | M3: July-Sept | N3: Oct-Dec | O3: Total
A4: Black and White Printing | B4: Qty | C4: 30 | D4: 10 | E4: 30 | F4: 30 | G4: 20 | H4: 30 | I4: 20 | J4: 20 | K4: 40 | L4: 20 | M4: 40 | N4: 30
B5: Price/ Unit | C5: ='PROPOSED PRICING'!E3 -> 5600 | D5: =C5 -> 5600 | E5: =D5 -> 5600 | F5: =E5 -> 5600 | G5: =F5 -> 5600 | H5: =G5 -> 5600 | I5: =H5 -> 5600 | J5: =I5 -> 5600 | K5: =J5 -> 5600 | ... N5: =M5 -> 5600
B6: Amt | C6: =C4*C5 -> 168000 | D6: =D4*D5 -> 56000 | E6: =E4*E5 -> 168000 | F6: =F4*F5 -> 168000 | G6: =G4*G5 -> 112000 | H6: =H4*H5 -> 168000 | I6: =I4*I5 -> 112000 | J6: =J4*J5 -> 112000 | ... N6: =N4*N5 -> 168000 | O6: =SUM(C6:N6) -> 1792000
A7: Photocopy | B7: Qty | C7: 30 | D7: 10 | E7: 30 | F7: 30 | G7: 20 | H7: 30 | I7: 20 | J7: 20 | K7: 30 | L7: 20 | M7: 30 | N7: 20
B8: Price/ Unit | C8: ='PROPOSED PRICING'!E4 -> 5600 | D8: =C8 -> 5600 | E8: =D8 -> 5600 | F8: =E8 -> 5600 | G8: =F8 -> 5600 | H8: =G8 -> 5600 | I8: =H8 -> 5600 | J8: =I8 -> 5600 | K8: =J8 -> 5600 | ... N8: =M8 -> 5600
B9: Amt | C9: =C7*C8 -> 168000 | D9: =D7*D8 -> 56000 | E9: =E7*E8 -> 168000 | F9: =F7*F8 -> 168000 | G9: =G7*G8 -> 112000 | H9: =H7*H8 -> 168000 | I9: =I7*I8 -> 112000 | J9: =J7*J8 -> 112000 | ... N9: =N7*N8 -> 112000 | O9: =SUM(C9:N9) -> 1624000
A10: Coloured printing | B10: Qty | C10: 1 | D10: 1 | E10: 1 | F10: 1 | G10: 1 | H10: 1 | I10: 1 | J10: 1 | K10: 1 | L10: 1 | M10: 1 | N10: 1
B11: Price/ Unit | C11: ='PROPOSED PRICING'!E5 -> 6000 | D11: =C11 -> 6000 | E11: =D11 -> 6000 | F11: =E11 -> 6000 | G11: =F11 -> 6000 | H11: =G11 -> 6000 | I11: =H11 -> 6000 | J11: =I11 -> 6000 | K11: =J11 -> 6000 | ... N11: =M11 -> 6000
B12: Amt | C12: =C10*C11 -> 6000 | D12: =D10*D11 -> 6000 | E12: =E10*E11 -> 6000 | F12: =F10*F11 -> 6000 | G12: =G10*G11 -> 6000 | H12: =H10*H11 -> 6000 | I12: =I10*I11 -> 6000 | J12: =J10*J11 -> 6000 | ... N12: =N10*N11 -> 6000 | O12: =SUM(C12:N12) -> 72000
A13: Scanning | B13: Qty | C13: 90 | D13: 30 | E13: 90 | F13: 90 | G13: 60 | H13: 90 | I13: 60 | J13: 60 | K13: 100 | L13: 60 | M13: 100 | N13: 90
B14: Price/ Unit | C14: ='PROPOSED PRICING'!E6 -> 5 | D14: =C14 -> 5 | E14: =D14 -> 5 | F14: =E14 -> 5 | G14: =F14 -> 5 | H14: =G14 -> 5 | I14: =H14 -> 5 | J14: =I14 -> 5 | K14: =J14 -> 5 | ... N14: =M14 -> 5
B15: Amt | C15: =C13*C14 -> 450 | D15: =D13*D14 -> 150 | E15: =E13*E14 -> 450 | F15: =F13*F14 -> 450 | G15: =G13*G14 -> 300 | H15: =H13*H14 -> 450 | I15: =I13*I14 -> 300 | J15: =J13*J14 -> 300 | ... N15: =N13*N14 -> 450 | O15: =SUM(C15:N15) -> 4600
A16: DVD + burning | B16: Qty | C16: 3 | D16: 1 | E16: 3 | F16: 3 | G16: 2 | H16: 3 | I16: 2 | J16: 2 | K16: 4 | L16: 2 | M16: 4 | N16: 3
B17: Price/ Unit | C17: ='PROPOSED PRICING'!E7 -> 2300 | D17: =C17 -> 2300 | E17: =D17 -> 2300 | F17: =E17 -> 2300 | G17: =F17 -> 2300 | H17: =G17 -> 2300 | I17: =H17 -> 2300 | J17: =I17 -> 2300 | K17: =J17 -> 2300 | ... N17: =M17 -> 2300
B18: Amt | C18: =C16*C17 -> 6900 | D18: =D16*D17 -> 2300 | E18: =E16*E17 -> 6900 | F18: =F16*F17 -> 6900 | G18: =G16*G17 -> 4600 | H18: =H16*H17 -> 6900 | I18: =I16*I17 -> 4600 | J18: =J16*J17 -> 4600 | ... N18: =N16*N17 -> 6900 | O18: =SUM(C18:N18) -> 73600
A19: Basic website design | B19: Qty | C19: 9 | D19: 9 | E19: 9 | F19: 9 | G19: 9 | H19: 9 | I19: 9 | J19: 9 | K19: 9 | L19: 9 | M19: 9 | N19: 9
B20: Price/ Unit | C20: ='PROPOSED PRICING'!E8 -> 3333.3333 | D20: =C20 -> 3333.3333 | E20: =D20 -> 3333.3333 | F20: =E20 -> 3333.3333 | G20: =F20 -> 3333.3333 | H20: =G20 -> 3333.3333 | I20: =H20 -> 3333.3333 | J20: =I20 -> 3333.3333 | K20: =J20 -> 3333.3333 | ... N20: =M20 -> 3333.3333
B21: Amt | C21: =C19*C20 -> 30000 | D21: =D19*D20 -> 30000 | E21: =E19*E20 -> 30000 | F21: =F19*F20 -> 30000 | G21: =G19*G20 -> 30000 | H21: =H19*H20 -> 30000 | I21: =I19*I20 -> 30000 | J21: =J19*J20 -> 30000 | ... N21: =N19*N20 -> 30000 | O21: =SUM(C21:N21) -> 360000
A22: Premium website design | B22: Qty | C22: 3 | D22: 3 | E22: 3 | F22: 3 | G22: 3 | H22: 3 | I22: 3 | J22: 3 | K22: 3 | L22: 3 | M22: 3 | N22: 3
B23: Price/ Unit | C23: ='PROPOSED PRICING'!E9 -> 16666.667 | D23: =C23 -> 16666.667 | E23: =D23 -> 16666.667 | F23: =E23 -> 16666.667 | G23: =F23 -> 16666.667 | H23: =G23 -> 16666.667 | I23: =H23 -> 16666.667 | J23: =I23 -> 16666.667 | K23: =J23 -> 16666.667 | ... N23: =M23 -> 16666.667
B24: Amt | C24: =C22*C23 -> 50000 | D24: =D22*D23 -> 50000 | E24: =E22*E23 -> 50000 | F24: =F22*F23 -> 50000 | G24: =G22*G23 -> 50000 | H24: =H22*H23 -> 50000 | I24: =I22*I23 -> 50000 | J24: =J22*J23 -> 50000 | ... N24: =N22*N23 -> 50000 | O24: =SUM(C24:N24) -> 600000
A25: Advanced website design | B25: Qty | C25: 1 | D25: 1 | E25: 1 | F25: 1 | G25: 1 | H25: 1 | I25: 1 | J25: 1 | K25: 1 | L25: 1 | M25: 1 | N25: 1
B26: Price/ Unit | C26: ='PROPOSED PRICING'!E10 -> 150000 | D26: =C26 -> 150000 | E26: =D26 -> 150000 | F26: =E26 -> 150000 | G26: =F26 -> 150000 | H26: =G26 -> 150000 | I26: =H26 -> 150000 | J26: =I26 -> 150000 | K26: =J26 -> 150000 | ... N26: =M26 -> 150000
B27: Amt | C27: =C25*C26 -> 150000 | D27: =D25*D26 -> 150000 | E27: =E25*E26 -> 150000 | F27: =F25*F26 -> 150000 | G27: =G25*G26 -> 150000 | H27: =H25*H26 -> 150000 | I27: =I25*I26 -> 150000 | J27: =J25*J26 -> 150000 | ... N27: =N25*N26 -> 150000 | O27: =SUM(C27:N27) -> 1800000
A28: Typesetting | B28: Qty | C28: 300 | D28: 100 | E28: 300 | F28: 300 | G28: 200 | H28: 300 | I28: 200 | J28: 200 | K28: 400 | L28: 200 | M28: 400 | N28: 300
B29: Price/ Unit | C29: ='PROPOSED PRICING'!E11 -> 5 | D29: =C29 -> 5 | E29: =D29 -> 5 | F29: =E29 -> 5 | G29: =F29 -> 5 | H29: =G29 -> 5 | I29: =H29 -> 5 | J29: =I29 -> 5 | K29: =J29 -> 5 | ... N29: =M29 -> 5
B30: Amt | C30: =C28*C29 -> 1500 | D30: =D28*D29 -> 500 | E30: =E28*E29 -> 1500 | F30: =F28*F29 -> 1500 | G30: =G28*G29 -> 1000 | H30: =H28*H29 -> 1500 | I30: =I28*I29 -> 1000 | J30: =J28*J29 -> 1000 | ... N30: =N28*N29 -> 1500 | O30: =SUM(C30:N30) -> 16000
A31: Online registrations | B31: Qty | C31: 30 | D31: 20 | E31: 30 | F31: 30 | G31: 20 | H31: 30 | I31: 20 | J31: 20 | K31: 40 | L31: 20 | M31: 40 | N31: 30
B32: Price/ Unit | C32: ='PROPOSED PRICING'!E12 -> 150 | D32: =C32 -> 150 | E32: =D32 -> 150 | F32: =E32 -> 150 | G32: =F32 -> 150 | H32: =G32 -> 150 | I32: =H32 -> 150 | J32: =I32 -> 150 | K32: =J32 -> 150 | ... N32: =M32 -> 150
B33: Amt | C33: =C31*C32 -> 4500 | D33: =D31*D32 -> 3000 | E33: =E31*E32 -> 4500 | F33: =F31*F32 -> 4500 | G33: =G31*G32 -> 3000 | H33: =H31*H32 -> 4500 | I33: =I31*I32 -> 3000 | J33: =J31*J32 -> 3000 | ... N33: =N31*N32 -> 4500 | O33: =SUM(C33:N33) -> 49500
A34: Spiral binding | B34: Qty | C34: 6 | D34: 2 | E34: 6 | F34: 6 | G34: 4 | H34: 6 | I34: 4 | J34: 4 | K34: 7 | L34: 4 | M34: 7 | N34: 6
B35: Price/ Unit | C35: ='PROPOSED PRICING'!E13 -> 3700 | D35: =C35 -> 3700 | E35: =D35 -> 3700 | F35: =E35 -> 3700 | G35: =F35 -> 3700 | H35: =G35 -> 3700 | I35: =H35 -> 3700 | J35: =I35 -> 3700 | K35: =J35 -> 3700 | ... N35: =M35 -> 3700
B36: Amt | C36: =C34*C35 -> 22200 | D36: =D34*D35 -> 7400 | E36: =E34*E35 -> 22200 | F36: =F34*F35 -> 22200 | G36: =G34*G35 -> 14800 | H36: =H34*H35 -> 22200 | I36: =I34*I35 -> 14800 | J36: =J34*J35 -> 14800 | ... N36: =N34*N35 -> 22200 | O36: =SUM(C36:N36) -> 229400
A37: Data analysis | B37: Qty | C37: 6 | D37: 2 | E37: 6 | F37: 6 | G37: 4 | H37: 6 | I37: 4 | J37: 4 | K37: 7 | L37: 4 | M37: 7 | N37: 6
B38: Price/ Unit | C38: ='PROPOSED PRICING'!E14 -> 5000 | D38: =C38 -> 5000 | E38: =D38 -> 5000 | F38: =E38 -> 5000 | G38: =F38 -> 5000 | H38: =G38 -> 5000 | I38: =H38 -> 5000 | J38: =I38 -> 5000 | K38: =J38 -> 5000 | ... N38: =M38 -> 5000
B39: Amt | C39: =C37*C38 -> 30000 | D39: =D37*D38 -> 10000 | E39: =E37*E38 -> 30000 | F39: =F37*F38 -> 30000 | G39: =G37*G38 -> 20000 | H39: =H37*H38 -> 30000 | I39: =I37*I38 -> 20000 | J39: =J37*J38 -> 20000 | ... N39: =N37*N38 -> 30000 | O39: =SUM(C39:N39) -> 310000
A40: Data recovery | B40: Qty | C40: 15 | D40: 15 | E40: 15 | F40: 15 | G40: 15 | H40: 15 | I40: 15 | J40: 15 | K40: 15 | L40: 15 | M40: 15 | N40: 15
...

Sheet Sales Forecast
A1: QUARTERLY SALES FORECAST
C2: P1 | D2: P2 | E2: P3 | F2: P4 | G2: P5 | H2: P6 | I2: P7 | J2: P8 | K2: P9 | L2: P10 | M2: P11 | N2: P12 | O2: TOTAL
C3: Jan- Mar | D3: Apr-June | E3: July-Sept | F3: Oct-Dec | G3: Jan- Mar | H3: Apr-June | I3: July-Sept | J3: Oct-Dec | K3: Jan- Mar | L3: Apr-June | M3: July-Sept | N3: Oct-Dec | O3: Total
A4: Black and White Printing | B4: Qty | C4: ='Cost Forecast'!C4 -> 30 | D4: ='Cost Forecast'!D4 -> 10 | E4: ='Cost Forecast'!E4 -> 30 | F4: ='Cost Forecast'!F4 -> 30 | G4: ='Cost Forecast'!G4 -> 20 | H4: ='Cost Forecast'!H4 -> 30 | I4: ='Cost Forecast'!I4 -> 20 | J4: ='Cost Forecast'!J4 -> 20 | ... N4: ='Cost Forecast'!N4 -> 30
B5: Price/ Unit | C5: ='PROPOSED PRICING'!G3 -> 25000 | D5: =C5 -> 25000 | E5: =D5 -> 25000 | F5: =E5 -> 25000 | G5: =F5 -> 25000 | H5: =G5 -> 25000 | I5: =H5 -> 25000 | J5: =I5 -> 25000 | K5: =J5 -> 25000 | ... N5: =M5 -> 25000
B6: Amt | C6: =C4*C5 -> 750000 | D6: =D4*D5 -> 250000 | E6: =E4*E5 -> 750000 | F6: =F4*F5 -> 750000 | G6: =G4*G5 -> 500000 | H6: =H4*H5 -> 750000 | I6: =I4*I5 -> 500000 | J6: =J4*J5 -> 500000 | ... N6: =N4*N5 -> 750000 | O6: =SUM(C6:N6) -> 8000000
A7: Photocopy | B7: Qty | C7: ='Cost Forecast'!C7 -> 30 | D7: ='Cost Forecast'!D7 -> 10 | E7: ='Cost Forecast'!E7 -> 30 | F7: ='Cost Forecast'!F7 -> 30 | G7: ='Cost Forecast'!G7 -> 20 | H7: ='Cost Forecast'!H7 -> 30 | I7: ='Cost Forecast'!I7 -> 20 | J7: ='Cost Forecast'!J7 -> 20 | ... N7: ='Cost Forecast'!N7 -> 20
B8: Price/ Unit | C8: ='PROPOSED PRICING'!G4 -> 50000 | D8: =C8 -> 50000 | E8: =D8 -> 50000 | F8: =E8 -> 50000 | G8: =F8 -> 50000 | H8: =G8 -> 50000 | I8: =H8 -> 50000 | J8: =I8 -> 50000 | K8: =J8 -> 50000 | ... N8: =M8 -> 50000
B9: Amt | C9: =C7*C8 -> 1500000 | D9: =D7*D8 -> 500000 | E9: =E7*E8 -> 1500000 | F9: =F7*F8 -> 1500000 | G9: =G7*G8 -> 1000000 | H9: =H7*H8 -> 1500000 | I9: =I7*I8 -> 1000000 | J9: =J7*J8 -> 1000000 | ... N9: =N7*N8 -> 1000000 | O9: =SUM(C9:N9) -> 14500000
A10: Coloured printing | B10: Qty | C10: ='Cost Forecast'!C10 -> 1 | D10: ='Cost Forecast'!D10 -> 1 | E10: ='Cost Forecast'!E10 -> 1 | F10: ='Cost Forecast'!F10 -> 1 | G10: ='Cost Forecast'!G10 -> 1 | H10: ='Cost Forecast'!H10 -> 1 | I10: ='Cost Forecast'!I10 -> 1 | J10: ='Cost Forecast'!J10 -> 1 | ... N10: ='Cost Forecast'!N10 -> 1
B11: Price/ Unit | C11: ='PROPOSED PRICING'!G5 -> 75000 | D11: =C11 -> 75000 | E11: =D11 -> 75000 | F11: =E11 -> 75000 | G11: =F11 -> 75000 | H11: =G11 -> 75000 | I11: =H11 -> 75000 | J11: =I11 -> 75000 | K11: =J11 -> 75000 | ... N11: =M11 -> 75000
B12: Amt | C12: =C10*C11 -> 75000 | D12: =D10*D11 -> 75000 | E12: =E10*E11 -> 75000 | F12: =F10*F11 -> 75000 | G12: =G10*G11 -> 75000 | H12: =H10*H11 -> 75000 | I12: =I10*I11 -> 75000 | J12: =J10*J11 -> 75000 | ... N12: =N10*N11 -> 75000 | O12: =SUM(C12:N12) -> 900000
A13: Scanning | B13: Qty | C13: ='Cost Forecast'!C13 -> 90 | D13: ='Cost Forecast'!D13 -> 30 | E13: ='Cost Forecast'!E13 -> 90 | F13: ='Cost Forecast'!F13 -> 90 | G13: ='Cost Forecast'!G13 -> 60 | H13: ='Cost Forecast'!H13 -> 90 | I13: ='Cost Forecast'!I13 -> 60 | J13: ='Cost Forecast'!J13 -> 60 | ... N13: ='Cost Forecast'!N13 -> 90
B14: Price/ Unit | C14: ='PROPOSED PRICING'!G6 -> 50 | D14: =C14 -> 50 | E14: =D14 -> 50 | F14: =E14 -> 50 | G14: =F14 -> 50 | H14: =G14 -> 50 | I14: =H14 -> 50 | J14: =I14 -> 50 | K14: =J14 -> 50 | ... N14: =M14 -> 50
B15: Amt | C15: =C13*C14 -> 4500 | D15: =D13*D14 -> 1500 | E15: =E13*E14 -> 4500 | F15: =F13*F14 -> 4500 | G15: =G13*G14 -> 3000 | H15: =H13*H14 -> 4500 | I15: =I13*I14 -> 3000 | J15: =J13*J14 -> 3000 | ... N15: =N13*N14 -> 4500 | O15: =SUM(C15:N15) -> 46000
A16: DVD + burning | B16: Qty | C16: ='Cost Forecast'!C16 -> 3 | D16: ='Cost Forecast'!D16 -> 1 | E16: ='Cost Forecast'!E16 -> 3 | F16: ='Cost Forecast'!F16 -> 3 | G16: ='Cost Forecast'!G16 -> 2 | H16: ='Cost Forecast'!H16 -> 3 | I16: ='Cost Forecast'!I16 -> 2 | J16: ='Cost Forecast'!J16 -> 2 | ... N16: ='Cost Forecast'!N16 -> 3
B17: Price/ Unit | C17: ='PROPOSED PRICING'!G7 -> 5000 | D17: =C17 -> 5000 | E17: =D17 -> 5000 | F17: =E17 -> 5000 | G17: =F17 -> 5000 | H17: =G17 -> 5000 | I17: =H17 -> 5000 | J17: =I17 -> 5000 | K17: =J17 -> 5000 | ... N17: =M17 -> 5000
B18: Amt | C18: =C16*C17 -> 15000 | D18: =D16*D17 -> 5000 | E18: =E16*E17 -> 15000 | F18: =F16*F17 -> 15000 | G18: =G16*G17 -> 10000 | H18: =H16*H17 -> 15000 | I18: =I16*I17 -> 10000 | J18: =J16*J17 -> 10000 | ... N18: =N16*N17 -> 15000 | O18: =SUM(C18:N18) -> 160000
A19: Basic website design | B19: Qty | C19: ='Cost Forecast'!C19 -> 9 | D19: ='Cost Forecast'!D19 -> 9 | E19: ='Cost Forecast'!E19 -> 9 | F19: ='Cost Forecast'!F19 -> 9 | G19: ='Cost Forecast'!G19 -> 9 | H19: ='Cost Forecast'!H19 -> 9 | I19: ='Cost Forecast'!I19 -> 9 | J19: ='Cost Forecast'!J19 -> 9 | ... N19: ='Cost Forecast'!N19 -> 9
B20: Price/ Unit | C20: ='PROPOSED PRICING'!G8 -> 30000 | D20: =C20 -> 30000 | E20: =D20 -> 30000 | F20: =E20 -> 30000 | G20: =F20 -> 30000 | H20: =G20 -> 30000 | I20: =H20 -> 30000 | J20: =I20 -> 30000 | K20: =J20 -> 30000 | ... N20: =M20 -> 30000
B21: Amt | C21: =C19*C20 -> 270000 | D21: =D19*D20 -> 270000 | E21: =E19*E20 -> 270000 | F21: =F19*F20 -> 270000 | G21: =G19*G20 -> 270000 | H21: =H19*H20 -> 270000 | I21: =I19*I20 -> 270000 | J21: =J19*J20 -> 270000 | ... N21: =N19*N20 -> 270000 | O21: =SUM(C21:N21) -> 3240000
A22: Premium website design | B22: Qty | C22: ='Cost Forecast'!C22 -> 3 | D22: ='Cost Forecast'!D22 -> 3 | E22: ='Cost Forecast'!E22 -> 3 | F22: ='Cost Forecast'!F22 -> 3 | G22: ='Cost Forecast'!G22 -> 3 | H22: ='Cost Forecast'!H22 -> 3 | I22: ='Cost Forecast'!I22 -> 3 | J22: ='Cost Forecast'!J22 -> 3 | ... N22: ='Cost Forecast'!N22 -> 3
B23: Price/ Unit | C23: ='PROPOSED PRICING'!G9 -> 150000 | D23: =C23 -> 150000 | E23: =D23 -> 150000 | F23: =E23 -> 150000 | G23: =F23 -> 150000 | H23: =G23 -> 150000 | I23: =H23 -> 150000 | J23: =I23 -> 150000 | K23: =J23 -> 150000 | ... N23: =M23 -> 150000
B24: Amt | C24: =C22*C23 -> 450000 | D24: =D22*D23 -> 450000 | E24: =E22*E23 -> 450000 | F24: =F22*F23 -> 450000 | G24: =G22*G23 -> 450000 | H24: =H22*H23 -> 450000 | I24: =I22*I23 -> 450000 | J24: =J22*J23 -> 450000 | ... N24: =N22*N23 -> 450000 | O24: =SUM(C24:N24) -> 5400000
A25: Advanced website design | B25: Qty | C25: ='Cost Forecast'!C25 -> 1 | D25: ='Cost Forecast'!D25 -> 1 | E25: ='Cost Forecast'!E25 -> 1 | F25: ='Cost Forecast'!F25 -> 1 | G25: ='Cost Forecast'!G25 -> 1 | H25: ='Cost Forecast'!H25 -> 1 | I25: ='Cost Forecast'!I25 -> 1 | J25: ='Cost Forecast'!J25 -> 1 | ... N25: ='Cost Forecast'!N25 -> 1
B26: Price/ Unit | C26: ='PROPOSED PRICING'!G10 -> 450000 | D26: =C26 -> 450000 | E26: =D26 -> 450000 | F26: =E26 -> 450000 | G26: =F26 -> 450000 | H26: =G26 -> 450000 | I26: =H26 -> 450000 | J26: =I26 -> 450000 | K26: =J26 -> 450000 | ... N26: =M26 -> 450000
B27: Amt | C27: =C25*C26 -> 450000 | D27: =D25*D26 -> 450000 | E27: =E25*E26 -> 450000 | F27: =F25*F26 -> 450000 | G27: =G25*G26 -> 450000 | H27: =H25*H26 -> 450000 | I27: =I25*I26 -> 450000 | J27: =J25*J26 -> 450000 | ... N27: =N25*N26 -> 450000 | O27: =SUM(C27:N27) -> 5400000
A28: Typesetting | B28: Qty | C28: ='Cost Forecast'!C28 -> 300 | D28: ='Cost Forecast'!D28 -> 100 | E28: ='Cost Forecast'!E28 -> 300 | F28: ='Cost Forecast'!F28 -> 300 | G28: ='Cost Forecast'!G28 -> 200 | H28: ='Cost Forecast'!H28 -> 300 | I28: ='Cost Forecast'!I28 -> 200 | J28: ='Cost Forecast'!J28 -> 200 | ... N28: ='Cost Forecast'!N28 -> 300
B29: Price/ Unit | C29: ='PROPOSED PRICING'!G11 -> 100 | D29: =C29 -> 100 | E29: =D29 -> 100 | F29: =E29 -> 100 | G29: =F29 -> 100 | H29: =G29 -> 100 | I29: =H29 -> 100 | J29: =I29 -> 100 | K29: =J29 -> 100 | ... N29: =M29 -> 100
B30: Amt | C30: =C28*C29 -> 30000 | D30: =D28*D29 -> 10000 | E30: =E28*E29 -> 30000 | F30: =F28*F29 -> 30000 | G30: =G28*G29 -> 20000 | H30: =H28*H29 -> 30000 | I30: =I28*I29 -> 20000 | J30: =J28*J29 -> 20000 | ... N30: =N28*N29 -> 30000 | O30: =SUM(C30:N30) -> 320000
A31: Online registrations | B31: Qty | C31: ='Cost Forecast'!C31 -> 30 | D31: ='Cost Forecast'!D31 -> 20 | E31: ='Cost Forecast'!E31 -> 30 | F31: ='Cost Forecast'!F31 -> 30 | G31: ='Cost Forecast'!G31 -> 20 | H31: ='Cost Forecast'!H31 -> 30 | I31: ='Cost Forecast'!I31 -> 20 | J31: ='Cost Forecast'!J31 -> 20 | ... N31: ='Cost Forecast'!N31 -> 30
B32: Price/ Unit | C32: ='PROPOSED PRICING'!G12 -> 500 | D32: =C32 -> 500 | E32: =D32 -> 500 | F32: =E32 -> 500 | G32: =F32 -> 500 | H32: =G32 -> 500 | I32: =H32 -> 500 | J32: =I32 -> 500 | K32: =J32 -> 500 | ... N32: =M32 -> 500
B33: Amt | C33: =C31*C32 -> 15000 | D33: =D31*D32 -> 10000 | E33: =E31*E32 -> 15000 | F33: =F31*F32 -> 15000 | G33: =G31*G32 -> 10000 | H33: =H31*H32 -> 15000 | I33: =I31*I32 -> 10000 | J33: =J31*J32 -> 10000 | ... N33: =N31*N32 -> 15000 | O33: =SUM(C33:N33) -> 165000
A34: Spiral binding | B34: Qty | C34: ='Cost Forecast'!C34 -> 6 | D34: ='Cost Forecast'!D34 -> 2 | E34: ='Cost Forecast'!E34 -> 6 | F34: ='Cost Forecast'!F34 -> 6 | G34: ='Cost Forecast'!G34 -> 4 | H34: ='Cost Forecast'!H34 -> 6 | I34: ='Cost Forecast'!I34 -> 4 | J34: ='Cost Forecast'!J34 -> 4 | ... N34: ='Cost Forecast'!N34 -> 6
B35: Price/ Unit | C35: ='PROPOSED PRICING'!G13 -> 8000 | D35: =C35 -> 8000 | E35: =D35 -> 8000 | F35: =E35 -> 8000 | G35: =F35 -> 8000 | H35: =G35 -> 8000 | I35: =H35 -> 8000 | J35: =I35 -> 8000 | K35: =J35 -> 8000 | ... N35: =M35 -> 8000
B36: Amt | C36: =C34*C35 -> 48000 | D36: =D34*D35 -> 16000 | E36: =E34*E35 -> 48000 | F36: =F34*F35 -> 48000 | G36: =G34*G35 -> 32000 | H36: =H34*H35 -> 48000 | I36: =I34*I35 -> 32000 | J36: =J34*J35 -> 32000 | ... N36: =N34*N35 -> 48000 | O36: =SUM(C36:N36) -> 496000
A37: Data analysis | B37: Qty | C37: ='Cost Forecast'!C37 -> 6 | D37: ='Cost Forecast'!D37 -> 2 | E37: ='Cost Forecast'!E37 -> 6 | F37: ='Cost Forecast'!F37 -> 6 | G37: ='Cost Forecast'!G37 -> 4 | H37: ='Cost Forecast'!H37 -> 6 | I37: ='Cost Forecast'!I37 -> 4 | J37: ='Cost Forecast'!J37 -> 4 | ... N37: ='Cost Forecast'!N37 -> 6
B38: Price/ Unit | C38: ='PROPOSED PRICING'!G14 -> 15000 | D38: =C38 -> 15000 | E38: =D38 -> 15000 | F38: =E38 -> 15000 | G38: =F38 -> 15000 | H38: =G38 -> 15000 | I38: =H38 -> 15000 | J38: =I38 -> 15000 | K38: =J38 -> 15000 | ... N38: =M38 -> 15000
B39: Amt | C39: =C37*C38 -> 90000 | D39: =D37*D38 -> 30000 | E39: =E37*E38 -> 90000 | F39: =F37*F38 -> 90000 | G39: =G37*G38 -> 60000 | H39: =H37*H38 -> 90000 | I39: =I37*I38 -> 60000 | J39: =J37*J38 -> 60000 | ... N39: =N37*N38 -> 90000 | O39: =SUM(C39:N39) -> 930000
A40: Data recovery | B40: Qty | C40: ='Cost Forecast'!C40 -> 15 | D40: ='Cost Forecast'!D40 -> 15 | E40: ='Cost Forecast'!E40 -> 15 | F40: ='Cost Forecast'!F40 -> 15 | G40: ='Cost Forecast'!G40 -> 15 | H40: ='Cost Forecast'!H40 -> 15 | I40: ='Cost Forecast'!I40 -> 15 | J40: ='Cost Forecast'!J40 -> 15 | ... N40: ='Cost Forecast'!N40 -> 15
...

Sheet Profit and Loss Statement
A1: QUARTERLY PROFIT AND LOSS PROJECTION
A2: Components | B2: 1 (Jan-Mar) | C2: 2(Apr-Jun) | D2: 3(Jul-Sep) | E2: 4(Oct-Dec) | F2: 5(Jan-Mar) | G2: 6(Apr-Jun) | H2: 7(Jul-Sep) | I2: 8(Oct-Dec) | J2: 9(Jan-Mar) | K2: 10(Apr-Jun) | L2: 11(Jul-Sep) | M2: 12(Oct-Dec) | N2: TOTAL
A3: TOTAL SALES | B3: ='Sales Forecast'!C95 -> 5606500 | C3: ='Sales Forecast'!D95 -> 3422500 | D3: ='Sales Forecast'!E95 -> 5606500 | E3: ='Sales Forecast'!F95 -> 5606500 | F3: ='Sales Forecast'!G95 -> 5376000 | G3: ='Sales Forecast'!H95 -> 6351500 | H3: ='Sales Forecast'!I95 -> 5406000 | I3: ='Sales Forecast'!J95 -> 5376000 | ... M3: ='Sales Forecast'!N95 -> 5956500 | N3: =SUM(B3:M3) -> 67937000
A4: OTHER INCOME | N4: =SUM(B4:M4) -> 0
A5: TOTAL INCOME | B5: =B3+B4 -> 5606500 | C5: =C3+C4 -> 3422500 | D5: =D3+D4 -> 5606500 | E5: =E3+E4 -> 5606500 | F5: =F3+F4 -> 5376000 | G5: =G3+G4 -> 6351500 | H5: =H3+H4 -> 5406000 | I5: =I3+I4 -> 5376000 | ... M5: =M3+M4 -> 5956500 | N5: =SUM(B5:M5) -> 67937000
A6: TOTAL COST OF SALES | B6: ='Cost Forecast'!C94 -> 1269550 | C6: ='Cost Forecast'!D94 -> 804950 | D6: ='Cost Forecast'!E94 -> 1269550 | E6: ='Cost Forecast'!F94 -> 1269550 | F6: ='Cost Forecast'!G94 -> 1212900 | G6: ='Cost Forecast'!H94 -> 1428550 | H6: ='Cost Forecast'!I94 -> 1221900 | I6: ='Cost Forecast'!J94 -> 1212900 | ... M6: ='Cost Forecast'!N94 -> 1389850 | N6: =SUM(B6:M6) -> 15497500
A7: GROSS PROFIT | B7: =B5-B6 -> 4336950 | C7: =C5-C6 -> 2617550 | D7: =D5-D6 -> 4336950 | E7: =E5-E6 -> 4336950 | F7: =F5-F6 -> 4163100 | G7: =G5-G6 -> 4922950 | H7: =H5-H6 -> 4184100 | I7: =I5-I6 -> 4163100 | ... M7: =M5-M6 -> 4566650 | N7: =SUM(B7:M7) -> 52439500
A8: EXPENSES | N8: =SUM(B8:M8) -> 0
A9: Operating Expenses | B9: ='OPERATING EXPENSE'!B16 -> 316045 | C9: ='OPERATING EXPENSE'!C16 -> 276045 | D9: ='OPERATING EXPENSE'!D16 -> 276045 | E9: ='OPERATING EXPENSE'!E16 -> 276045 | F9: ='OPERATING EXPENSE'!F16 -> 288045 | G9: ='OPERATING EXPENSE'!G16 -> 288045 | H9: ='OPERATING EXPENSE'!H16 -> 288045 | I9: ='OPERATING EXPENSE'!I16 -> 288045 | ... M9: ='OPERATING EXPENSE'!M16 -> 300645 | N9: =SUM(B9:M9) -> 3498940
A10: Interest | B10: ='LOAN REPAYMENT'!H5*3 -> 56827.069 | C10: =B10 -> 56827.069 | D10: =C10 -> 56827.069 | E10: =D10 -> 56827.069 | F10: ='LOAN REPAYMENT'!H17*3 -> 41328.777 | G10: =F10 -> 41328.777 | H10: =G10 -> 41328.777 | I10: =H10 -> 41328.777 | J10: =+'LOAN REPAYMENT'!H29*3 -> 20664.389 | K10: =J10 -> 20664.389 | L10: =K10 -> 20664.389 | M10: =L10 -> 20664.389 | N10: =SUM(B10:M10) -> 475280.94
A11: Depreciation | B11: ='PRE-OPERATING, EQUIPMENT'!O23*3 -> 89833.333 | C11: =B11 -> 89833.333 | D11: =C11 -> 89833.333 | E11: =D11 -> 89833.333 | F11: =E11 -> 89833.333 | G11: =F11 -> 89833.333 | H11: =G11 -> 89833.333 | I11: =H11 -> 89833.333 | J11: =I11 -> 89833.333 | ... M11: =L11 -> 89833.333 | N11: =SUM(B11:M11) -> 1078000
A12: Rent | B12: ='PRE-OPERATING, EQUIPMENT'!K29/12 -> 33333.333 | C12: =B12 -> 33333.333 | D12: =C12 -> 33333.333 | E12: =D12 -> 33333.333 | F12: =E12 -> 33333.333 | G12: =F12 -> 33333.333 | H12: =G12 -> 33333.333 | I12: =H12 -> 33333.333 | J12: =I12 -> 33333.333 | ... M12: =L12 -> 33333.333 | N12: =SUM(B12:M12) -> 400000
A13: Bad Debt | B13: =2%*B3 -> 112130 | C13: =2%*C3 -> 68450 | D13: =2%*D3 -> 112130 | E13: =2%*E3 -> 112130 | F13: =2%*F3 -> 107520 | G13: =2%*G3 -> 127030 | H13: =2%*H3 -> 108120 | I13: =2%*I3 -> 107520 | ... M13: =2%*M3 -> 119130 | N13: =SUM(B13:M13) -> 1358740
A14: Provision for discount allowed | B14: 0 | C14: 0 | D14: 0 | E14: =1%*E3 -> 56065 | F14: =1%*F3 -> 53760 | G14: =1%*G3 -> 63515 | H14: =1%*H3 -> 54060 | I14: =1%*I3 -> 53760 | J14: =1%*J3 -> 68890 | K14: =1%*K3 -> 54510 | L14: =1%*L3 -> 68890 | M14: =1%*M3 -> 59565 | N14: =SUM(B14:M14) -> 533015
A15: Insurance | B15: ='PRE-OPERATING, EQUIPMENT'!K33/4 -> 11787.5 | C15: =B15 -> 11787.5 | D15: =C15 -> 11787.5 | E15: =D15 -> 11787.5 | F15: =E15 -> 11787.5 | G15: =F15 -> 11787.5 | H15: =G15 -> 11787.5 | I15: =H15 -> 11787.5 | J15: =I15 -> 11787.5 | ... M15: =L15 -> 11787.5 | N15: =SUM(B15:M15) -> 141450
A16: Other Expenses | N16: =SUM(B16:M16) -> 0
A17: TOTAL EXPENSES | B17: =SUM(B9:B16) -> 619956.24 | C17: =SUM(C9:C16) -> 536276.24 | D17: =SUM(D9:D16) -> 579956.24 | E17: =SUM(E9:E16) -> 636021.24 | F17: =SUM(F9:F16) -> 625607.94 | G17: =SUM(G9:G16) -> 654872.94 | H17: =SUM(H9:H16) -> 626507.94 | I17: =SUM(I9:I16) -> 625607.94 | ... M17: =SUM(M9:M16) -> 634958.56 | N17: =SUM(B17:M17) -> 7485425.9
A18: NET PROFIT BEFORE TAX | B18: =B7-B17 -> 3716993.8 | C18: =C7-C17 -> 2081273.8 | D18: =D7-D17 -> 3756993.8 | E18: =E7-E17 -> 3700928.8 | F18: =F7-F17 -> 3537492.1 | G18: =G7-G17 -> 4268077.1 | H18: =H7-H17 -> 3557592.1 | I18: =I7-I17 -> 3537492.1 | ... M18: =M7-M17 -> 3931691.4 | N18: =SUM(B18:M18) -> 44954074
A19: Income Tax | B19: =B18*20% -> 743398.75 | C19: =C18*20% -> 416254.75 | D19: =D18*20% -> 751398.75 | E19: =E18*20% -> 740185.75 | F19: =F18*20% -> 707498.41 | G19: =G18*20% -> 853615.41 | H19: =H18*20% -> 711518.41 | I19: =I18*20% -> 707498.41 | ... M19: =M18*20% -> 786338.29 | N19: =SUM(B19:M19) -> 8990814.8
A20: NET PROFIT AFTER TAX | B20: =B18-B19 -> 2973595 | C20: =C18-C19 -> 1665019 | D20: =D18-D19 -> 3005595 | E20: =E18-E19 -> 2960743 | F20: =F18-F19 -> 2829993.6 | G20: =G18-G19 -> 3414461.6 | H20: =H18-H19 -> 2846073.6 | I20: =I18-I19 -> 2829993.6 | ... M20: =M18-M19 -> 3145353.2 | N20: =SUM(B20:M20) -> 35963259

Sheet Cash Flow
A1: TRI-Monthly Cash flow Plan (36 Months)
A2: Components | B2: Pre Startup | C2: 1 | D2: 2 | E2: 3 | F2: 4 | G2: 5 | H2: 6 | I2: 7 | J2: 8 | K2: 9 | L2: 10 | M2: 11 | N2: 12
A3: CASH INFLOW
A4: Cash at Hand (beginning of month) | C4: =B20 -> -245210 | D4: =C20 -> 2930348.3 | E4: =D20 -> 4524046.4 | F4: =E20 -> 7502000.4 | G4: =F20 -> 10491167 | H4: =G20 -> 13342670 | I4: =H20 -> 16807906 | J4: =I20 -> 19676388 | ... N4: =M20 -> 32977880
A5: Cash Sales | C5: ='Profit and Loss Statement'!B3 -> 5606500 | D5: ='Profit and Loss Statement'!C3 -> 3422500 | E5: ='Profit and Loss Statement'!D3 -> 5606500 | F5: ='Profit and Loss Statement'!E3 -> 5606500 | G5: ='Profit and Loss Statement'!F3 -> 5376000 | H5: ='Profit and Loss Statement'!G3 -> 6351500 | I5: ='Profit and Loss Statement'!H3 -> 5406000 | J5: ='Profit and Loss Statement'!I3 -> 5376000 | ... N5: ='Profit and Loss Statement'!M3 -> 5956500
A6: Equity | B6: =-'LOAN REPAYMENT'!B8 -> -280627.5
A7: Loan Proceed | B7: ='LOAN REPAYMENT'!B9 -> 2525647.5
A8: Total Cash Inflow | B8: =SUM(B4:B7) -> 2245020 | C8: =SUM(C4:C7) -> 5361290 | D8: =SUM(D4:D7) -> 6352848.3 | E8: =SUM(E4:E7) -> 10130546 | F8: =SUM(F4:F7) -> 13108500 | G8: =SUM(G4:G7) -> 15867167 | H8: =SUM(H4:H7) -> 19694170 | I8: =SUM(I4:I7) -> 22213906 | ... N8: =SUM(N4:N7) -> 38934380
A9: CASH OUTFLOW
A10: Pre-operating Expenses | B10: ='LOAN REPAYMENT'!B3 -> 1862740
A11: Opening inventory Total Cost | B11: ='LOAN REPAYMENT'!B4 -> 627490 | C11: ='Profit and Loss Statement'!B6 -> 1269550 | D11: ='Profit and Loss Statement'!C6 -> 804950 | E11: ='Profit and Loss Statement'!D6 -> 1269550 | F11: ='Profit and Loss Statement'!E6 -> 1269550 | G11: ='Profit and Loss Statement'!F6 -> 1212900 | H11: ='Profit and Loss Statement'!G6 -> 1428550 | I11: ='Profit and Loss Statement'!H6 -> 1221900 | J11: ='Profit and Loss Statement'!I6 -> 1212900 | ... N11: ='Profit and Loss Statement'!M6 -> 1389850
A12: Operating Expenses | C12: ='Profit and Loss Statement'!B9 -> 316045 | D12: ='Profit and Loss Statement'!C9 -> 276045 | E12: ='Profit and Loss Statement'!D9 -> 276045 | F12: ='Profit and Loss Statement'!E9 -> 276045 | G12: ='Profit and Loss Statement'!F9 -> 288045 | H12: ='Profit and Loss Statement'!G9 -> 288045 | I12: ='Profit and Loss Statement'!H9 -> 288045 | J12: ='Profit and Loss Statement'!I9 -> 288045 | ... N12: ='Profit and Loss Statement'!M9 -> 300645
A13: Interest | C13: ='Profit and Loss Statement'!B10 -> 56827.069 | D13: ='Profit and Loss Statement'!C10 -> 56827.069 | E13: ='Profit and Loss Statement'!D10 -> 56827.069 | F13: ='Profit and Loss Statement'!E10 -> 56827.069 | G13: ='Profit and Loss Statement'!F10 -> 41328.777 | H13: ='Profit and Loss Statement'!G10 -> 41328.777 | I13: ='Profit and Loss Statement'!H10 -> 41328.777 | J13: ='Profit and Loss Statement'!I10 -> 41328.777 | ... N13: ='Profit and Loss Statement'!M10 -> 20664.389
A14: Loan Repayment | C14: ='LOAN REPAYMENT'!G5+'LOAN REPAYMENT'!G6+'LOAN REPAYMENT'!G7 -> 0 | D14: ='LOAN REPAYMENT'!G8*3 -> 229604.32 | E14: =D14 -> 229604.32 | F14: =E14 -> 229604.32 | G14: =F14 -> 229604.32 | H14: =G14 -> 229604.32 | I14: =H14 -> 229604.32 | J14: =I14 -> 229604.32 | K14: =J14 -> 229604.32 | L14: =K14 -> 229604.32 | ... N14: =M14 -> 229604.32
A15: Rent | C15: ='Profit and Loss Statement'!B12 -> 33333.333 | D15: ='Profit and Loss Statement'!C12 -> 33333.333 | E15: ='Profit and Loss Statement'!D12 -> 33333.333 | F15: ='Profit and Loss Statement'!E12 -> 33333.333 | G15: ='Profit and Loss Statement'!F12 -> 33333.333 | H15: ='Profit and Loss Statement'!G12 -> 33333.333 | I15: ='Profit and Loss Statement'!H12 -> 33333.333 | J15: ='Profit and Loss Statement'!I12 -> 33333.333 | ... N15: ='Profit and Loss Statement'!M12 -> 33333.333
A16: Insurance | C16: ='Profit and Loss Statement'!B15 -> 11787.5 | D16: ='Profit and Loss Statement'!C15 -> 11787.5 | E16: ='Profit and Loss Statement'!D15 -> 11787.5 | F16: ='Profit and Loss Statement'!E15 -> 11787.5 | G16: ='Profit and Loss Statement'!F15 -> 11787.5 | H16: ='Profit and Loss Statement'!G15 -> 11787.5 | I16: ='Profit and Loss Statement'!H15 -> 11787.5 | J16: ='Profit and Loss Statement'!I15 -> 11787.5 | ... N16: ='Profit and Loss Statement'!M15 -> 11787.5
A17: Other expenses | C17: ='Profit and Loss Statement'!B16 -> 0 | D17: ='Profit and Loss Statement'!C16 -> 0 | E17: ='Profit and Loss Statement'!D16 -> 0 | F17: ='Profit and Loss Statement'!E16 -> 0 | G17: ='Profit and Loss Statement'!F16 -> 0 | H17: ='Profit and Loss Statement'!G16 -> 0 | I17: ='Profit and Loss Statement'!H16 -> 0 | J17: ='Profit and Loss Statement'!I16 -> 0 | ... N17: ='Profit and Loss Statement'!M16 -> 0
A18: Income Tax | C18: ='Profit and Loss Statement'!B19 -> 743398.75 | D18: ='Profit and Loss Statement'!C19 -> 416254.75 | E18: ='Profit and Loss Statement'!D19 -> 751398.75 | F18: ='Profit and Loss Statement'!E19 -> 740185.75 | G18: ='Profit and Loss Statement'!F19 -> 707498.41 | H18: ='Profit and Loss Statement'!G19 -> 853615.41 | I18: ='Profit and Loss Statement'!H19 -> 711518.41 | J18: ='Profit and Loss Statement'!I19 -> 707498.41 | ... N18: ='Profit and Loss Statement'!M19 -> 786338.29
A19: Total Cash Outflow | B19: =SUM(B10:B18) -> 2490230 | C19: =SUM(C10:C18) -> 2430941.7 | D19: =SUM(D10:D18) -> 1828802 | E19: =SUM(E10:E18) -> 2628546 | F19: =SUM(F10:F18) -> 2617333 | G19: =SUM(G10:G18) -> 2524497.3 | H19: =SUM(H10:H18) -> 2886264.3 | I19: =SUM(I10:I18) -> 2537517.3 | ... N19: =SUM(N10:N18) -> 2772222.8
A20: Cash Balance (end of the month) | B20: =B8-B19 -> -245210 | C20: =C8-C19 -> 2930348.3 | D20: =D8-D19 -> 4524046.4 | E20: =E8-E19 -> 7502000.4 | F20: =F8-F19 -> 10491167 | G20: =G8-G19 -> 13342670 | H20: =H8-H19 -> 16807906 | I20: =I8-I19 -> 19676388 | ... N20: =N8-N19 -> 36162157

Sheet Viability Analysis
C1: SENSITIVITY ANALYSIS FOR
B2: 0 | C2: 1 | D2: 2 | E2: 3 | F2: 4 | G2: 5 | H2: 6 | I2: 7 | J2: 8 | K2: 9 | L2: 10 | M2: 11 | N2: 12 | O2: Total
A3: Cash Inflow | B3: ='Cash Flow'!B8 -> 2245020 | C3: ='Cash Flow'!C8 -> 5361290 | D3: ='Cash Flow'!D8 -> 6352848.3 | E3: ='Cash Flow'!E8 -> 10130546 | F3: ='Cash Flow'!F8 -> 13108500 | G3: ='Cash Flow'!G8 -> 15867167 | H3: ='Cash Flow'!H8 -> 19694170 | I3: ='Cash Flow'!I8 -> 22213906 | ... N3: ='Cash Flow'!N8 -> 38934380 | O3: =SUM(B3:N3) -> 2.5622288e+08
A4: Red Rev 20% | C4: =C3*0.8 -> 4289032 | D4: =D3*0.8 -> 5082278.7 | E4: =E3*0.8 -> 8104437.1 | F4: =F3*0.8 -> 10486800 | G4: =G3*0.8 -> 12693734 | H4: =H3*0.8 -> 15755336 | I4: =I3*0.8 -> 17771125 | J4: =J3*0.8 -> 20041911 | ... N4: =N3*0.8 -> 31147504
A6: Cash Outflow | B6: ='Cash Flow'!B19 -> 2490230 | C6: ='Cash Flow'!C19 -> 2430941.7 | D6: ='Cash Flow'!D19 -> 1828802 | E6: ='Cash Flow'!E19 -> 2628546 | F6: ='Cash Flow'!F19 -> 2617333 | G6: ='Cash Flow'!G19 -> 2524497.3 | H6: ='Cash Flow'!H19 -> 2886264.3 | I6: ='Cash Flow'!I19 -> 2537517.3 | ... N6: ='Cash Flow'!N19 -> 2772222.8
A7: Inc Cost 15% | C7: =C6*1.15 -> 2795582.9 | D7: =D6*1.15 -> 2103122.3 | E7: =E6*1.15 -> 3022827.9 | F7: =F6*1.15 -> 3009932.9 | G7: =G6*1.15 -> 2903171.9 | H7: =H6*1.15 -> 3319204 | I7: =I6*1.15 -> 2918144.9 | J7: =J6*1.15 -> 2903171.9 | ... N7: =N6*1.15 -> 3188056.3
A9: Presented | B9: =-B6 -> -2490230 | C9: =C3-C6 -> 2930348.3 | D9: =D3-D6 -> 4524046.4 | E9: =E3-E6 -> 7502000.4 | F9: =F3-F6 -> 10491167 | G9: =G3-G6 -> 13342670 | H9: =H3-H6 -> 16807906 | I9: =I3-I6 -> 19676388 | J9: =J3-J6 -> 22527891 | ... N9: =N3-N6 -> 36162157
A10: Scenerio 1 | B10: =B9 -> -2490230 | C10: =C4-C6 -> 1858090.3 | D10: =D4-D6 -> 3253476.7 | E10: =E4-E6 -> 5475891.1 | F10: =F4-F6 -> 7869467.3 | G10: =G4-G6 -> 10169237 | H10: =H4-H6 -> 12869072 | I10: =I4-I6 -> 15233607 | J10: =J4-J6 -> 17517413 | ... N10: =N4-N6 -> 28375281
A11: Scenerio 2 | B11: =B10 -> -2490230 | C11: =C3-C7 -> 2565707.1 | D11: =D3-D7 -> 4249726.1 | E11: =E3-E7 -> 7107718.5 | F11: =F3-F7 -> 10098567 | G11: =G3-G7 -> 12963995 | H11: =H3-H7 -> 16374966 | I11: =I3-I7 -> 19295761 | J11: =J3-J7 -> 22149216 | ... N11: =N3-N7 -> 35746323
E13: Presented | F13: Scenario 1 | G13: Scenario 2
D14: NPV | E14: =NPV(20%,B9:N9) -> 43770055 | F14: =NPV(20%,B10:N10) -> 32750812 | G14: =NPV(20%,B11:N11) -> 42382410
D15: IRR | E15: =IRR(B9:N9,30%) -> 1.6812249 | F15: =IRR(B10:N10,20%) -> 1.29888 | G15: =IRR(B11:N11,40%) -> 1.5794179

Sheet PROFILE INFORMATION
C1: Profile
A3: Name of business
A4: Type of Business (Production, Service, Trade) | C4: PRODUCTS AND SERVICES
A5: Product/Services
A6: Business Location
A7: Name of promoter | H7: Phone
B9: Gender | D9: Age | F9: Email
A10: Contact Home address
A11: State of Origin
A12: Business Status (Startup, Existing, Expansion)
A13: Likely take off date for the business
A15: Type of ownership | D15: SOLE PROPRIETOR
A18: Investment
A19: Expansion Capital | B19: ='Cash Flow'!B8 -> 2245020 | D19: Number of employee | H19: 3
A20: Equity | B20: ='Cash Flow'!B6 -> -280627.5
A21: Loan | B21: ='Cash Flow'!B7 -> 2525647.5 | D21: Total value of Equipment | H21: ='PRE-OPERATING, EQUIPMENT'!M23 -> 943000
A22: Loan tenor ( Months) | B22: 36 MONTHS | D22: Total pre-operating exp | H22: ='Cash Flow'!B10 -> 1862740
A23: Moratorium | B23: 3 MONTHS | D23: Monthly Operating exp
A24: Interest rated considered | B24: 0.09
A27: Financial indicators
A28: Number of Months projected: | B28: 36 | D28: Type of Projection | H28: =IF(B28=12,"Monthly",IF(B28=24,"Bimontly", IF(B28=36,"Quarterly",IF(B28=60,"Semi-annual","")))) -> Quarterly
A29: Total turnover | B29: ='Profit and Loss Statement'!N3 -> 67937000 | D29: Length or period (Months)
A30: Total Gross profit | B30: ='Profit and Loss Statement'!N7 -> 52439500
A31: Total Net Profit bf tax | B31: ='Profit and Loss Statement'!N18 -> 44954074 | D31: NPV | H31: ='Viability Analysis'!E14 -> 43770055
A32: Net profit after tax | B32: ='Profit and Loss Statement'!N20 -> 35963259 | D32: IRR | H32: ='Viability Analysis'!E15 -> 1.6812249
A33: Cash balance end of the period | B33: ='Cash Flow'!N20 -> 36162157 | D33: ROI | H33: =B32/B19*100 -> 1601.9126
A37: Trainees Batch Number: | C37: Supervisor’s Name
A38: Training Location:
A39: Date of Submission: | F39: Number of copy Submitted: | I39: 1
