Workbook
Name Event: 'Todo-Holiday-Event'!$M$9:$M$28
Name Event_Date: 'Todo-Holiday-Event'!$L$9:$L$28
Name Holiday: 'Todo-Holiday-Event'!$I$9:$I$28
Name Holiday_Date: 'Todo-Holiday-Event'!$H$9:$H$28
Name MonthRef: 'Supporting Calendar'!$J$2:$J$13
Name Months: 'Supporting Calendar'!$K$2:$K$13
Name StartMonth: 'Todo-Holiday-Event'!$E$4

Sheet Todo-Holiday-Event
B2: 2019 MONTHLY CALENDAR - EVENT TABLE
B4: STARTING MONTH | E4: February
B6: YEAR | E6: 2019 | K6: © 2019 - exceltemplate.net
B8: NO | C8: DATE | D8: TIME | E8: TO DO | G8: NO | H8: DATE | I8: HOLIDAY | K8: NO | L8: DATE | M8: IMPORTANT EVENT
B9: 1 | C9: 43595 | D9: 0.625 | E9: Booking Hotel | G9: 1 | H9: 43497 | I9: New Year’s Day | K9: 1 | L9: 43467 | M9: Company Birthday
B10: 2 | C10: 43602 | D10: 0.375 | E10: Warriors vs Lakers | G10: 2 | H10: =DATE(E6,1,1)+IF(2<WEEKDAY(DATE(E6,1,1)),7-WEEKDAY(DATE(E6,1,1))+2,2-WEEKDAY(DATE(E6,1,1)))+((3-1)*7) -> 43486 | I10: Martin Luther King, Jr. Day | K10: 2 | L10: 43623 | M10: Jane Doe Birthday
B11: 3 | C11: 43609 | D11: 0.375 | E11: House Renovation | G11: 3 | H11: =DATE(E6,2,1)+IF(2<WEEKDAY(DATE(E6,2,1)),7-WEEKDAY(DATE(E6,2,1))+2,2-WEEKDAY(DATE(E6,2,1)))+((3-1)*7) -> 43514 | I11: Presidents’ Day | K11: 3 | L11: 43684 | M11: Jane Doe Show
B12: 4 | C12: 43616 | D12: 0.625 | E12: MU vs Arsenal | G12: 4 | H12: =DATE(E6,6,1)+IF(2<WEEKDAY(DATE(E6,6,1)),7-WEEKDAY(DATE(E6,6,1))+2,2-WEEKDAY(DATE(E6,6,1)))+((1-1)*7)-7 -> 43612 | I12: Memorial Day | K12: 4 | L12: 43533 | M12: John Doe Birthday
B13: 5 | C13: 43716 | D13: 0.70833333 | E13: Madrid vs Barcelona | G13: 5 | H13: =DATE(E6,7,4) -> 43650 | I13: Independence Day | K13: 5
B14: 6 | C14: 43684 | D14: 0.375 | E14: Meeting with ABC | G14: 6 | H14: =DATE(E6,9,1)+IF(2<WEEKDAY(DATE(E6,9,1)),7-WEEKDAY(DATE(E6,9,1))+2,2-WEEKDAY(DATE(E6,9,1)))+((1-1)*7) -> 43710 | I14: Labor Day | K14: 6
B15: 7 | C15: 43717 | D15: 0.75 | E15: Romantic Dinner | G15: 7 | H15: =DATE(E6,11,11) -> 43780 | I15: Veterans Day | K15: 7
B16: 8 | C16: 43695 | D16: 0.70833333 | E16: Shopping | G16: 8 | H16: =DATE(E6,10,1)+IF(2<WEEKDAY(DATE(E6,10,1)),7-WEEKDAY(DATE(E6,10,1))+2,2-WEEKDAY(DATE(E6,10,1)))+((2-1)*7) -> 43752 | I16: Columbus Day | K16: 8
B17: 9 | C17: 43498 | D17: 0.70833333 | E17: Finalizing Proposal | G17: 9 | H17: =DATE(E6,11,1)+IF(5<WEEKDAY(DATE(E6,11,1)),7-WEEKDAY(DATE(E6,11,1))+5,5-WEEKDAY(DATE(E6,11,1)))+((4-1)*7) -> 43797 | I17: Thanksgiving Day | K17: 9
B18: 10 | C18: 43497 | D18: 0.75 | E18: Hang Out | G18: 10 | H18: =DATE(E6,12,25) -> 43824 | I18: Christmas Day | K18: 10
B19: 11 | G19: 11 | K19: 11
B20: 12 | G20: 12 | K20: 12
B21: 13 | G21: 13 | K21: 13
B22: 14 | G22: 14 | K22: 14
B23: 15 | G23: 15 | K23: 15
B24: 16 | G24: 16 | K24: 16
B25: 17 | G25: 17 | K25: 17
B26: 18 | G26: 18 | K26: 18
B27: 19 | G27: 19 | K27: 19
B28: 20 | G28: 20 | K28: 20
B29: 21
B30: 22
B31: 23
B32: 24
B33: 25
B34: 26
B35: 27
B36: 28
B37: 29
B38: 30
B39: 31
B40: 32
... B258: 250

Sheet Layout 1
A2: =UPPER(TEXT(DATE(M31,O31,K16),"mmmm yyyy")) -> AUGUST YYYY
C5: SUNDAY | E5: MONDAY | G5: TUESDAY | I5: WEDNESDAY | K5: THURSDAY | M5: FRIDAY | O5: SATURDAY
C6: =IF(WEEKDAY(DATE($M$31,$O$31,1))=1,1,"") | D6: =IF(C6<>"",IF(ISNA(VLOOKUP(DATE($M$31,$O$31,C6),'Todo-Holiday-Event'!$L$9:$M$28,2,FALSE)),IF(ISNA(VLOOKUP(DATE($M$31,$O$31,C6),'Todo-Holiday-Event'!$H$9:$I$28,2,FALSE)),"",VLOOKUP(DATE($M$31,$O$31,C6),'Todo-Holiday-Event'!$H$9:$I$28,2,FALSE)),VLOOKUP(DATE($M$31,$O$31,C6),'Todo-Holiday-Event'!$L$9:$M$28,2,FALSE)),"") | E6: =IF(C6<>"",C6+1,IF(WEEKDAY(DATE($M$31,$O$31,1))=2,1,"")) | F6: =IF(E6<>"",IF(ISNA(VLOOKUP(DATE($M$31,$O$31,E6),'Todo-Holiday-Event'!$L$9:$M$28,2,FALSE)),IF(ISNA(VLOOKUP(DATE($M$31,$O$31,E6),'Todo-Holiday-Event'!$H$9:$I$28,2,FALSE)),"",VLOOKUP(DATE($M$31,$O$31,E6),'Todo-Holiday-Event'!$H$9:$I$28,2,FALSE)),VLOOKUP(DATE($M$31,$O$31,E6),'Todo-Holiday-Event'!$L$9:$M$28,2,FALSE)),"") | G6: =IF(E6<>"",E6+1,IF(WEEKDAY(DATE($M$31,$O$31,1))=3,1,"")) | H6: =IF(G6<>"",IF(ISNA(VLOOKUP(DATE($M$31,$O$31,G6),'Todo-Holiday-Event'!$L$9:$M$28,2,FALSE)),IF(ISNA(VLOOKUP(DATE($M$31,$O$31,G6),'Todo-Holiday-Event'!$H$9:$I$28,2,FALSE)),"",VLOOKUP(DATE($M$31,$O$31,G6),'Todo-Holiday-Event'!$H$9:$I$28,2,FALSE)),VLOOKUP(DATE($M$31,$O$31,G6),'Todo-Holiday-Event'!$L$9:$M$28,2,FALSE)),"") | I6: =IF(G6<>"",G6+1,IF(WEEKDAY(DATE($M$31,$O$31,1))=4,1,"")) | J6: =IF(I6<>"",IF(ISNA(VLOOKUP(DATE($M$31,$O$31,I6),'Todo-Holiday-Event'!$L$9:$M$28,2,FALSE)),IF(ISNA(VLOOKUP(DATE($M$31,$O$31,I6),'Todo-Holiday-Event'!$H$9:$I$28,2,FALSE)),"",VLOOKUP(DATE($M$31,$O$31,I6),'Todo-Holiday-Event'!$H$9:$I$28,2,FALSE)),VLOOKUP(DATE($M$31,$O$31,I6),'Todo-Holiday-Event'!$L$9:$M$28,2,FALSE)),"") | K6: =IF(I6<>"",I6+1,IF(WEEKDAY(DATE($M$31,$O$31,1))=5,1,"")) -> 1 | L6: =IF(K6<>"",IF(ISNA(VLOOKUP(DATE($M$31,$O$31,K6),'Todo-Holiday-Event'!$L$9:$M$28,2,FALSE)),IF(ISNA(VLOOKUP(DATE($M$31,$O$31,K6),'Todo-Holiday-Event'!$H$9:$I$28,2,FALSE)),"",VLOOKUP(DATE($M$31,$O$31,K6),'Todo-Holiday-Event'!$H$9:$I$28,2,FALSE)),VLOOKUP(DATE($M$31,$O$31,K6),'Todo-Holiday-Event'!$L$9:$M$28,2,FALSE)),"") | M6: =IF(K6<>"",K6+1,IF(WEEKDAY(DATE($M$31,$O$31,1))=6,1,"")) -> 2 | N6: =IF(M6<>"",IF(ISNA(VLOOKUP(DATE($M$31,$O$31,M6),'Todo-Holiday-Event'!$L$9:$M$28,2,FALSE)),IF(ISNA(VLOOKUP(DATE($M$31,$O$31,M6),'Todo-Holiday-Event'!$H$9:$I$28,2,FALSE)),"",VLOOKUP(DATE($M$31,$O$31,M6),'Todo-Holiday-Event'!$H$9:$I$28,2,FALSE)),VLOOKUP(DATE($M$31,$O$31,M6),'Todo-Holiday-Event'!$L$9:$M$28,2,FALSE)),"") | O6: =IF(M6<>"",M6+1,IF(WEEKDAY(DATE($M$31,$O$31,1))=7,1,"")) -> 3 | P6: =IF(O6<>"",IF(ISNA(VLOOKUP(DATE($M$31,$O$31,O6),'Todo-Holiday-Event'!$L$9:$M$28,2,FALSE)),IF(ISNA(VLOOKUP(DATE($M$31,$O$31,O6),'Todo-Holiday-Event'!$H$9:$I$28,2,FALSE)),"",VLOOKUP(DATE($M$31,$O$31,O6),'Todo-Holiday-Event'!$H$9:$I$28,2,FALSE)),VLOOKUP(DATE($M$31,$O$31,O6),'Todo-Holiday-Event'!$L$9:$M$28,2,FALSE)),"")
C7: =IF(ISERROR('Supporting Calendar'!AB1),"",INDEX('Todo-Holiday-Event'!$D$9:$D$258,'Supporting Calendar'!AB1)) | D7: =IF(ISERROR('Supporting Calendar'!AB1),"",INDEX('Todo-Holiday-Event'!$E$9:$E$258,'Supporting Calendar'!AB1)) | E7: =IF(ISERROR('Supporting Calendar'!AC1),"",INDEX('Todo-Holiday-Event'!$D$9:$D$258,'Supporting Calendar'!AC1)) | F7: =IF(ISERROR('Supporting Calendar'!AC1),"",INDEX('Todo-Holiday-Event'!$E$9:$E$258,'Supporting Calendar'!AC1)) | G7: =IF(ISERROR('Supporting Calendar'!AD1),"",INDEX('Todo-Holiday-Event'!$D$9:$D$258,'Supporting Calendar'!AD1)) | H7: =IF(ISERROR('Supporting Calendar'!AD1),"",INDEX('Todo-Holiday-Event'!$E$9:$E$258,'Supporting Calendar'!AD1)) | I7: =IF(ISERROR('Supporting Calendar'!AE1),"",INDEX('Todo-Holiday-Event'!$D$9:$D$258,'Supporting Calendar'!AE1)) | J7: =IF(ISERROR('Supporting Calendar'!AE1),"",INDEX('Todo-Holiday-Event'!$E$9:$E$258,'Supporting Calendar'!AE1)) | K7: =IF(ISERROR('Supporting Calendar'!AF1),"",INDEX('Todo-Holiday-Event'!$D$9:$D$258,'Supporting Calendar'!AF1)) | L7: =IF(ISERROR('Supporting Calendar'!AF1),"",INDEX('Todo-Holiday-Event'!$E$9:$E$258,'Supporting Calendar'!AF1)) | M7: =IF(ISERROR('Supporting Calendar'!AG1),"",INDEX('Todo-Holiday-Event'!$D$9:$D$258,'Supporting Calendar'!AG1)) | N7: =IF(ISERROR('Supporting Calendar'!AG1),"",INDEX('Todo-Holiday-Event'!$E$9:$E$258,'Supporting Calendar'!AG1)) | O7: =IF(ISERROR('Supporting Calendar'!AH1),"",INDEX('Todo-Holiday-Event'!$D$9:$D$258,'Supporting Calendar'!AH1)) | P7: =IF(ISERROR('Supporting Calendar'!AH1),"",INDEX('Todo-Holiday-Event'!$E$9:$E$258,'Supporting Calendar'!AH1))
C8: =IF(ISERROR('Supporting Calendar'!AB2),"",INDEX('Todo-Holiday-Event'!$D$9:$D$258,'Supporting Calendar'!AB2)) | D8: =IF(ISERROR('Supporting Calendar'!AB2),"",INDEX('Todo-Holiday-Event'!$E$9:$E$258,'Supporting Calendar'!AB2)) | E8: =IF(ISERROR('Supporting Calendar'!AC2),"",INDEX('Todo-Holiday-Event'!$D$9:$D$258,'Supporting Calendar'!AC2)) | F8: =IF(ISERROR('Supporting Calendar'!AC2),"",INDEX('Todo-Holiday-Event'!$E$9:$E$258,'Supporting Calendar'!AC2)) | G8: =IF(ISERROR('Supporting Calendar'!AD2),"",INDEX('Todo-Holiday-Event'!$D$9:$D$258,'Supporting Calendar'!AD2)) | H8: =IF(ISERROR('Supporting Calendar'!AD2),"",INDEX('Todo-Holiday-Event'!$E$9:$E$258,'Supporting Calendar'!AD2)) | I8: =IF(ISERROR('Supporting Calendar'!AE2),"",INDEX('Todo-Holiday-Event'!$D$9:$D$258,'Supporting Calendar'!AE2)) | J8: =IF(ISERROR('Supporting Calendar'!AE2),"",INDEX('Todo-Holiday-Event'!$E$9:$E$258,'Supporting Calendar'!AE2)) | K8: =IF(ISERROR('Supporting Calendar'!AF2),"",INDEX('Todo-Holiday-Event'!$D$9:$D$258,'Supporting Calendar'!AF2)) | L8: =IF(ISERROR('Supporting Calendar'!AF2),"",INDEX('Todo-Holiday-Event'!$E$9:$E$258,'Supporting Calendar'!AF2)) | M8: =IF(ISERROR('Supporting Calendar'!AG2),"",INDEX('Todo-Holiday-Event'!$D$9:$D$258,'Supporting Calendar'!AG2)) | N8: =IF(ISERROR('Supporting Calendar'!AG2),"",INDEX('Todo-Holiday-Event'!$E$9:$E$258,'Supporting Calendar'!AG2)) | O8: =IF(ISERROR('Supporting Calendar'!AH2),"",INDEX('Todo-Holiday-Event'!$D$9:$D$258,'Supporting Calendar'!AH2)) | P8: =IF(ISERROR('Supporting Calendar'!AH2),"",INDEX('Todo-Holiday-Event'!$E$9:$E$258,'Supporting Calendar'!AH2))
C9: =IF(ISERROR('Supporting Calendar'!AB3),"",INDEX('Todo-Holiday-Event'!$D$9:$D$258,'Supporting Calendar'!AB3)) | D9: =IF(ISERROR('Supporting Calendar'!AB3),"",INDEX('Todo-Holiday-Event'!$E$9:$E$258,'Supporting Calendar'!AB3)) | E9: =IF(ISERROR('Supporting Calendar'!AC3),"",INDEX('Todo-Holiday-Event'!$D$9:$D$258,'Supporting Calendar'!AC3)) | F9: =IF(ISERROR('Supporting Calendar'!AC3),"",INDEX('Todo-Holiday-Event'!$E$9:$E$258,'Supporting Calendar'!AC3)) | G9: =IF(ISERROR('Supporting Calendar'!AD3),"",INDEX('Todo-Holiday-Event'!$D$9:$D$258,'Supporting Calendar'!AD3)) | H9: =IF(ISERROR('Supporting Calendar'!AD3),"",INDEX('Todo-Holiday-Event'!$E$9:$E$258,'Supporting Calendar'!AD3)) | I9: =IF(ISERROR('Supporting Calendar'!AE3),"",INDEX('Todo-Holiday-Event'!$D$9:$D$258,'Supporting Calendar'!AE3)) | J9: =IF(ISERROR('Supporting Calendar'!AE3),"",INDEX('Todo-Holiday-Event'!$E$9:$E$258,'Supporting Calendar'!AE3)) | K9: =IF(ISERROR('Supporting Calendar'!AF3),"",INDEX('Todo-Holiday-Event'!$D$9:$D$258,'Supporting Calendar'!AF3)) | L9: =IF(ISERROR('Supporting Calendar'!AF3),"",INDEX('Todo-Holiday-Event'!$E$9:$E$258,'Supporting Calendar'!AF3)) | M9: =IF(ISERROR('Supporting Calendar'!AG3),"",INDEX('Todo-Holiday-Event'!$D$9:$D$258,'Supporting Calendar'!AG3)) | N9: =IF(ISERROR('Supporting Calendar'!AG3),"",INDEX('Todo-Holiday-Event'!$E$9:$E$258,'Supporting Calendar'!AG3)) | O9: =IF(ISERROR('Supporting Calendar'!AH3),"",INDEX('Todo-Holiday-Event'!$D$9:$D$258,'Supporting Calendar'!AH3)) | P9: =IF(ISERROR('Supporting Calendar'!AH3),"",INDEX('Todo-Holiday-Event'!$E$9:$E$258,'Supporting Calendar'!AH3))
C10: =IF(ISERROR('Supporting Calendar'!AB4),"",INDEX('Todo-Holiday-Event'!$D$9:$D$258,'Supporting Calendar'!AB4)) | D10: =IF(ISERROR('Supporting Calendar'!AB4),"",INDEX('Todo-Holiday-Event'!$E$9:$E$258,'Supporting Calendar'!AB4)) | E10: =IF(ISERROR('Supporting Calendar'!AC4),"",INDEX('Todo-Holiday-Event'!$D$9:$D$258,'Supporting Calendar'!AC4)) | F10: =IF(ISERROR('Supporting Calendar'!AC4),"",INDEX('Todo-Holiday-Event'!$E$9:$E$258,'Supporting Calendar'!AC4)) | G10: =IF(ISERROR('Supporting Calendar'!AD4),"",INDEX('Todo-Holiday-Event'!$D$9:$D$258,'Supporting Calendar'!AD4)) | H10: =IF(ISERROR('Supporting Calendar'!AD4),"",INDEX('Todo-Holiday-Event'!$E$9:$E$258,'Supporting Calendar'!AD4)) | I10: =IF(ISERROR('Supporting Calendar'!AE4),"",INDEX('Todo-Holiday-Event'!$D$9:$D$258,'Supporting Calendar'!AE4)) | J10: =IF(ISERROR('Supporting Calendar'!AE4),"",INDEX('Todo-Holiday-Event'!$E$9:$E$258,'Supporting Calendar'!AE4)) | K10: =IF(ISERROR('Supporting Calendar'!AF4),"",INDEX('Todo-Holiday-Event'!$D$9:$D$258,'Supporting Calendar'!AF4)) | L10: =IF(ISERROR('Supporting Calendar'!AF4),"",INDEX('Todo-Holiday-Event'!$E$9:$E$258,'Supporting Calendar'!AF4)) | M10: =IF(ISERROR('Supporting Calendar'!AG4),"",INDEX('Todo-Holiday-Event'!$D$9:$D$258,'Supporting Calendar'!AG4)) | N10: =IF(ISERROR('Supporting Calendar'!AG4),"",INDEX('Todo-Holiday-Event'!$E$9:$E$258,'Supporting Calendar'!AG4)) | O10: =IF(ISERROR('Supporting Calendar'!AH4),"",INDEX('Todo-Holiday-Event'!$D$9:$D$258,'Supporting Calendar'!AH4)) | P10: =IF(ISERROR('Supporting Calendar'!AH4),"",INDEX('Todo-Holiday-Event'!$E$9:$E$258,'Supporting Calendar'!AH4))
C11: =O6+1 -> 4 | D11: =IF(C11<>"",IF(ISNA(VLOOKUP(DATE($M$31,$O$31,C11),'Todo-Holiday-Event'!$L$9:$M$28,2,FALSE)),IF(ISNA(VLOOKUP(DATE($M$31,$O$31,C11),'Todo-Holiday-Event'!$H$9:$I$28,2,FALSE)),"",VLOOKUP(DATE($M$31,$O$31,C11),'Todo-Holiday-Event'!$H$9:$I$28,2,FALSE)),VLOOKUP(DATE($M$31,$O$31,C11),'Todo-Holiday-Event'!$L$9:$M$28,2,FALSE)),"") | E11: =C11+1 -> 5 | F11: =IF(E11<>"",IF(ISNA(VLOOKUP(DATE($M$31,$O$31,E11),'Todo-Holiday-Event'!$L$9:$M$28,2,FALSE)),IF(ISNA(VLOOKUP(DATE($M$31,$O$31,E11),'Todo-Holiday-Event'!$H$9:$I$28,2,FALSE)),"",VLOOKUP(DATE($M$31,$O$31,E11),'Todo-Holiday-Event'!$H$9:$I$28,2,FALSE)),VLOOKUP(DATE($M$31,$O$31,E11),'Todo-Holiday-Event'!$L$9:$M$28,2,FALSE)),"") | G11: =E11+1 -> 6 | H11: =IF(G11<>"",IF(ISNA(VLOOKUP(DATE($M$31,$O$31,G11),'Todo-Holiday-Event'!$L$9:$M$28,2,FALSE)),IF(ISNA(VLOOKUP(DATE($M$31,$O$31,G11),'Todo-Holiday-Event'!$H$9:$I$28,2,FALSE)),"",VLOOKUP(DATE($M$31,$O$31,G11),'Todo-Holiday-Event'!$H$9:$I$28,2,FALSE)),VLOOKUP(DATE($M$31,$O$31,G11),'Todo-Holiday-Event'!$L$9:$M$28,2,FALSE)),"") | I11: =G11+1 -> 7 | J11: =IF(I11<>"",IF(ISNA(VLOOKUP(DATE($M$31,$O$31,I11),'Todo-Holiday-Event'!$L$9:$M$28,2,FALSE)),IF(ISNA(VLOOKUP(DATE($M$31,$O$31,I11),'Todo-Holiday-Event'!$H$9:$I$28,2,FALSE)),"",VLOOKUP(DATE($M$31,$O$31,I11),'Todo-Holiday-Event'!$H$9:$I$28,2,FALSE)),VLOOKUP(DATE($M$31,$O$31,I11),'Todo-Holiday-Event'!$L$9:$M$28,2,FALSE)),"") -> Jane Doe Show | K11: =I11+1 -> 8 | L11: =IF(K11<>"",IF(ISNA(VLOOKUP(DATE($M$31,$O$31,K11),'Todo-Holiday-Event'!$L$9:$M$28,2,FALSE)),IF(ISNA(VLOOKUP(DATE($M$31,$O$31,K11),'Todo-Holiday-Event'!$H$9:$I$28,2,FALSE)),"",VLOOKUP(DATE($M$31,$O$31,K11),'Todo-Holiday-Event'!$H$9:$I$28,2,FALSE)),VLOOKUP(DATE($M$31,$O$31,K11),'Todo-Holiday-Event'!$L$9:$M$28,2,FALSE)),"") | M11: =K11+1 -> 9 | N11: =IF(M11<>"",IF(ISNA(VLOOKUP(DATE($M$31,$O$31,M11),'Todo-Holiday-Event'!$L$9:$M$28,2,FALSE)),IF(ISNA(VLOOKUP(DATE($M$31,$O$31,M11),'Todo-Holiday-Event'!$H$9:$I$28,2,FALSE)),"",VLOOKUP(DATE($M$31,$O$31,M11),'Todo-Holiday-Event'!$H$9:$I$28,2,FALSE)),VLOOKUP(DATE($M$31,$O$31,M11),'Todo-Holiday-Event'!$L$9:$M$28,2,FALSE)),"") | O11: =M11+1 -> 10 | P11: =IF(O11<>"",IF(ISNA(VLOOKUP(DATE($M$31,$O$31,O11),'Todo-Holiday-Event'!$L$9:$M$28,2,FALSE)),IF(ISNA(VLOOKUP(DATE($M$31,$O$31,O11),'Todo-Holiday-Event'!$H$9:$I$28,2,FALSE)),"",VLOOKUP(DATE($M$31,$O$31,O11),'Todo-Holiday-Event'!$H$9:$I$28,2,FALSE)),VLOOKUP(DATE($M$31,$O$31,O11),'Todo-Holiday-Event'!$L$9:$M$28,2,FALSE)),"")
C12: =IF(ISERROR('Supporting Calendar'!AB7),"",INDEX('Todo-Holiday-Event'!$D$9:$D$258,'Supporting Calendar'!AB7)) | D12: =IF(ISERROR('Supporting Calendar'!AB7),"",INDEX('Todo-Holiday-Event'!$E$9:$E$258,'Supporting Calendar'!AB7)) | E12: =IF(ISERROR('Supporting Calendar'!AC7),"",INDEX('Todo-Holiday-Event'!$D$9:$D$258,'Supporting Calendar'!AC7)) | F12: =IF(ISERROR('Supporting Calendar'!AC7),"",INDEX('Todo-Holiday-Event'!$E$9:$E$258,'Supporting Calendar'!AC7)) | G12: =IF(ISERROR('Supporting Calendar'!AD7),"",INDEX('Todo-Holiday-Event'!$D$9:$D$258,'Supporting Calendar'!AD7)) | H12: =IF(ISERROR('Supporting Calendar'!AD7),"",INDEX('Todo-Holiday-Event'!$E$9:$E$258,'Supporting Calendar'!AD7)) | I12: =IF(ISERROR('Supporting Calendar'!AE7),"",INDEX('Todo-Holiday-Event'!$D$9:$D$258,'Supporting Calendar'!AE7)) -> 0.375 | J12: =IF(ISERROR('Supporting Calendar'!AE7),"",INDEX('Todo-Holiday-Event'!$E$9:$E$258,'Supporting Calendar'!AE7)) -> Meeting with ABC | K12: =IF(ISERROR('Supporting Calendar'!AF7),"",INDEX('Todo-Holiday-Event'!$D$9:$D$258,'Supporting Calendar'!AF7)) | L12: =IF(ISERROR('Supporting Calendar'!AF7),"",INDEX('Todo-Holiday-Event'!$E$9:$E$258,'Supporting Calendar'!AF7)) | M12: =IF(ISERROR('Supporting Calendar'!AG7),"",INDEX('Todo-Holiday-Event'!$D$9:$D$258,'Supporting Calendar'!AG7)) | N12: =IF(ISERROR('Supporting Calendar'!AG7),"",INDEX('Todo-Holiday-Event'!$E$9:$E$258,'Supporting Calendar'!AG7)) | O12: =IF(ISERROR('Supporting Calendar'!AH7),"",INDEX('Todo-Holiday-Event'!$D$9:$D$258,'Supporting Calendar'!AH7)) | P12: =IF(ISERROR('Supporting Calendar'!AH7),"",INDEX('Todo-Holiday-Event'!$E$9:$E$258,'Supporting Calendar'!AH7))
C13: =IF(ISERROR('Supporting Calendar'!AB8),"",INDEX('Todo-Holiday-Event'!$D$9:$D$258,'Supporting Calendar'!AB8)) | D13: =IF(ISERROR('Supporting Calendar'!AB8),"",INDEX('Todo-Holiday-Event'!$E$9:$E$258,'Supporting Calendar'!AB8)) | E13: =IF(ISERROR('Supporting Calendar'!AC8),"",INDEX('Todo-Holiday-Event'!$D$9:$D$258,'Supporting Calendar'!AC8)) | F13: =IF(ISERROR('Supporting Calendar'!AC8),"",INDEX('Todo-Holiday-Event'!$E$9:$E$258,'Supporting Calendar'!AC8)) | G13: =IF(ISERROR('Supporting Calendar'!AD8),"",INDEX('Todo-Holiday-Event'!$D$9:$D$258,'Supporting Calendar'!AD8)) | H13: =IF(ISERROR('Supporting Calendar'!AD8),"",INDEX('Todo-Holiday-Event'!$E$9:$E$258,'Supporting Calendar'!AD8)) | I13: =IF(ISERROR('Supporting Calendar'!AE8),"",INDEX('Todo-Holiday-Event'!$D$9:$D$258,'Supporting Calendar'!AE8)) | J13: =IF(ISERROR('Supporting Calendar'!AE8),"",INDEX('Todo-Holiday-Event'!$E$9:$E$258,'Supporting Calendar'!AE8)) | K13: =IF(ISERROR('Supporting Calendar'!AF8),"",INDEX('Todo-Holiday-Event'!$D$9:$D$258,'Supporting Calendar'!AF8)) | L13: =IF(ISERROR('Supporting Calendar'!AF8),"",INDEX('Todo-Holiday-Event'!$E$9:$E$258,'Supporting Calendar'!AF8)) | M13: =IF(ISERROR('Supporting Calendar'!AG8),"",INDEX('Todo-Holiday-Event'!$D$9:$D$258,'Supporting Calendar'!AG8)) | N13: =IF(ISERROR('Supporting Calendar'!AG8),"",INDEX('Todo-Holiday-Event'!$E$9:$E$258,'Supporting Calendar'!AG8)) | O13: =IF(ISERROR('Supporting Calendar'!AH8),"",INDEX('Todo-Holiday-Event'!$D$9:$D$258,'Supporting Calendar'!AH8)) | P13: =IF(ISERROR('Supporting Calendar'!AH8),"",INDEX('Todo-Holiday-Event'!$E$9:$E$258,'Supporting Calendar'!AH8))
C14: =IF(ISERROR('Supporting Calendar'!AB9),"",INDEX('Todo-Holiday-Event'!$D$9:$D$258,'Supporting Calendar'!AB9)) | D14: =IF(ISERROR('Supporting Calendar'!AB9),"",INDEX('Todo-Holiday-Event'!$E$9:$E$258,'Supporting Calendar'!AB9)) | E14: =IF(ISERROR('Supporting Calendar'!AC9),"",INDEX('Todo-Holiday-Event'!$D$9:$D$258,'Supporting Calendar'!AC9)) | F14: =IF(ISERROR('Supporting Calendar'!AC9),"",INDEX('Todo-Holiday-Event'!$E$9:$E$258,'Supporting Calendar'!AC9)) | G14: =IF(ISERROR('Supporting Calendar'!AD9),"",INDEX('Todo-Holiday-Event'!$D$9:$D$258,'Supporting Calendar'!AD9)) | H14: =IF(ISERROR('Supporting Calendar'!AD9),"",INDEX('Todo-Holiday-Event'!$E$9:$E$258,'Supporting Calendar'!AD9)) | I14: =IF(ISERROR('Supporting Calendar'!AE9),"",INDEX('Todo-Holiday-Event'!$D$9:$D$258,'Supporting Calendar'!AE9)) | J14: =IF(ISERROR('Supporting Calendar'!AE9),"",INDEX('Todo-Holiday-Event'!$E$9:$E$258,'Supporting Calendar'!AE9)) | K14: =IF(ISERROR('Supporting Calendar'!AF9),"",INDEX('Todo-Holiday-Event'!$D$9:$D$258,'Supporting Calendar'!AF9)) | L14: =IF(ISERROR('Supporting Calendar'!AF9),"",INDEX('Todo-Holiday-Event'!$E$9:$E$258,'Supporting Calendar'!AF9)) | M14: =IF(ISERROR('Supporting Calendar'!AG9),"",INDEX('Todo-Holiday-Event'!$D$9:$D$258,'Supporting Calendar'!AG9)) | N14: =IF(ISERROR('Supporting Calendar'!AG9),"",INDEX('Todo-Holiday-Event'!$E$9:$E$258,'Supporting Calendar'!AG9)) | O14: =IF(ISERROR('Supporting Calendar'!AH9),"",INDEX('Todo-Holiday-Event'!$D$9:$D$258,'Supporting Calendar'!AH9)) | P14: =IF(ISERROR('Supporting Calendar'!AH9),"",INDEX('Todo-Holiday-Event'!$E$9:$E$258,'Supporting Calendar'!AH9))
C15: =IF(ISERROR('Supporting Calendar'!AB10),"",INDEX('Todo-Holiday-Event'!$D$9:$D$258,'Supporting Calendar'!AB10)) | D15: =IF(ISERROR('Supporting Calendar'!AB10),"",INDEX('Todo-Holiday-Event'!$E$9:$E$258,'Supporting Calendar'!AB10)) | E15: =IF(ISERROR('Supporting Calendar'!AC10),"",INDEX('Todo-Holiday-Event'!$D$9:$D$258,'Supporting Calendar'!AC10)) | F15: =IF(ISERROR('Supporting Calendar'!AC10),"",INDEX('Todo-Holiday-Event'!$E$9:$E$258,'Supporting Calendar'!AC10)) | G15: =IF(ISERROR('Supporting Calendar'!AD10),"",INDEX('Todo-Holiday-Event'!$D$9:$D$258,'Supporting Calendar'!AD10)) | H15: =IF(ISERROR('Supporting Calendar'!AD10),"",INDEX('Todo-Holiday-Event'!$E$9:$E$258,'Supporting Calendar'!AD10)) | I15: =IF(ISERROR('Supporting Calendar'!AE10),"",INDEX('Todo-Holiday-Event'!$D$9:$D$258,'Supporting Calendar'!AE10)) | J15: =IF(ISERROR('Supporting Calendar'!AE10),"",INDEX('Todo-Holiday-Event'!$E$9:$E$258,'Supporting Calendar'!AE10)) | K15: =IF(ISERROR('Supporting Calendar'!AF10),"",INDEX('Todo-Holiday-Event'!$D$9:$D$258,'Supporting Calendar'!AF10)) | L15: =IF(ISERROR('Supporting Calendar'!AF10),"",INDEX('Todo-Holiday-Event'!$E$9:$E$258,'Supporting Calendar'!AF10)) | M15: =IF(ISERROR('Supporting Calendar'!AG10),"",INDEX('Todo-Holiday-Event'!$D$9:$D$258,'Supporting Calendar'!AG10)) | N15: =IF(ISERROR('Supporting Calendar'!AG10),"",INDEX('Todo-Holiday-Event'!$E$9:$E$258,'Supporting Calendar'!AG10)) | O15: =IF(ISERROR('Supporting Calendar'!AH10),"",INDEX('Todo-Holiday-Event'!$D$9:$D$258,'Supporting Calendar'!AH10)) | P15: =IF(ISERROR('Supporting Calendar'!AH10),"",INDEX('Todo-Holiday-Event'!$E$9:$E$258,'Supporting Calendar'!AH10))
C16: =O11+1 -> 11 | D16: =IF(C16<>"",IF(ISNA(VLOOKUP(DATE($M$31,$O$31,C16),'Todo-Holiday-Event'!$L$9:$M$28,2,FALSE)),IF(ISNA(VLOOKUP(DATE($M$31,$O$31,C16),'Todo-Holiday-Event'!$H$9:$I$28,2,FALSE)),"",VLOOKUP(DATE($M$31,$O$31,C16),'Todo-Holiday-Event'!$H$9:$I$28,2,FALSE)),VLOOKUP(DATE($M$31,$O$31,C16),'Todo-Holiday-Event'!$L$9:$M$28,2,FALSE)),"") | E16: =C16+1 -> 12 | F16: =IF(E16<>"",IF(ISNA(VLOOKUP(DATE($M$31,$O$31,E16),'Todo-Holiday-Event'!$L$9:$M$28,2,FALSE)),IF(ISNA(VLOOKUP(DATE($M$31,$O$31,E16),'Todo-Holiday-Event'!$H$9:$I$28,2,FALSE)),"",VLOOKUP(DATE($M$31,$O$31,E16),'Todo-Holiday-Event'!$H$9:$I$28,2,FALSE)),VLOOKUP(DATE($M$31,$O$31,E16),'Todo-Holiday-Event'!$L$9:$M$28,2,FALSE)),"") | G16: =E16+1 -> 13 | H16: =IF(G16<>"",IF(ISNA(VLOOKUP(DATE($M$31,$O$31,G16),'Todo-Holiday-Event'!$L$9:$M$28,2,FALSE)),IF(ISNA(VLOOKUP(DATE($M$31,$O$31,G16),'Todo-Holiday-Event'!$H$9:$I$28,2,FALSE)),"",VLOOKUP(DATE($M$31,$O$31,G16),'Todo-Holiday-Event'!$H$9:$I$28,2,FALSE)),VLOOKUP(DATE($M$31,$O$31,G16),'Todo-Holiday-Event'!$L$9:$M$28,2,FALSE)),"") | I16: =G16+1 -> 14 | J16: =IF(I16<>"",IF(ISNA(VLOOKUP(DATE($M$31,$O$31,I16),'Todo-Holiday-Event'!$L$9:$M$28,2,FALSE)),IF(ISNA(VLOOKUP(DATE($M$31,$O$31,I16),'Todo-Holiday-Event'!$H$9:$I$28,2,FALSE)),"",VLOOKUP(DATE($M$31,$O$31,I16),'Todo-Holiday-Event'!$H$9:$I$28,2,FALSE)),VLOOKUP(DATE($M$31,$O$31,I16),'Todo-Holiday-Event'!$L$9:$M$28,2,FALSE)),"") | K16: =I16+1 -> 15 | L16: =IF(K16<>"",IF(ISNA(VLOOKUP(DATE($M$31,$O$31,K16),'Todo-Holiday-Event'!$L$9:$M$28,2,FALSE)),IF(ISNA(VLOOKUP(DATE($M$31,$O$31,K16),'Todo-Holiday-Event'!$H$9:$I$28,2,FALSE)),"",VLOOKUP(DATE($M$31,$O$31,K16),'Todo-Holiday-Event'!$H$9:$I$28,2,FALSE)),VLOOKUP(DATE($M$31,$O$31,K16),'Todo-Holiday-Event'!$L$9:$M$28,2,FALSE)),"") | M16: =K16+1 -> 16 | N16: =IF(M16<>"",IF(ISNA(VLOOKUP(DATE($M$31,$O$31,M16),'Todo-Holiday-Event'!$L$9:$M$28,2,FALSE)),IF(ISNA(VLOOKUP(DATE($M$31,$O$31,M16),'Todo-Holiday-Event'!$H$9:$I$28,2,FALSE)),"",VLOOKUP(DATE($M$31,$O$31,M16),'Todo-Holiday-Event'!$H$9:$I$28,2,FALSE)),VLOOKUP(DATE($M$31,$O$31,M16),'Todo-Holiday-Event'!$L$9:$M$28,2,FALSE)),"") | O16: =M16+1 -> 17 | P16: =IF(O16<>"",IF(ISNA(VLOOKUP(DATE($M$31,$O$31,O16),'Todo-Holiday-Event'!$L$9:$M$28,2,FALSE)),IF(ISNA(VLOOKUP(DATE($M$31,$O$31,O16),'Todo-Holiday-Event'!$H$9:$I$28,2,FALSE)),"",VLOOKUP(DATE($M$31,$O$31,O16),'Todo-Holiday-Event'!$H$9:$I$28,2,FALSE)),VLOOKUP(DATE($M$31,$O$31,O16),'Todo-Holiday-Event'!$L$9:$M$28,2,FALSE)),"")
C17: =IF(ISERROR('Supporting Calendar'!AB13),"",INDEX('Todo-Holiday-Event'!$D$9:$D$258,'Supporting Calendar'!AB13)) | D17: =IF(ISERROR('Supporting Calendar'!AB13),"",INDEX('Todo-Holiday-Event'!$E$9:$E$258,'Supporting Calendar'!AB13)) | E17: =IF(ISERROR('Supporting Calendar'!AC13),"",INDEX('Todo-Holiday-Event'!$D$9:$D$258,'Supporting Calendar'!AC13)) | F17: =IF(ISERROR('Supporting Calendar'!AC13),"",INDEX('Todo-Holiday-Event'!$E$9:$E$258,'Supporting Calendar'!AC13)) | G17: =IF(ISERROR('Supporting Calendar'!AD13),"",INDEX('Todo-Holiday-Event'!$D$9:$D$258,'Supporting Calendar'!AD13)) | H17: =IF(ISERROR('Supporting Calendar'!AD13),"",INDEX('Todo-Holiday-Event'!$E$9:$E$258,'Supporting Calendar'!AD13)) | I17: =IF(ISERROR('Supporting Calendar'!AE13),"",INDEX('Todo-Holiday-Event'!$D$9:$D$258,'Supporting Calendar'!AE13)) | J17: =IF(ISERROR('Supporting Calendar'!AE13),"",INDEX('Todo-Holiday-Event'!$E$9:$E$258,'Supporting Calendar'!AE13)) | K17: =IF(ISERROR('Supporting Calendar'!AF13),"",INDEX('Todo-Holiday-Event'!$D$9:$D$258,'Supporting Calendar'!AF13)) | L17: =IF(ISERROR('Supporting Calendar'!AF13),"",INDEX('Todo-Holiday-Event'!$E$9:$E$258,'Supporting Calendar'!AF13)) | M17: =IF(ISERROR('Supporting Calendar'!AG13),"",INDEX('Todo-Holiday-Event'!$D$9:$D$258,'Supporting Calendar'!AG13)) | N17: =IF(ISERROR('Supporting Calendar'!AG13),"",INDEX('Todo-Holiday-Event'!$E$9:$E$258,'Supporting Calendar'!AG13)) | O17: =IF(ISERROR('Supporting Calendar'!AH13),"",INDEX('Todo-Holiday-Event'!$D$9:$D$258,'Supporting Calendar'!AH13)) | P17: =IF(ISERROR('Supporting Calendar'!AH13),"",INDEX('Todo-Holiday-Event'!$E$9:$E$258,'Supporting Calendar'!AH13))
C18: =IF(ISERROR('Supporting Calendar'!AB14),"",INDEX('Todo-Holiday-Event'!$D$9:$D$258,'Supporting Calendar'!AB14)) | D18: =IF(ISERROR('Supporting Calendar'!AB14),"",INDEX('Todo-Holiday-Event'!$E$9:$E$258,'Supporting Calendar'!AB14)) | E18: =IF(ISERROR('Supporting Calendar'!AC14),"",INDEX('Todo-Holiday-Event'!$D$9:$D$258,'Supporting Calendar'!AC14)) | F18: =IF(ISERROR('Supporting Calendar'!AC14),"",INDEX('Todo-Holiday-Event'!$E$9:$E$258,'Supporting Calendar'!AC14)) | G18: =IF(ISERROR('Supporting Calendar'!AD14),"",INDEX('Todo-Holiday-Event'!$D$9:$D$258,'Supporting Calendar'!AD14)) | H18: =IF(ISERROR('Supporting Calendar'!AD14),"",INDEX('Todo-Holiday-Event'!$E$9:$E$258,'Supporting Calendar'!AD14)) | I18: =IF(ISERROR('Supporting Calendar'!AE14),"",INDEX('Todo-Holiday-Event'!$D$9:$D$258,'Supporting Calendar'!AE14)) | J18: =IF(ISERROR('Supporting Calendar'!AE14),"",INDEX('Todo-Holiday-Event'!$E$9:$E$258,'Supporting Calendar'!AE14)) | K18: =IF(ISERROR('Supporting Calendar'!AF14),"",INDEX('Todo-Holiday-Event'!$D$9:$D$258,'Supporting Calendar'!AF14)) | L18: =IF(ISERROR('Supporting Calendar'!AF14),"",INDEX('Todo-Holiday-Event'!$E$9:$E$258,'Supporting Calendar'!AF14)) | M18: =IF(ISERROR('Supporting Calendar'!AG14),"",INDEX('Todo-Holiday-Event'!$D$9:$D$258,'Supporting Calendar'!AG14)) | N18: =IF(ISERROR('Supporting Calendar'!AG14),"",INDEX('Todo-Holiday-Event'!$E$9:$E$258,'Supporting Calendar'!AG14)) | O18: =IF(ISERROR('Supporting Calendar'!AH14),"",INDEX('Todo-Holiday-Event'!$D$9:$D$258,'Supporting Calendar'!AH14)) | P18: =IF(ISERROR('Supporting Calendar'!AH14),"",INDEX('Todo-Holiday-Event'!$E$9:$E$258,'Supporting Calendar'!AH14))
C19: =IF(ISERROR('Supporting Calendar'!AB15),"",INDEX('Todo-Holiday-Event'!$D$9:$D$258,'Supporting Calendar'!AB15)) | D19: =IF(ISERROR('Supporting Calendar'!AB15),"",INDEX('Todo-Holiday-Event'!$E$9:$E$258,'Supporting Calendar'!AB15)) | E19: =IF(ISERROR('Supporting Calendar'!AC15),"",INDEX('Todo-Holiday-Event'!$D$9:$D$258,'Supporting Calendar'!AC15)) | F19: =IF(ISERROR('Supporting Calendar'!AC15),"",INDEX('Todo-Holiday-Event'!$E$9:$E$258,'Supporting Calendar'!AC15)) | G19: =IF(ISERROR('Supporting Calendar'!AD15),"",INDEX('Todo-Holiday-Event'!$D$9:$D$258,'Supporting Calendar'!AD15)) | H19: =IF(ISERROR('Supporting Calendar'!AD15),"",INDEX('Todo-Holiday-Event'!$E$9:$E$258,'Supporting Calendar'!AD15)) | I19: =IF(ISERROR('Supporting Calendar'!AE15),"",INDEX('Todo-Holiday-Event'!$D$9:$D$258,'Supporting Calendar'!AE15)) | J19: =IF(ISERROR('Supporting Calendar'!AE15),"",INDEX('Todo-Holiday-Event'!$E$9:$E$258,'Supporting Calendar'!AE15)) | K19: =IF(ISERROR('Supporting Calendar'!AF15),"",INDEX('Todo-Holiday-Event'!$D$9:$D$258,'Supporting Calendar'!AF15)) | L19: =IF(ISERROR('Supporting Calendar'!AF15),"",INDEX('Todo-Holiday-Event'!$E$9:$E$258,'Supporting Calendar'!AF15)) | M19: =IF(ISERROR('Supporting Calendar'!AG15),"",INDEX('Todo-Holiday-Event'!$D$9:$D$258,'Supporting Calendar'!AG15)) | N19: =IF(ISERROR('Supporting Calendar'!AG15),"",INDEX('Todo-Holiday-Event'!$E$9:$E$258,'Supporting Calendar'!AG15)) | O19: =IF(ISERROR('Supporting Calendar'!AH15),"",INDEX('Todo-Holiday-Event'!$D$9:$D$258,'Supporting Calendar'!AH15)) | P19: =IF(ISERROR('Supporting Calendar'!AH15),"",INDEX('Todo-Holiday-Event'!$E$9:$E$258,'Supporting Calendar'!AH15))
C20: =IF(ISERROR('Supporting Calendar'!AB16),"",INDEX('Todo-Holiday-Event'!$D$9:$D$258,'Supporting Calendar'!AB16)) | D20: =IF(ISERROR('Supporting Calendar'!AB16),"",INDEX('Todo-Holiday-Event'!$E$9:$E$258,'Supporting Calendar'!AB16)) | E20: =IF(ISERROR('Supporting Calendar'!AC16),"",INDEX('Todo-Holiday-Event'!$D$9:$D$258,'Supporting Calendar'!AC16)) | F20: =IF(ISERROR('Supporting Calendar'!AC16),"",INDEX('Todo-Holiday-Event'!$E$9:$E$258,'Supporting Calendar'!AC16)) | G20: =IF(ISERROR('Supporting Calendar'!AD16),"",INDEX('Todo-Holiday-Event'!$D$9:$D$258,'Supporting Calendar'!AD16)) | H20: =IF(ISERROR('Supporting Calendar'!AD16),"",INDEX('Todo-Holiday-Event'!$E$9:$E$258,'Supporting Calendar'!AD16)) | I20: =IF(ISERROR('Supporting Calendar'!AE16),"",INDEX('Todo-Holiday-Event'!$D$9:$D$258,'Supporting Calendar'!AE16)) | J20: =IF(ISERROR('Supporting Calendar'!AE16),"",INDEX('Todo-Holiday-Event'!$E$9:$E$258,'Supporting Calendar'!AE16)) | K20: =IF(ISERROR('Supporting Calendar'!AF16),"",INDEX('Todo-Holiday-Event'!$D$9:$D$258,'Supporting Calendar'!AF16)) | L20: =IF(ISERROR('Supporting Calendar'!AF16),"",INDEX('Todo-Holiday-Event'!$E$9:$E$258,'Supporting Calendar'!AF16)) | M20: =IF(ISERROR('Supporting Calendar'!AG16),"",INDEX('Todo-Holiday-Event'!$D$9:$D$258,'Supporting Calendar'!AG16)) | N20: =IF(ISERROR('Supporting Calendar'!AG16),"",INDEX('Todo-Holiday-Event'!$E$9:$E$258,'Supporting Calendar'!AG16)) | O20: =IF(ISERROR('Supporting Calendar'!AH16),"",INDEX('Todo-Holiday-Event'!$D$9:$D$258,'Supporting Calendar'!AH16)) | P20: =IF(ISERROR('Supporting Calendar'!AH16),"",INDEX('Todo-Holiday-Event'!$E$9:$E$258,'Supporting Calendar'!AH16))
C21: =O16+1 -> 18 | D21: =IF(C21<>"",IF(ISNA(VLOOKUP(DATE($M$31,$O$31,C21),'Todo-Holiday-Event'!$L$9:$M$28,2,FALSE)),IF(ISNA(VLOOKUP(DATE($M$31,$O$31,C21),'Todo-Holiday-Event'!$H$9:$I$28,2,FALSE)),"",VLOOKUP(DATE($M$31,$O$31,C21),'Todo-Holiday-Event'!$H$9:$I$28,2,FALSE)),VLOOKUP(DATE($M$31,$O$31,C21),'Todo-Holiday-Event'!$L$9:$M$28,2,FALSE)),"") | E21: =C21+1 -> 19 | F21: =IF(E21<>"",IF(ISNA(VLOOKUP(DATE($M$31,$O$31,E21),'Todo-Holiday-Event'!$L$9:$M$28,2,FALSE)),IF(ISNA(VLOOKUP(DATE($M$31,$O$31,E21),'Todo-Holiday-Event'!$H$9:$I$28,2,FALSE)),"",VLOOKUP(DATE($M$31,$O$31,E21),'Todo-Holiday-Event'!$H$9:$I$28,2,FALSE)),VLOOKUP(DATE($M$31,$O$31,E21),'Todo-Holiday-Event'!$L$9:$M$28,2,FALSE)),"") | G21: =E21+1 -> 20 | H21: =IF(G21<>"",IF(ISNA(VLOOKUP(DATE($M$31,$O$31,G21),'Todo-Holiday-Event'!$L$9:$M$28,2,FALSE)),IF(ISNA(VLOOKUP(DATE($M$31,$O$31,G21),'Todo-Holiday-Event'!$H$9:$I$28,2,FALSE)),"",VLOOKUP(DATE($M$31,$O$31,G21),'Todo-Holiday-Event'!$H$9:$I$28,2,FALSE)),VLOOKUP(DATE($M$31,$O$31,G21),'Todo-Holiday-Event'!$L$9:$M$28,2,FALSE)),"") | I21: =G21+1 -> 21 | J21: =IF(I21<>"",IF(ISNA(VLOOKUP(DATE($M$31,$O$31,I21),'Todo-Holiday-Event'!$L$9:$M$28,2,FALSE)),IF(ISNA(VLOOKUP(DATE($M$31,$O$31,I21),'Todo-Holiday-Event'!$H$9:$I$28,2,FALSE)),"",VLOOKUP(DATE($M$31,$O$31,I21),'Todo-Holiday-Event'!$H$9:$I$28,2,FALSE)),VLOOKUP(DATE($M$31,$O$31,I21),'Todo-Holiday-Event'!$L$9:$M$28,2,FALSE)),"") | K21: =I21+1 -> 22 | L21: =IF(K21<>"",IF(ISNA(VLOOKUP(DATE($M$31,$O$31,K21),'Todo-Holiday-Event'!$L$9:$M$28,2,FALSE)),IF(ISNA(VLOOKUP(DATE($M$31,$O$31,K21),'Todo-Holiday-Event'!$H$9:$I$28,2,FALSE)),"",VLOOKUP(DATE($M$31,$O$31,K21),'Todo-Holiday-Event'!$H$9:$I$28,2,FALSE)),VLOOKUP(DATE($M$31,$O$31,K21),'Todo-Holiday-Event'!$L$9:$M$28,2,FALSE)),"") | M21: =K21+1 -> 23 | N21: =IF(M21<>"",IF(ISNA(VLOOKUP(DATE($M$31,$O$31,M21),'Todo-Holiday-Event'!$L$9:$M$28,2,FALSE)),IF(ISNA(VLOOKUP(DATE($M$31,$O$31,M21),'Todo-Holiday-Event'!$H$9:$I$28,2,FALSE)),"",VLOOKUP(DATE($M$31,$O$31,M21),'Todo-Holiday-Event'!$H$9:$I$28,2,FALSE)),VLOOKUP(DATE($M$31,$O$31,M21),'Todo-Holiday-Event'!$L$9:$M$28,2,FALSE)),"") | O21: =M21+1 -> 24 | P21: =IF(O21<>"",IF(ISNA(VLOOKUP(DATE($M$31,$O$31,O21),'Todo-Holiday-Event'!$L$9:$M$28,2,FALSE)),IF(ISNA(VLOOKUP(DATE($M$31,$O$31,O21),'Todo-Holiday-Event'!$H$9:$I$28,2,FALSE)),"",VLOOKUP(DATE($M$31,$O$31,O21),'Todo-Holiday-Event'!$H$9:$I$28,2,FALSE)),VLOOKUP(DATE($M$31,$O$31,O21),'Todo-Holiday-Event'!$L$9:$M$28,2,FALSE)),"")
C22: =IF(ISERROR('Supporting Calendar'!AB19),"",INDEX('Todo-Holiday-Event'!$D$9:$D$258,'Supporting Calendar'!AB19)) -> 0.70833333 | D22: =IF(ISERROR('Supporting Calendar'!AB19),"",INDEX('Todo-Holiday-Event'!$E$9:$E$258,'Supporting Calendar'!AB19)) -> Shopping | E22: =IF(ISERROR('Supporting Calendar'!AC19),"",INDEX('Todo-Holiday-Event'!$D$9:$D$258,'Supporting Calendar'!AC19)) | F22: =IF(ISERROR('Supporting Calendar'!AC19),"",INDEX('Todo-Holiday-Event'!$E$9:$E$258,'Supporting Calendar'!AC19)) | G22: =IF(ISERROR('Supporting Calendar'!AD19),"",INDEX('Todo-Holiday-Event'!$D$9:$D$258,'Supporting Calendar'!AD19)) | H22: =IF(ISERROR('Supporting Calendar'!AD19),"",INDEX('Todo-Holiday-Event'!$E$9:$E$258,'Supporting Calendar'!AD19)) | I22: =IF(ISERROR('Supporting Calendar'!AE19),"",INDEX('Todo-Holiday-Event'!$D$9:$D$258,'Supporting Calendar'!AE19)) | J22: =IF(ISERROR('Supporting Calendar'!AE19),"",INDEX('Todo-Holiday-Event'!$E$9:$E$258,'Supporting Calendar'!AE19)) | K22: =IF(ISERROR('Supporting Calendar'!AF19),"",INDEX('Todo-Holiday-Event'!$D$9:$D$258,'Supporting Calendar'!AF19)) | L22: =IF(ISERROR('Supporting Calendar'!AF19),"",INDEX('Todo-Holiday-Event'!$E$9:$E$258,'Supporting Calendar'!AF19)) | M22: =IF(ISERROR('Supporting Calendar'!AG19),"",INDEX('Todo-Holiday-Event'!$D$9:$D$258,'Supporting Calendar'!AG19)) | N22: =IF(ISERROR('Supporting Calendar'!AG19),"",INDEX('Todo-Holiday-Event'!$E$9:$E$258,'Supporting Calendar'!AG19)) | O22: =IF(ISERROR('Supporting Calendar'!AH19),"",INDEX('Todo-Holiday-Event'!$D$9:$D$258,'Supporting Calendar'!AH19)) | P22: =IF(ISERROR('Supporting Calendar'!AH19),"",INDEX('Todo-Holiday-Event'!$E$9:$E$258,'Supporting Calendar'!AH19))
C23: =IF(ISERROR('Supporting Calendar'!AB20),"",INDEX('Todo-Holiday-Event'!$D$9:$D$258,'Supporting Calendar'!AB20)) | D23: =IF(ISERROR('Supporting Calendar'!AB20),"",INDEX('Todo-Holiday-Event'!$E$9:$E$258,'Supporting Calendar'!AB20)) | E23: =IF(ISERROR('Supporting Calendar'!AC20),"",INDEX('Todo-Holiday-Event'!$D$9:$D$258,'Supporting Calendar'!AC20)) | F23: =IF(ISERROR('Supporting Calendar'!AC20),"",INDEX('Todo-Holiday-Event'!$E$9:$E$258,'Supporting Calendar'!AC20)) | G23: =IF(ISERROR('Supporting Calendar'!AD20),"",INDEX('Todo-Holiday-Event'!$D$9:$D$258,'Supporting Calendar'!AD20)) | H23: =IF(ISERROR('Supporting Calendar'!AD20),"",INDEX('Todo-Holiday-Event'!$E$9:$E$258,'Supporting Calendar'!AD20)) | I23: =IF(ISERROR('Supporting Calendar'!AE20),"",INDEX('Todo-Holiday-Event'!$D$9:$D$258,'Supporting Calendar'!AE20)) | J23: =IF(ISERROR('Supporting Calendar'!AE20),"",INDEX('Todo-Holiday-Event'!$E$9:$E$258,'Supporting Calendar'!AE20)) | K23: =IF(ISERROR('Supporting Calendar'!AF20),"",INDEX('Todo-Holiday-Event'!$D$9:$D$258,'Supporting Calendar'!AF20)) | L23: =IF(ISERROR('Supporting Calendar'!AF20),"",INDEX('Todo-Holiday-Event'!$E$9:$E$258,'Supporting Calendar'!AF20)) | M23: =IF(ISERROR('Supporting Calendar'!AG20),"",INDEX('Todo-Holiday-Event'!$D$9:$D$258,'Supporting Calendar'!AG20)) | N23: =IF(ISERROR('Supporting Calendar'!AG20),"",INDEX('Todo-Holiday-Event'!$E$9:$E$258,'Supporting Calendar'!AG20)) | O23: =IF(ISERROR('Supporting Calendar'!AH20),"",INDEX('Todo-Holiday-Event'!$D$9:$D$258,'Supporting Calendar'!AH20)) | P23: =IF(ISERROR('Supporting Calendar'!AH20),"",INDEX('Todo-Holiday-Event'!$E$9:$E$258,'Supporting Calendar'!AH20))
C24: =IF(ISERROR('Supporting Calendar'!AB21),"",INDEX('Todo-Holiday-Event'!$D$9:$D$258,'Supporting Calendar'!AB21)) | D24: =IF(ISERROR('Supporting Calendar'!AB21),"",INDEX('Todo-Holiday-Event'!$E$9:$E$258,'Supporting Calendar'!AB21)) | E24: =IF(ISERROR('Supporting Calendar'!AC21),"",INDEX('Todo-Holiday-Event'!$D$9:$D$258,'Supporting Calendar'!AC21)) | F24: =IF(ISERROR('Supporting Calendar'!AC21),"",INDEX('Todo-Holiday-Event'!$E$9:$E$258,'Supporting Calendar'!AC21)) | G24: =IF(ISERROR('Supporting Calendar'!AD21),"",INDEX('Todo-Holiday-Event'!$D$9:$D$258,'Supporting Calendar'!AD21)) | H24: =IF(ISERROR('Supporting Calendar'!AD21),"",INDEX('Todo-Holiday-Event'!$E$9:$E$258,'Supporting Calendar'!AD21)) | I24: =IF(ISERROR('Supporting Calendar'!AE21),"",INDEX('Todo-Holiday-Event'!$D$9:$D$258,'Supporting Calendar'!AE21)) | J24: =IF(ISERROR('Supporting Calendar'!AE21),"",INDEX('Todo-Holiday-Event'!$E$9:$E$258,'Supporting Calendar'!AE21)) | K24: =IF(ISERROR('Supporting Calendar'!AF21),"",INDEX('Todo-Holiday-Event'!$D$9:$D$258,'Supporting Calendar'!AF21)) | L24: =IF(ISERROR('Supporting Calendar'!AF21),"",INDEX('Todo-Holiday-Event'!$E$9:$E$258,'Supporting Calendar'!AF21)) | M24: =IF(ISERROR('Supporting Calendar'!AG21),"",INDEX('Todo-Holiday-Event'!$D$9:$D$258,'Supporting Calendar'!AG21)) | N24: =IF(ISERROR('Supporting Calendar'!AG21),"",INDEX('Todo-Holiday-Event'!$E$9:$E$258,'Supporting Calendar'!AG21)) | O24: =IF(ISERROR('Supporting Calendar'!AH21),"",INDEX('Todo-Holiday-Event'!$D$9:$D$258,'Supporting Calendar'!AH21)) | P24: =IF(ISERROR('Supporting Calendar'!AH21),"",INDEX('Todo-Holiday-Event'!$E$9:$E$258,'Supporting Calendar'!AH21))
C25: =IF(ISERROR('Supporting Calendar'!AB22),"",INDEX('Todo-Holiday-Event'!$D$9:$D$258,'Supporting Calendar'!AB22)) | D25: =IF(ISERROR('Supporting Calendar'!AB22),"",INDEX('Todo-Holiday-Event'!$E$9:$E$258,'Supporting Calendar'!AB22)) | E25: =IF(ISERROR('Supporting Calendar'!AC22),"",INDEX('Todo-Holiday-Event'!$D$9:$D$258,'Supporting Calendar'!AC22)) | F25: =IF(ISERROR('Supporting Calendar'!AC22),"",INDEX('Todo-Holiday-Event'!$E$9:$E$258,'Supporting Calendar'!AC22)) | G25: =IF(ISERROR('Supporting Calendar'!AD22),"",INDEX('Todo-Holiday-Event'!$D$9:$D$258,'Supporting Calendar'!AD22)) | H25: =IF(ISERROR('Supporting Calendar'!AD22),"",INDEX('Todo-Holiday-Event'!$E$9:$E$258,'Supporting Calendar'!AD22)) | I25: =IF(ISERROR('Supporting Calendar'!AE22),"",INDEX('Todo-Holiday-Event'!$D$9:$D$258,'Supporting Calendar'!AE22)) | J25: =IF(ISERROR('Supporting Calendar'!AE22),"",INDEX('Todo-Holiday-Event'!$E$9:$E$258,'Supporting Calendar'!AE22)) | K25: =IF(ISERROR('Supporting Calendar'!AF22),"",INDEX('Todo-Holiday-Event'!$D$9:$D$258,'Supporting Calendar'!AF22)) | L25: =IF(ISERROR('Supporting Calendar'!AF22),"",INDEX('Todo-Holiday-Event'!$E$9:$E$258,'Supporting Calendar'!AF22)) | M25: =IF(ISERROR('Supporting Calendar'!AG22),"",INDEX('Todo-Holiday-Event'!$D$9:$D$258,'Supporting Calendar'!AG22)) | N25: =IF(ISERROR('Supporting Calendar'!AG22),"",INDEX('Todo-Holiday-Event'!$E$9:$E$258,'Supporting Calendar'!AG22)) | O25: =IF(ISERROR('Supporting Calendar'!AH22),"",INDEX('Todo-Holiday-Event'!$D$9:$D$258,'Supporting Calendar'!AH22)) | P25: =IF(ISERROR('Supporting Calendar'!AH22),"",INDEX('Todo-Holiday-Event'!$E$9:$E$258,'Supporting Calendar'!AH22))
C26: =IF(O21<>"",IF(DAY(EOMONTH(DATE($M$31,$O$31,1),0))=O21,"",O21+1),"") -> 25 | D26: =IF(C26<>"",IF(ISNA(VLOOKUP(DATE($M$31,$O$31,C26),'Todo-Holiday-Event'!$L$9:$M$28,2,FALSE)),IF(ISNA(VLOOKUP(DATE($M$31,$O$31,C26),'Todo-Holiday-Event'!$H$9:$I$28,2,FALSE)),"",VLOOKUP(DATE($M$31,$O$31,C26),'Todo-Holiday-Event'!$H$9:$I$28,2,FALSE)),VLOOKUP(DATE($M$31,$O$31,C26),'Todo-Holiday-Event'!$L$9:$M$28,2,FALSE)),"") | E26: =IF(C26<>"",IF(DAY(EOMONTH(DATE($M$31,$O$31,1),0))=C26,"",C26+1),"") -> 26 | F26: =IF(E26<>"",IF(ISNA(VLOOKUP(DATE($M$31,$O$31,E26),'Todo-Holiday-Event'!$L$9:$M$28,2,FALSE)),IF(ISNA(VLOOKUP(DATE($M$31,$O$31,E26),'Todo-Holiday-Event'!$H$9:$I$28,2,FALSE)),"",VLOOKUP(DATE($M$31,$O$31,E26),'Todo-Holiday-Event'!$H$9:$I$28,2,FALSE)),VLOOKUP(DATE($M$31,$O$31,E26),'Todo-Holiday-Event'!$L$9:$M$28,2,FALSE)),"") | G26: =IF(E26<>"",IF(DAY(EOMONTH(DATE($M$31,$O$31,1),0))=E26,"",E26+1),"") -> 27 | H26: =IF(G26<>"",IF(ISNA(VLOOKUP(DATE($M$31,$O$31,G26),'Todo-Holiday-Event'!$L$9:$M$28,2,FALSE)),IF(ISNA(VLOOKUP(DATE($M$31,$O$31,G26),'Todo-Holiday-Event'!$H$9:$I$28,2,FALSE)),"",VLOOKUP(DATE($M$31,$O$31,G26),'Todo-Holiday-Event'!$H$9:$I$28,2,FALSE)),VLOOKUP(DATE($M$31,$O$31,G26),'Todo-Holiday-Event'!$L$9:$M$28,2,FALSE)),"") | I26: =IF(G26<>"",IF(DAY(EOMONTH(DATE($M$31,$O$31,1),0))=G26,"",G26+1),"") -> 28 | J26: =IF(I26<>"",IF(ISNA(VLOOKUP(DATE($M$31,$O$31,I26),'Todo-Holiday-Event'!$L$9:$M$28,2,FALSE)),IF(ISNA(VLOOKUP(DATE($M$31,$O$31,I26),'Todo-Holiday-Event'!$H$9:$I$28,2,FALSE)),"",VLOOKUP(DATE($M$31,$O$31,I26),'Todo-Holiday-Event'!$H$9:$I$28,2,FALSE)),VLOOKUP(DATE($M$31,$O$31,I26),'Todo-Holiday-Event'!$L$9:$M$28,2,FALSE)),"") | K26: =IF(I26<>"",IF(DAY(EOMONTH(DATE($M$31,$O$31,1),0))=I26,"",I26+1),"") -> 29 | L26: =IF(K26<>"",IF(ISNA(VLOOKUP(DATE($M$31,$O$31,K26),'Todo-Holiday-Event'!$L$9:$M$28,2,FALSE)),IF(ISNA(VLOOKUP(DATE($M$31,$O$31,K26),'Todo-Holiday-Event'!$H$9:$I$28,2,FALSE)),"",VLOOKUP(DATE($M$31,$O$31,K26),'Todo-Holiday-Event'!$H$9:$I$28,2,FALSE)),VLOOKUP(DATE($M$31,$O$31,K26),'Todo-Holiday-Event'!$L$9:$M$28,2,FALSE)),"") | M26: =IF(K26<>"",IF(DAY(EOMONTH(DATE($M$31,$O$31,1),0))=K26,"",K26+1),"") -> 30 | N26: =IF(M26<>"",IF(ISNA(VLOOKUP(DATE($M$31,$O$31,M26),'Todo-Holiday-Event'!$L$9:$M$28,2,FALSE)),IF(ISNA(VLOOKUP(DATE($M$31,$O$31,M26),'Todo-Holiday-Event'!$H$9:$I$28,2,FALSE)),"",VLOOKUP(DATE($M$31,$O$31,M26),'Todo-Holiday-Event'!$H$9:$I$28,2,FALSE)),VLOOKUP(DATE($M$31,$O$31,M26),'Todo-Holiday-Event'!$L$9:$M$28,2,FALSE)),"") | O26: =IF(M26<>"",IF(DAY(EOMONTH(DATE($M$31,$O$31,1),0))=M26,"",M26+1),"") -> 31 | P26: =IF(O26<>"",IF(ISNA(VLOOKUP(DATE($M$31,$O$31,O26),'Todo-Holiday-Event'!$L$9:$M$28,2,FALSE)),IF(ISNA(VLOOKUP(DATE($M$31,$O$31,O26),'Todo-Holiday-Event'!$H$9:$I$28,2,FALSE)),"",VLOOKUP(DATE($M$31,$O$31,O26),'Todo-Holiday-Event'!$H$9:$I$28,2,FALSE)),VLOOKUP(DATE($M$31,$O$31,O26),'Todo-Holiday-Event'!$L$9:$M$28,2,FALSE)),"")
C27: =IF(ISERROR('Supporting Calendar'!AB25),"",INDEX('Todo-Holiday-Event'!$D$9:$D$258,'Supporting Calendar'!AB25)) | D27: =IF(ISERROR('Supporting Calendar'!AB25),"",INDEX('Todo-Holiday-Event'!$E$9:$E$258,'Supporting Calendar'!AB25)) | E27: =IF(ISERROR('Supporting Calendar'!AC25),"",INDEX('Todo-Holiday-Event'!$D$9:$D$258,'Supporting Calendar'!AC25)) | F27: =IF(ISERROR('Supporting Calendar'!AC25),"",INDEX('Todo-Holiday-Event'!$E$9:$E$258,'Supporting Calendar'!AC25)) | G27: =IF(ISERROR('Supporting Calendar'!AD25),"",INDEX('Todo-Holiday-Event'!$D$9:$D$258,'Supporting Calendar'!AD25)) | H27: =IF(ISERROR('Supporting Calendar'!AD25),"",INDEX('Todo-Holiday-Event'!$E$9:$E$258,'Supporting Calendar'!AD25)) | I27: =IF(ISERROR('Supporting Calendar'!AE25),"",INDEX('Todo-Holiday-Event'!$D$9:$D$258,'Supporting Calendar'!AE25)) | J27: =IF(ISERROR('Supporting Calendar'!AE25),"",INDEX('Todo-Holiday-Event'!$E$9:$E$258,'Supporting Calendar'!AE25)) | K27: =IF(ISERROR('Supporting Calendar'!AF25),"",INDEX('Todo-Holiday-Event'!$D$9:$D$258,'Supporting Calendar'!AF25)) | L27: =IF(ISERROR('Supporting Calendar'!AF25),"",INDEX('Todo-Holiday-Event'!$E$9:$E$258,'Supporting Calendar'!AF25)) | M27: =IF(ISERROR('Supporting Calendar'!AG25),"",INDEX('Todo-Holiday-Event'!$D$9:$D$258,'Supporting Calendar'!AG25)) | N27: =IF(ISERROR('Supporting Calendar'!AG25),"",INDEX('Todo-Holiday-Event'!$E$9:$E$258,'Supporting Calendar'!AG25)) | O27: =IF(ISERROR('Supporting Calendar'!AH25),"",INDEX('Todo-Holiday-Event'!$D$9:$D$258,'Supporting Calendar'!AH25)) | P27: =IF(ISERROR('Supporting Calendar'!AH25),"",INDEX('Todo-Holiday-Event'!$E$9:$E$258,'Supporting Calendar'!AH25))
C28: =IF(ISERROR('Supporting Calendar'!AB26),"",INDEX('Todo-Holiday-Event'!$D$9:$D$258,'Supporting Calendar'!AB26)) | D28: =IF(ISERROR('Supporting Calendar'!AB26),"",INDEX('Todo-Holiday-Event'!$E$9:$E$258,'Supporting Calendar'!AB26)) | E28: =IF(ISERROR('Supporting Calendar'!AC26),"",INDEX('Todo-Holiday-Event'!$D$9:$D$258,'Supporting Calendar'!AC26)) | F28: =IF(ISERROR('Supporting Calendar'!AC26),"",INDEX('Todo-Holiday-Event'!$E$9:$E$258,'Supporting Calendar'!AC26)) | G28: =IF(ISERROR('Supporting Calendar'!AD26),"",INDEX('Todo-Holiday-Event'!$D$9:$D$258,'Supporting Calendar'!AD26)) | H28: =IF(ISERROR('Supporting Calendar'!AD26),"",INDEX('Todo-Holiday-Event'!$E$9:$E$258,'Supporting Calendar'!AD26)) | I28: =IF(ISERROR('Supporting Calendar'!AE26),"",INDEX('Todo-Holiday-Event'!$D$9:$D$258,'Supporting Calendar'!AE26)) | J28: =IF(ISERROR('Supporting Calendar'!AE26),"",INDEX('Todo-Holiday-Event'!$E$9:$E$258,'Supporting Calendar'!AE26)) | K28: =IF(ISERROR('Supporting Calendar'!AF26),"",INDEX('Todo-Holiday-Event'!$D$9:$D$258,'Supporting Calendar'!AF26)) | L28: =IF(ISERROR('Supporting Calendar'!AF26),"",INDEX('Todo-Holiday-Event'!$E$9:$E$258,'Supporting Calendar'!AF26)) | M28: =IF(ISERROR('Supporting Calendar'!AG26),"",INDEX('Todo-Holiday-Event'!$D$9:$D$258,'Supporting Calendar'!AG26)) | N28: =IF(ISERROR('Supporting Calendar'!AG26),"",INDEX('Todo-Holiday-Event'!$E$9:$E$258,'Supporting Calendar'!AG26)) | O28: =IF(ISERROR('Supporting Calendar'!AH26),"",INDEX('Todo-Holiday-Event'!$D$9:$D$258,'Supporting Calendar'!AH26)) | P28: =IF(ISERROR('Supporting Calendar'!AH26),"",INDEX('Todo-Holiday-Event'!$E$9:$E$258,'Supporting Calendar'!AH26))
C29: =IF(ISERROR('Supporting Calendar'!AB27),"",INDEX('Todo-Holiday-Event'!$D$9:$D$258,'Supporting Calendar'!AB27)) | D29: =IF(ISERROR('Supporting Calendar'!AB27),"",INDEX('Todo-Holiday-Event'!$E$9:$E$258,'Supporting Calendar'!AB27)) | E29: =IF(ISERROR('Supporting Calendar'!AC27),"",INDEX('Todo-Holiday-Event'!$D$9:$D$258,'Supporting Calendar'!AC27)) | F29: =IF(ISERROR('Supporting Calendar'!AC27),"",INDEX('Todo-Holiday-Event'!$E$9:$E$258,'Supporting Calendar'!AC27)) | G29: =IF(ISERROR('Supporting Calendar'!AD27),"",INDEX('Todo-Holiday-Event'!$D$9:$D$258,'Supporting Calendar'!AD27)) | H29: =IF(ISERROR('Supporting Calendar'!AD27),"",INDEX('Todo-Holiday-Event'!$E$9:$E$258,'Supporting Calendar'!AD27)) | I29: =IF(ISERROR('Supporting Calendar'!AE27),"",INDEX('Todo-Holiday-Event'!$D$9:$D$258,'Supporting Calendar'!AE27)) | J29: =IF(ISERROR('Supporting Calendar'!AE27),"",INDEX('Todo-Holiday-Event'!$E$9:$E$258,'Supporting Calendar'!AE27)) | K29: =IF(ISERROR('Supporting Calendar'!AF27),"",INDEX('Todo-Holiday-Event'!$D$9:$D$258,'Supporting Calendar'!AF27)) | L29: =IF(ISERROR('Supporting Calendar'!AF27),"",INDEX('Todo-Holiday-Event'!$E$9:$E$258,'Supporting Calendar'!AF27)) | M29: =IF(ISERROR('Supporting Calendar'!AG27),"",INDEX('Todo-Holiday-Event'!$D$9:$D$258,'Supporting Calendar'!AG27)) | N29: =IF(ISERROR('Supporting Calendar'!AG27),"",INDEX('Todo-Holiday-Event'!$E$9:$E$258,'Supporting Calendar'!AG27)) | O29: =IF(ISERROR('Supporting Calendar'!AH27),"",INDEX('Todo-Holiday-Event'!$D$9:$D$258,'Supporting Calendar'!AH27)) | P29: =IF(ISERROR('Supporting Calendar'!AH27),"",INDEX('Todo-Holiday-Event'!$E$9:$E$258,'Supporting Calendar'!AH27))
C30: =IF(ISERROR('Supporting Calendar'!AB28),"",INDEX('Todo-Holiday-Event'!$D$9:$D$258,'Supporting Calendar'!AB28)) | D30: =IF(ISERROR('Supporting Calendar'!AB28),"",INDEX('Todo-Holiday-Event'!$E$9:$E$258,'Supporting Calendar'!AB28)) | E30: =IF(ISERROR('Supporting Calendar'!AC28),"",INDEX('Todo-Holiday-Event'!$D$9:$D$258,'Supporting Calendar'!AC28)) | F30: =IF(ISERROR('Supporting Calendar'!AC28),"",INDEX('Todo-Holiday-Event'!$E$9:$E$258,'Supporting Calendar'!AC28)) | G30: =IF(ISERROR('Supporting Calendar'!AD28),"",INDEX('Todo-Holiday-Event'!$D$9:$D$258,'Supporting Calendar'!AD28)) | H30: =IF(ISERROR('Supporting Calendar'!AD28),"",INDEX('Todo-Holiday-Event'!$E$9:$E$258,'Supporting Calendar'!AD28)) | I30: =IF(ISERROR('Supporting Calendar'!AE28),"",INDEX('Todo-Holiday-Event'!$D$9:$D$258,'Supporting Calendar'!AE28)) | J30: =IF(ISERROR('Supporting Calendar'!AE28),"",INDEX('Todo-Holiday-Event'!$E$9:$E$258,'Supporting Calendar'!AE28)) | K30: =IF(ISERROR('Supporting Calendar'!AF28),"",INDEX('Todo-Holiday-Event'!$D$9:$D$258,'Supporting Calendar'!AF28)) | L30: =IF(ISERROR('Supporting Calendar'!AF28),"",INDEX('Todo-Holiday-Event'!$E$9:$E$258,'Supporting Calendar'!AF28)) | M30: =IF(ISERROR('Supporting Calendar'!AG28),"",INDEX('Todo-Holiday-Event'!$D$9:$D$258,'Supporting Calendar'!AG28)) | N30: =IF(ISERROR('Supporting Calendar'!AG28),"",INDEX('Todo-Holiday-Event'!$E$9:$E$258,'Supporting Calendar'!AG28)) | O30: =IF(ISERROR('Supporting Calendar'!AH28),"",INDEX('Todo-Holiday-Event'!$D$9:$D$258,'Supporting Calendar'!AH28)) | P30: =IF(ISERROR('Supporting Calendar'!AH28),"",INDEX('Todo-Holiday-Event'!$E$9:$E$258,'Supporting Calendar'!AH28))
C31: =IF(O26<>"",IF(DAY(EOMONTH(DATE($M$31,$O$31,1),0))=O26,"",O26+1),"") | D31: =IF(C31<>"",IF(ISNA(VLOOKUP(DATE($M$31,$O$31,C31),'Todo-Holiday-Event'!$L$9:$M$28,2,FALSE)),IF(ISNA(VLOOKUP(DATE($M$31,$O$31,C31),'Todo-Holiday-Event'!$H$9:$I$28,2,FALSE)),"",VLOOKUP(DATE($M$31,$O$31,C31),'Todo-Holiday-Event'!$H$9:$I$28,2,FALSE)),VLOOKUP(DATE($M$31,$O$31,C31),'Todo-Holiday-Event'!$L$9:$M$28,2,FALSE)),"") | E31: =IF(C31<>"",IF(DAY(EOMONTH(DATE($M$31,$O$31,1),0))=C31,"",C31+1),"") | F31: =IF(E31<>"",IF(ISNA(VLOOKUP(DATE($M$31,$O$31,E31),'Todo-Holiday-Event'!$L$9:$M$28,2,FALSE)),IF(ISNA(VLOOKUP(DATE($M$31,$O$31,E31),'Todo-Holiday-Event'!$H$9:$I$28,2,FALSE)),"",VLOOKUP(DATE($M$31,$O$31,E31),'Todo-Holiday-Event'!$H$9:$I$28,2,FALSE)),VLOOKUP(DATE($M$31,$O$31,E31),'Todo-Holiday-Event'!$L$9:$M$28,2,FALSE)),"") | G31: Notes : | M31: =IF(O33+O32>24,M33+2,IF(O33+O32>12,M33+1,M33)) -> 2019 | O31: =IF(O33+O32>24,O33+O32-24,IF(O33+O32>12,O33+O32-12,O33+O32)) -> 8
C32: =IF(ISERROR('Supporting Calendar'!AB31),"",INDEX('Todo-Holiday-Event'!$D$9:$D$258,'Supporting Calendar'!AB31)) | D32: =IF(ISERROR('Supporting Calendar'!AB31),"",INDEX('Todo-Holiday-Event'!$E$9:$E$258,'Supporting Calendar'!AB31)) | E32: =IF(ISERROR('Supporting Calendar'!AC31),"",INDEX('Todo-Holiday-Event'!$D$9:$D$258,'Supporting Calendar'!AC31)) | F32: =IF(ISERROR('Supporting Calendar'!AC31),"",INDEX('Todo-Holiday-Event'!$E$9:$E$258,'Supporting Calendar'!AC31)) | O32: 6
C33: =IF(ISERROR('Supporting Calendar'!AB32),"",INDEX('Todo-Holiday-Event'!$D$9:$D$258,'Supporting Calendar'!AB32)) | D33: =IF(ISERROR('Supporting Calendar'!AB32),"",INDEX('Todo-Holiday-Event'!$E$9:$E$258,'Supporting Calendar'!AB32)) | E33: =IF(ISERROR('Supporting Calendar'!AC32),"",INDEX('Todo-Holiday-Event'!$D$9:$D$258,'Supporting Calendar'!AC32)) | F33: =IF(ISERROR('Supporting Calendar'!AC32),"",INDEX('Todo-Holiday-Event'!$E$9:$E$258,'Supporting Calendar'!AC32)) | M33: ='Todo-Holiday-Event'!E6 -> 2019 | O33: =INDEX(MonthRef,MATCH(StartMonth,Months,0),0) -> 2
C34: =IF(ISERROR('Supporting Calendar'!AB33),"",INDEX('Todo-Holiday-Event'!$D$9:$D$258,'Supporting Calendar'!AB33)) | D34: =IF(ISERROR('Supporting Calendar'!AB33),"",INDEX('Todo-Holiday-Event'!$E$9:$E$258,'Supporting Calendar'!AB33)) | E34: =IF(ISERROR('Supporting Calendar'!AC33),"",INDEX('Todo-Holiday-Event'!$D$9:$D$258,'Supporting Calendar'!AC33)) | F34: =IF(ISERROR('Supporting Calendar'!AC33),"",INDEX('Todo-Holiday-Event'!$E$9:$E$258,'Supporting Calendar'!AC33))
C35: =IF(ISERROR('Supporting Calendar'!AB34),"",INDEX('Todo-Holiday-Event'!$D$9:$D$258,'Supporting Calendar'!AB34)) | D35: =IF(ISERROR('Supporting Calendar'!AB34),"",INDEX('Todo-Holiday-Event'!$E$9:$E$258,'Supporting Calendar'!AB34)) | E35: =IF(ISERROR('Supporting Calendar'!AC34),"",INDEX('Todo-Holiday-Event'!$D$9:$D$258,'Supporting Calendar'!AC34)) | F35: =IF(ISERROR('Supporting Calendar'!AC34),"",INDEX('Todo-Holiday-Event'!$E$9:$E$258,'Supporting Calendar'!AC34))
C36: © 2021 - ExcelTemplate.net

Sheet Layout 2
A2: ='Layout 1'!A2:P3 -> AUGUST YYYY
C5: SUNDAY | E5: MONDAY | G5: TUESDAY | I5: WEDNESDAY | K5: THURSDAY | M5: FRIDAY | O5: SATURDAY
C6: =IF(WEEKDAY(DATE($M$31,$O$31,1))=1,1,"") | D6: =IF(C6<>"",IF(ISNA(VLOOKUP(DATE($M$31,$O$31,C6),'Todo-Holiday-Event'!$L$9:$M$28,2,FALSE)),IF(ISNA(VLOOKUP(DATE($M$31,$O$31,C6),'Todo-Holiday-Event'!$H$9:$I$28,2,FALSE)),"",VLOOKUP(DATE($M$31,$O$31,C6),'Todo-Holiday-Event'!$H$9:$I$28,2,FALSE)),VLOOKUP(DATE($M$31,$O$31,C6),'Todo-Holiday-Event'!$L$9:$M$28,2,FALSE)),"") | E6: =IF(C6<>"",C6+1,IF(WEEKDAY(DATE($M$31,$O$31,1))=2,1,"")) | F6: =IF(E6<>"",IF(ISNA(VLOOKUP(DATE($M$31,$O$31,E6),'Todo-Holiday-Event'!$L$9:$M$28,2,FALSE)),IF(ISNA(VLOOKUP(DATE($M$31,$O$31,E6),'Todo-Holiday-Event'!$H$9:$I$28,2,FALSE)),"",VLOOKUP(DATE($M$31,$O$31,E6),'Todo-Holiday-Event'!$H$9:$I$28,2,FALSE)),VLOOKUP(DATE($M$31,$O$31,E6),'Todo-Holiday-Event'!$L$9:$M$28,2,FALSE)),"") | G6: =IF(E6<>"",E6+1,IF(WEEKDAY(DATE($M$31,$O$31,1))=3,1,"")) | H6: =IF(G6<>"",IF(ISNA(VLOOKUP(DATE($M$31,$O$31,G6),'Todo-Holiday-Event'!$L$9:$M$28,2,FALSE)),IF(ISNA(VLOOKUP(DATE($M$31,$O$31,G6),'Todo-Holiday-Event'!$H$9:$I$28,2,FALSE)),"",VLOOKUP(DATE($M$31,$O$31,G6),'Todo-Holiday-Event'!$H$9:$I$28,2,FALSE)),VLOOKUP(DATE($M$31,$O$31,G6),'Todo-Holiday-Event'!$L$9:$M$28,2,FALSE)),"") | I6: =IF(G6<>"",G6+1,IF(WEEKDAY(DATE($M$31,$O$31,1))=4,1,"")) | J6: =IF(I6<>"",IF(ISNA(VLOOKUP(DATE($M$31,$O$31,I6),'Todo-Holiday-Event'!$L$9:$M$28,2,FALSE)),IF(ISNA(VLOOKUP(DATE($M$31,$O$31,I6),'Todo-Holiday-Event'!$H$9:$I$28,2,FALSE)),"",VLOOKUP(DATE($M$31,$O$31,I6),'Todo-Holiday-Event'!$H$9:$I$28,2,FALSE)),VLOOKUP(DATE($M$31,$O$31,I6),'Todo-Holiday-Event'!$L$9:$M$28,2,FALSE)),"") | K6: =IF(I6<>"",I6+1,IF(WEEKDAY(DATE($M$31,$O$31,1))=5,1,"")) -> 1 | L6: =IF(K6<>"",IF(ISNA(VLOOKUP(DATE($M$31,$O$31,K6),'Todo-Holiday-Event'!$L$9:$M$28,2,FALSE)),IF(ISNA(VLOOKUP(DATE($M$31,$O$31,K6),'Todo-Holiday-Event'!$H$9:$I$28,2,FALSE)),"",VLOOKUP(DATE($M$31,$O$31,K6),'Todo-Holiday-Event'!$H$9:$I$28,2,FALSE)),VLOOKUP(DATE($M$31,$O$31,K6),'Todo-Holiday-Event'!$L$9:$M$28,2,FALSE)),"") | M6: =IF(K6<>"",K6+1,IF(WEEKDAY(DATE($M$31,$O$31,1))=6,1,"")) -> 2 | N6: =IF(M6<>"",IF(ISNA(VLOOKUP(DATE($M$31,$O$31,M6),'Todo-Holiday-Event'!$L$9:$M$28,2,FALSE)),IF(ISNA(VLOOKUP(DATE($M$31,$O$31,M6),'Todo-Holiday-Event'!$H$9:$I$28,2,FALSE)),"",VLOOKUP(DATE($M$31,$O$31,M6),'Todo-Holiday-Event'!$H$9:$I$28,2,FALSE)),VLOOKUP(DATE($M$31,$O$31,M6),'Todo-Holiday-Event'!$L$9:$M$28,2,FALSE)),"") | O6: =IF(M6<>"",M6+1,IF(WEEKDAY(DATE($M$31,$O$31,1))=7,1,"")) -> 3 | P6: =IF(O6<>"",IF(ISNA(VLOOKUP(DATE($M$31,$O$31,O6),'Todo-Holiday-Event'!$L$9:$M$28,2,FALSE)),IF(ISNA(VLOOKUP(DATE($M$31,$O$31,O6),'Todo-Holiday-Event'!$H$9:$I$28,2,FALSE)),"",VLOOKUP(DATE($M$31,$O$31,O6),'Todo-Holiday-Event'!$H$9:$I$28,2,FALSE)),VLOOKUP(DATE($M$31,$O$31,O6),'Todo-Holiday-Event'!$L$9:$M$28,2,FALSE)),"")
C7: =IF(ISERROR('Supporting Calendar'!AB1),"",INDEX('Todo-Holiday-Event'!$D$9:$D$258,'Supporting Calendar'!AB1)) | D7: =IF(ISERROR('Supporting Calendar'!AB1),"",INDEX('Todo-Holiday-Event'!$E$9:$E$258,'Supporting Calendar'!AB1)) | E7: =IF(ISERROR('Supporting Calendar'!AC1),"",INDEX('Todo-Holiday-Event'!$D$9:$D$258,'Supporting Calendar'!AC1)) | F7: =IF(ISERROR('Supporting Calendar'!AC1),"",INDEX('Todo-Holiday-Event'!$E$9:$E$258,'Supporting Calendar'!AC1)) | G7: =IF(ISERROR('Supporting Calendar'!AD1),"",INDEX('Todo-Holiday-Event'!$D$9:$D$258,'Supporting Calendar'!AD1)) | H7: =IF(ISERROR('Supporting Calendar'!AD1),"",INDEX('Todo-Holiday-Event'!$E$9:$E$258,'Supporting Calendar'!AD1)) | I7: =IF(ISERROR('Supporting Calendar'!AE1),"",INDEX('Todo-Holiday-Event'!$D$9:$D$258,'Supporting Calendar'!AE1)) | J7: =IF(ISERROR('Supporting Calendar'!AE1),"",INDEX('Todo-Holiday-Event'!$E$9:$E$258,'Supporting Calendar'!AE1)) | K7: =IF(ISERROR('Supporting Calendar'!AF1),"",INDEX('Todo-Holiday-Event'!$D$9:$D$258,'Supporting Calendar'!AF1)) | L7: =IF(ISERROR('Supporting Calendar'!AF1),"",INDEX('Todo-Holiday-Event'!$E$9:$E$258,'Supporting Calendar'!AF1)) | M7: =IF(ISERROR('Supporting Calendar'!AG1),"",INDEX('Todo-Holiday-Event'!$D$9:$D$258,'Supporting Calendar'!AG1)) | N7: =IF(ISERROR('Supporting Calendar'!AG1),"",INDEX('Todo-Holiday-Event'!$E$9:$E$258,'Supporting Calendar'!AG1)) | O7: =IF(ISERROR('Supporting Calendar'!AH1),"",INDEX('Todo-Holiday-Event'!$D$9:$D$258,'Supporting Calendar'!AH1)) | P7: =IF(ISERROR('Supporting Calendar'!AH1),"",INDEX('Todo-Holiday-Event'!$E$9:$E$258,'Supporting Calendar'!AH1))
C8: =IF(ISERROR('Supporting Calendar'!AB2),"",INDEX('Todo-Holiday-Event'!$D$9:$D$258,'Supporting Calendar'!AB2)) | D8: =IF(ISERROR('Supporting Calendar'!AB2),"",INDEX('Todo-Holiday-Event'!$E$9:$E$258,'Supporting Calendar'!AB2)) | E8: =IF(ISERROR('Supporting Calendar'!AC2),"",INDEX('Todo-Holiday-Event'!$D$9:$D$258,'Supporting Calendar'!AC2)) | F8: =IF(ISERROR('Supporting Calendar'!AC2),"",INDEX('Todo-Holiday-Event'!$E$9:$E$258,'Supporting Calendar'!AC2)) | G8: =IF(ISERROR('Supporting Calendar'!AD2),"",INDEX('Todo-Holiday-Event'!$D$9:$D$258,'Supporting Calendar'!AD2)) | H8: =IF(ISERROR('Supporting Calendar'!AD2),"",INDEX('Todo-Holiday-Event'!$E$9:$E$258,'Supporting Calendar'!AD2)) | I8: =IF(ISERROR('Supporting Calendar'!AE2),"",INDEX('Todo-Holiday-Event'!$D$9:$D$258,'Supporting Calendar'!AE2)) | J8: =IF(ISERROR('Supporting Calendar'!AE2),"",INDEX('Todo-Holiday-Event'!$E$9:$E$258,'Supporting Calendar'!AE2)) | K8: =IF(ISERROR('Supporting Calendar'!AF2),"",INDEX('Todo-Holiday-Event'!$D$9:$D$258,'Supporting Calendar'!AF2)) | L8: =IF(ISERROR('Supporting Calendar'!AF2),"",INDEX('Todo-Holiday-Event'!$E$9:$E$258,'Supporting Calendar'!AF2)) | M8: =IF(ISERROR('Supporting Calendar'!AG2),"",INDEX('Todo-Holiday-Event'!$D$9:$D$258,'Supporting Calendar'!AG2)) | N8: =IF(ISERROR('Supporting Calendar'!AG2),"",INDEX('Todo-Holiday-Event'!$E$9:$E$258,'Supporting Calendar'!AG2)) | O8: =IF(ISERROR('Supporting Calendar'!AH2),"",INDEX('Todo-Holiday-Event'!$D$9:$D$258,'Supporting Calendar'!AH2)) | P8: =IF(ISERROR('Supporting Calendar'!AH2),"",INDEX('Todo-Holiday-Event'!$E$9:$E$258,'Supporting Calendar'!AH2))
C9: =IF(ISERROR('Supporting Calendar'!AB3),"",INDEX('Todo-Holiday-Event'!$D$9:$D$258,'Supporting Calendar'!AB3)) | D9: =IF(ISERROR('Supporting Calendar'!AB3),"",INDEX('Todo-Holiday-Event'!$E$9:$E$258,'Supporting Calendar'!AB3)) | E9: =IF(ISERROR('Supporting Calendar'!AC3),"",INDEX('Todo-Holiday-Event'!$D$9:$D$258,'Supporting Calendar'!AC3)) | F9: =IF(ISERROR('Supporting Calendar'!AC3),"",INDEX('Todo-Holiday-Event'!$E$9:$E$258,'Supporting Calendar'!AC3)) | G9: =IF(ISERROR('Supporting Calendar'!AD3),"",INDEX('Todo-Holiday-Event'!$D$9:$D$258,'Supporting Calendar'!AD3)) | H9: =IF(ISERROR('Supporting Calendar'!AD3),"",INDEX('Todo-Holiday-Event'!$E$9:$E$258,'Supporting Calendar'!AD3)) | I9: =IF(ISERROR('Supporting Calendar'!AE3),"",INDEX('Todo-Holiday-Event'!$D$9:$D$258,'Supporting Calendar'!AE3)) | J9: =IF(ISERROR('Supporting Calendar'!AE3),"",INDEX('Todo-Holiday-Event'!$E$9:$E$258,'Supporting Calendar'!AE3)) | K9: =IF(ISERROR('Supporting Calendar'!AF3),"",INDEX('Todo-Holiday-Event'!$D$9:$D$258,'Supporting Calendar'!AF3)) | L9: =IF(ISERROR('Supporting Calendar'!AF3),"",INDEX('Todo-Holiday-Event'!$E$9:$E$258,'Supporting Calendar'!AF3)) | M9: =IF(ISERROR('Supporting Calendar'!AG3),"",INDEX('Todo-Holiday-Event'!$D$9:$D$258,'Supporting Calendar'!AG3)) | N9: =IF(ISERROR('Supporting Calendar'!AG3),"",INDEX('Todo-Holiday-Event'!$E$9:$E$258,'Supporting Calendar'!AG3)) | O9: =IF(ISERROR('Supporting Calendar'!AH3),"",INDEX('Todo-Holiday-Event'!$D$9:$D$258,'Supporting Calendar'!AH3)) | P9: =IF(ISERROR('Supporting Calendar'!AH3),"",INDEX('Todo-Holiday-Event'!$E$9:$E$258,'Supporting Calendar'!AH3))
